A new study created in RDB with name: MLP_62330
Trial 0 failed because of the following error: KeyboardInterrupt()
Traceback (most recent call last):
  File "/usr/local/lib/python3.8/dist-packages/optuna/study/_optimize.py", line 196, in _run_trial
    value_or_values = func(trial)
  File "/tmp/ipykernel_102620/1044665534.py", line 53, in __call__
    model.fit(tr_x=train_explanatory_variable, tr_y=train_objective_variable,
  File "/tmp/ipykernel_102620/2216372960.py", line 71, in fit
    history = self.model.fit(
  File "/usr/local/lib/python3.8/dist-packages/keras/utils/traceback_utils.py", line 64, in error_handler
    return fn(*args, **kwargs)
  File "/usr/local/lib/python3.8/dist-packages/keras/engine/training.py", line 1409, in fit
    tmp_logs = self.train_function(iterator)
  File "/usr/local/lib/python3.8/dist-packages/tensorflow/python/util/traceback_utils.py", line 150, in error_handler
    return fn(*args, **kwargs)
  File "/usr/local/lib/python3.8/dist-packages/tensorflow/python/eager/def_function.py", line 915, in __call__
    result = self._call(*args, **kwds)
  File "/usr/local/lib/python3.8/dist-packages/tensorflow/python/eager/def_function.py", line 947, in _call
    return self._stateless_fn(*args, **kwds)  # pylint: disable=not-callable
  File "/usr/local/lib/python3.8/dist-packages/tensorflow/python/eager/function.py", line 2453, in __call__
    return graph_function._call_flat(
  File "/usr/local/lib/python3.8/dist-packages/tensorflow/python/eager/function.py", line 1860, in _call_flat
    return self._build_call_outputs(self._inference_function.call(
  File "/usr/local/lib/python3.8/dist-packages/tensorflow/python/eager/function.py", line 497, in call
    outputs = execute.execute(
  File "/usr/local/lib/python3.8/dist-packages/tensorflow/python/eager/execute.py", line 54, in quick_execute
    tensors = pywrap_tfe.TFE_Py_Execute(ctx._handle, device_name, op_name,
KeyboardInterrupt
