A new study created in RDB with name: MLP_82716
Trial 9 failed because of the following error: TypeError("add() got an unexpected keyword argument 'input_shape'")
Traceback (most recent call last):
  File "/usr/local/lib/python3.8/dist-packages/optuna/study/_optimize.py", line 196, in _run_trial
    value_or_values = func(trial)
  File "/tmp/ipykernel_76101/1401318789.py", line 53, in __call__
    model.fit(tr_x=train_explanatory_variable, tr_y=train_objective_variable,
  File "/tmp/ipykernel_76101/2065902392.py", line 25, in fit
    self.model.add(Dropout(rate=input_dropout), input_shape=(tr_x.shape[1],))
  File "/usr/local/lib/python3.8/dist-packages/tensorflow/python/training/tracking/base.py", line 587, in _method_wrapper
    result = method(self, *args, **kwargs)
  File "/usr/local/lib/python3.8/dist-packages/keras/utils/traceback_utils.py", line 67, in error_handler
    raise e.with_traceback(filtered_tb) from None
  File "/usr/local/lib/python3.8/dist-packages/keras/utils/traceback_utils.py", line 64, in error_handler
    return fn(*args, **kwargs)
TypeError: add() got an unexpected keyword argument 'input_shape'
Trial 2 failed because of the following error: TypeError("add() got an unexpected keyword argument 'input_shape'")
Traceback (most recent call last):
  File "/usr/local/lib/python3.8/dist-packages/optuna/study/_optimize.py", line 196, in _run_trial
    value_or_values = func(trial)
  File "/tmp/ipykernel_76101/1401318789.py", line 53, in __call__
    model.fit(tr_x=train_explanatory_variable, tr_y=train_objective_variable,
  File "/tmp/ipykernel_76101/2065902392.py", line 25, in fit
    self.model.add(Dropout(rate=input_dropout), input_shape=(tr_x.shape[1],))
  File "/usr/local/lib/python3.8/dist-packages/tensorflow/python/training/tracking/base.py", line 587, in _method_wrapper
    result = method(self, *args, **kwargs)
  File "/usr/local/lib/python3.8/dist-packages/keras/utils/traceback_utils.py", line 67, in error_handler
    raise e.with_traceback(filtered_tb) from None
  File "/usr/local/lib/python3.8/dist-packages/keras/utils/traceback_utils.py", line 64, in error_handler
    return fn(*args, **kwargs)
TypeError: add() got an unexpected keyword argument 'input_shape'
Trial 23 failed because of the following error: TypeError("add() got an unexpected keyword argument 'input_shape'")
Traceback (most recent call last):
  File "/usr/local/lib/python3.8/dist-packages/optuna/study/_optimize.py", line 196, in _run_trial
    value_or_values = func(trial)
  File "/tmp/ipykernel_76101/1401318789.py", line 53, in __call__
    model.fit(tr_x=train_explanatory_variable, tr_y=train_objective_variable,
  File "/tmp/ipykernel_76101/2065902392.py", line 25, in fit
    self.model.add(Dropout(rate=input_dropout), input_shape=(tr_x.shape[1],))
  File "/usr/local/lib/python3.8/dist-packages/tensorflow/python/training/tracking/base.py", line 587, in _method_wrapper
    result = method(self, *args, **kwargs)
  File "/usr/local/lib/python3.8/dist-packages/keras/utils/traceback_utils.py", line 67, in error_handler
    raise e.with_traceback(filtered_tb) from None
  File "/usr/local/lib/python3.8/dist-packages/keras/utils/traceback_utils.py", line 64, in error_handler
    return fn(*args, **kwargs)
TypeError: add() got an unexpected keyword argument 'input_shape'
Trial 0 failed because of the following error: TypeError("add() got an unexpected keyword argument 'input_shape'")
Traceback (most recent call last):
  File "/usr/local/lib/python3.8/dist-packages/optuna/study/_optimize.py", line 196, in _run_trial
    value_or_values = func(trial)
  File "/tmp/ipykernel_76101/1401318789.py", line 53, in __call__
    model.fit(tr_x=train_explanatory_variable, tr_y=train_objective_variable,
  File "/tmp/ipykernel_76101/2065902392.py", line 25, in fit
    self.model.add(Dropout(rate=input_dropout), input_shape=(tr_x.shape[1],))
  File "/usr/local/lib/python3.8/dist-packages/tensorflow/python/training/tracking/base.py", line 587, in _method_wrapper
    result = method(self, *args, **kwargs)
  File "/usr/local/lib/python3.8/dist-packages/keras/utils/traceback_utils.py", line 67, in error_handler
    raise e.with_traceback(filtered_tb) from None
  File "/usr/local/lib/python3.8/dist-packages/keras/utils/traceback_utils.py", line 64, in error_handler
    return fn(*args, **kwargs)
TypeError: add() got an unexpected keyword argument 'input_shape'
Trial 20 failed because of the following error: TypeError("add() got an unexpected keyword argument 'input_shape'")
Traceback (most recent call last):
  File "/usr/local/lib/python3.8/dist-packages/optuna/study/_optimize.py", line 196, in _run_trial
    value_or_values = func(trial)
  File "/tmp/ipykernel_76101/1401318789.py", line 53, in __call__
    model.fit(tr_x=train_explanatory_variable, tr_y=train_objective_variable,
  File "/tmp/ipykernel_76101/2065902392.py", line 25, in fit
    self.model.add(Dropout(rate=input_dropout), input_shape=(tr_x.shape[1],))
  File "/usr/local/lib/python3.8/dist-packages/tensorflow/python/training/tracking/base.py", line 587, in _method_wrapper
    result = method(self, *args, **kwargs)
  File "/usr/local/lib/python3.8/dist-packages/keras/utils/traceback_utils.py", line 67, in error_handler
    raise e.with_traceback(filtered_tb) from None
  File "/usr/local/lib/python3.8/dist-packages/keras/utils/traceback_utils.py", line 64, in error_handler
    return fn(*args, **kwargs)
TypeError: add() got an unexpected keyword argument 'input_shape'
Trial 8 failed because of the following error: TypeError("add() got an unexpected keyword argument 'input_shape'")
Traceback (most recent call last):
  File "/usr/local/lib/python3.8/dist-packages/optuna/study/_optimize.py", line 196, in _run_trial
    value_or_values = func(trial)
  File "/tmp/ipykernel_76101/1401318789.py", line 53, in __call__
    model.fit(tr_x=train_explanatory_variable, tr_y=train_objective_variable,
  File "/tmp/ipykernel_76101/2065902392.py", line 25, in fit
    self.model.add(Dropout(rate=input_dropout), input_shape=(tr_x.shape[1],))
  File "/usr/local/lib/python3.8/dist-packages/tensorflow/python/training/tracking/base.py", line 587, in _method_wrapper
    result = method(self, *args, **kwargs)
  File "/usr/local/lib/python3.8/dist-packages/keras/utils/traceback_utils.py", line 67, in error_handler
    raise e.with_traceback(filtered_tb) from None
  File "/usr/local/lib/python3.8/dist-packages/keras/utils/traceback_utils.py", line 64, in error_handler
    return fn(*args, **kwargs)
TypeError: add() got an unexpected keyword argument 'input_shape'
Trial 14 failed because of the following error: TypeError("add() got an unexpected keyword argument 'input_shape'")
Traceback (most recent call last):
  File "/usr/local/lib/python3.8/dist-packages/optuna/study/_optimize.py", line 196, in _run_trial
    value_or_values = func(trial)
  File "/tmp/ipykernel_76101/1401318789.py", line 53, in __call__
    model.fit(tr_x=train_explanatory_variable, tr_y=train_objective_variable,
  File "/tmp/ipykernel_76101/2065902392.py", line 25, in fit
    self.model.add(Dropout(rate=input_dropout), input_shape=(tr_x.shape[1],))
  File "/usr/local/lib/python3.8/dist-packages/tensorflow/python/training/tracking/base.py", line 587, in _method_wrapper
    result = method(self, *args, **kwargs)
  File "/usr/local/lib/python3.8/dist-packages/keras/utils/traceback_utils.py", line 67, in error_handler
    raise e.with_traceback(filtered_tb) from None
  File "/usr/local/lib/python3.8/dist-packages/keras/utils/traceback_utils.py", line 64, in error_handler
    return fn(*args, **kwargs)
TypeError: add() got an unexpected keyword argument 'input_shape'
Trial 7 failed because of the following error: TypeError("add() got an unexpected keyword argument 'input_shape'")
Traceback (most recent call last):
  File "/usr/local/lib/python3.8/dist-packages/optuna/study/_optimize.py", line 196, in _run_trial
    value_or_values = func(trial)
  File "/tmp/ipykernel_76101/1401318789.py", line 53, in __call__
    model.fit(tr_x=train_explanatory_variable, tr_y=train_objective_variable,
  File "/tmp/ipykernel_76101/2065902392.py", line 25, in fit
    self.model.add(Dropout(rate=input_dropout), input_shape=(tr_x.shape[1],))
  File "/usr/local/lib/python3.8/dist-packages/tensorflow/python/training/tracking/base.py", line 587, in _method_wrapper
    result = method(self, *args, **kwargs)
  File "/usr/local/lib/python3.8/dist-packages/keras/utils/traceback_utils.py", line 67, in error_handler
    raise e.with_traceback(filtered_tb) from None
  File "/usr/local/lib/python3.8/dist-packages/keras/utils/traceback_utils.py", line 64, in error_handler
    return fn(*args, **kwargs)
TypeError: add() got an unexpected keyword argument 'input_shape'
Trial 17 failed because of the following error: TypeError("add() got an unexpected keyword argument 'input_shape'")
Traceback (most recent call last):
  File "/usr/local/lib/python3.8/dist-packages/optuna/study/_optimize.py", line 196, in _run_trial
    value_or_values = func(trial)
  File "/tmp/ipykernel_76101/1401318789.py", line 53, in __call__
    model.fit(tr_x=train_explanatory_variable, tr_y=train_objective_variable,
  File "/tmp/ipykernel_76101/2065902392.py", line 25, in fit
    self.model.add(Dropout(rate=input_dropout), input_shape=(tr_x.shape[1],))
  File "/usr/local/lib/python3.8/dist-packages/tensorflow/python/training/tracking/base.py", line 587, in _method_wrapper
    result = method(self, *args, **kwargs)
  File "/usr/local/lib/python3.8/dist-packages/keras/utils/traceback_utils.py", line 67, in error_handler
    raise e.with_traceback(filtered_tb) from None
  File "/usr/local/lib/python3.8/dist-packages/keras/utils/traceback_utils.py", line 64, in error_handler
    return fn(*args, **kwargs)
TypeError: add() got an unexpected keyword argument 'input_shape'
Trial 15 failed because of the following error: TypeError("add() got an unexpected keyword argument 'input_shape'")
Traceback (most recent call last):
  File "/usr/local/lib/python3.8/dist-packages/optuna/study/_optimize.py", line 196, in _run_trial
    value_or_values = func(trial)
  File "/tmp/ipykernel_76101/1401318789.py", line 53, in __call__
    model.fit(tr_x=train_explanatory_variable, tr_y=train_objective_variable,
  File "/tmp/ipykernel_76101/2065902392.py", line 25, in fit
    self.model.add(Dropout(rate=input_dropout), input_shape=(tr_x.shape[1],))
  File "/usr/local/lib/python3.8/dist-packages/tensorflow/python/training/tracking/base.py", line 587, in _method_wrapper
    result = method(self, *args, **kwargs)
  File "/usr/local/lib/python3.8/dist-packages/keras/utils/traceback_utils.py", line 67, in error_handler
    raise e.with_traceback(filtered_tb) from None
  File "/usr/local/lib/python3.8/dist-packages/keras/utils/traceback_utils.py", line 64, in error_handler
    return fn(*args, **kwargs)
TypeError: add() got an unexpected keyword argument 'input_shape'
Trial 1 failed because of the following error: TypeError("add() got an unexpected keyword argument 'input_shape'")
Traceback (most recent call last):
  File "/usr/local/lib/python3.8/dist-packages/optuna/study/_optimize.py", line 196, in _run_trial
    value_or_values = func(trial)
  File "/tmp/ipykernel_76101/1401318789.py", line 53, in __call__
    model.fit(tr_x=train_explanatory_variable, tr_y=train_objective_variable,
  File "/tmp/ipykernel_76101/2065902392.py", line 25, in fit
    self.model.add(Dropout(rate=input_dropout), input_shape=(tr_x.shape[1],))
  File "/usr/local/lib/python3.8/dist-packages/tensorflow/python/training/tracking/base.py", line 587, in _method_wrapper
    result = method(self, *args, **kwargs)
  File "/usr/local/lib/python3.8/dist-packages/keras/utils/traceback_utils.py", line 67, in error_handler
    raise e.with_traceback(filtered_tb) from None
  File "/usr/local/lib/python3.8/dist-packages/keras/utils/traceback_utils.py", line 64, in error_handler
    return fn(*args, **kwargs)
TypeError: add() got an unexpected keyword argument 'input_shape'
Trial 21 failed because of the following error: TypeError("add() got an unexpected keyword argument 'input_shape'")
Traceback (most recent call last):
  File "/usr/local/lib/python3.8/dist-packages/optuna/study/_optimize.py", line 196, in _run_trial
    value_or_values = func(trial)
  File "/tmp/ipykernel_76101/1401318789.py", line 53, in __call__
    model.fit(tr_x=train_explanatory_variable, tr_y=train_objective_variable,
  File "/tmp/ipykernel_76101/2065902392.py", line 25, in fit
    self.model.add(Dropout(rate=input_dropout), input_shape=(tr_x.shape[1],))
  File "/usr/local/lib/python3.8/dist-packages/tensorflow/python/training/tracking/base.py", line 587, in _method_wrapper
    result = method(self, *args, **kwargs)
  File "/usr/local/lib/python3.8/dist-packages/keras/utils/traceback_utils.py", line 67, in error_handler
    raise e.with_traceback(filtered_tb) from None
  File "/usr/local/lib/python3.8/dist-packages/keras/utils/traceback_utils.py", line 64, in error_handler
    return fn(*args, **kwargs)
TypeError: add() got an unexpected keyword argument 'input_shape'
Trial 10 failed because of the following error: TypeError("add() got an unexpected keyword argument 'input_shape'")
Traceback (most recent call last):
  File "/usr/local/lib/python3.8/dist-packages/optuna/study/_optimize.py", line 196, in _run_trial
    value_or_values = func(trial)
  File "/tmp/ipykernel_76101/1401318789.py", line 53, in __call__
    model.fit(tr_x=train_explanatory_variable, tr_y=train_objective_variable,
  File "/tmp/ipykernel_76101/2065902392.py", line 25, in fit
    self.model.add(Dropout(rate=input_dropout), input_shape=(tr_x.shape[1],))
  File "/usr/local/lib/python3.8/dist-packages/tensorflow/python/training/tracking/base.py", line 587, in _method_wrapper
    result = method(self, *args, **kwargs)
  File "/usr/local/lib/python3.8/dist-packages/keras/utils/traceback_utils.py", line 67, in error_handler
    raise e.with_traceback(filtered_tb) from None
  File "/usr/local/lib/python3.8/dist-packages/keras/utils/traceback_utils.py", line 64, in error_handler
    return fn(*args, **kwargs)
TypeError: add() got an unexpected keyword argument 'input_shape'
Trial 18 failed because of the following error: TypeError("add() got an unexpected keyword argument 'input_shape'")
Traceback (most recent call last):
  File "/usr/local/lib/python3.8/dist-packages/optuna/study/_optimize.py", line 196, in _run_trial
    value_or_values = func(trial)
  File "/tmp/ipykernel_76101/1401318789.py", line 53, in __call__
    model.fit(tr_x=train_explanatory_variable, tr_y=train_objective_variable,
  File "/tmp/ipykernel_76101/2065902392.py", line 25, in fit
    self.model.add(Dropout(rate=input_dropout), input_shape=(tr_x.shape[1],))
  File "/usr/local/lib/python3.8/dist-packages/tensorflow/python/training/tracking/base.py", line 587, in _method_wrapper
    result = method(self, *args, **kwargs)
  File "/usr/local/lib/python3.8/dist-packages/keras/utils/traceback_utils.py", line 67, in error_handler
    raise e.with_traceback(filtered_tb) from None
  File "/usr/local/lib/python3.8/dist-packages/keras/utils/traceback_utils.py", line 64, in error_handler
    return fn(*args, **kwargs)
TypeError: add() got an unexpected keyword argument 'input_shape'
Trial 19 failed because of the following error: TypeError("add() got an unexpected keyword argument 'input_shape'")
Traceback (most recent call last):
  File "/usr/local/lib/python3.8/dist-packages/optuna/study/_optimize.py", line 196, in _run_trial
    value_or_values = func(trial)
  File "/tmp/ipykernel_76101/1401318789.py", line 53, in __call__
    model.fit(tr_x=train_explanatory_variable, tr_y=train_objective_variable,
  File "/tmp/ipykernel_76101/2065902392.py", line 25, in fit
    self.model.add(Dropout(rate=input_dropout), input_shape=(tr_x.shape[1],))
  File "/usr/local/lib/python3.8/dist-packages/tensorflow/python/training/tracking/base.py", line 587, in _method_wrapper
    result = method(self, *args, **kwargs)
  File "/usr/local/lib/python3.8/dist-packages/keras/utils/traceback_utils.py", line 67, in error_handler
    raise e.with_traceback(filtered_tb) from None
  File "/usr/local/lib/python3.8/dist-packages/keras/utils/traceback_utils.py", line 64, in error_handler
    return fn(*args, **kwargs)
TypeError: add() got an unexpected keyword argument 'input_shape'
Trial 3 failed because of the following error: TypeError("add() got an unexpected keyword argument 'input_shape'")
Traceback (most recent call last):
  File "/usr/local/lib/python3.8/dist-packages/optuna/study/_optimize.py", line 196, in _run_trial
    value_or_values = func(trial)
  File "/tmp/ipykernel_76101/1401318789.py", line 53, in __call__
    model.fit(tr_x=train_explanatory_variable, tr_y=train_objective_variable,
  File "/tmp/ipykernel_76101/2065902392.py", line 25, in fit
    self.model.add(Dropout(rate=input_dropout), input_shape=(tr_x.shape[1],))
  File "/usr/local/lib/python3.8/dist-packages/tensorflow/python/training/tracking/base.py", line 587, in _method_wrapper
    result = method(self, *args, **kwargs)
  File "/usr/local/lib/python3.8/dist-packages/keras/utils/traceback_utils.py", line 67, in error_handler
    raise e.with_traceback(filtered_tb) from None
  File "/usr/local/lib/python3.8/dist-packages/keras/utils/traceback_utils.py", line 64, in error_handler
    return fn(*args, **kwargs)
TypeError: add() got an unexpected keyword argument 'input_shape'
Trial 11 failed because of the following error: TypeError("add() got an unexpected keyword argument 'input_shape'")
Traceback (most recent call last):
  File "/usr/local/lib/python3.8/dist-packages/optuna/study/_optimize.py", line 196, in _run_trial
    value_or_values = func(trial)
  File "/tmp/ipykernel_76101/1401318789.py", line 53, in __call__
    model.fit(tr_x=train_explanatory_variable, tr_y=train_objective_variable,
  File "/tmp/ipykernel_76101/2065902392.py", line 25, in fit
    self.model.add(Dropout(rate=input_dropout), input_shape=(tr_x.shape[1],))
  File "/usr/local/lib/python3.8/dist-packages/tensorflow/python/training/tracking/base.py", line 587, in _method_wrapper
    result = method(self, *args, **kwargs)
  File "/usr/local/lib/python3.8/dist-packages/keras/utils/traceback_utils.py", line 67, in error_handler
    raise e.with_traceback(filtered_tb) from None
  File "/usr/local/lib/python3.8/dist-packages/keras/utils/traceback_utils.py", line 64, in error_handler
    return fn(*args, **kwargs)
TypeError: add() got an unexpected keyword argument 'input_shape'
Trial 5 failed because of the following error: TypeError("add() got an unexpected keyword argument 'input_shape'")
Traceback (most recent call last):
  File "/usr/local/lib/python3.8/dist-packages/optuna/study/_optimize.py", line 196, in _run_trial
    value_or_values = func(trial)
  File "/tmp/ipykernel_76101/1401318789.py", line 53, in __call__
    model.fit(tr_x=train_explanatory_variable, tr_y=train_objective_variable,
  File "/tmp/ipykernel_76101/2065902392.py", line 25, in fit
    self.model.add(Dropout(rate=input_dropout), input_shape=(tr_x.shape[1],))
  File "/usr/local/lib/python3.8/dist-packages/tensorflow/python/training/tracking/base.py", line 587, in _method_wrapper
    result = method(self, *args, **kwargs)
  File "/usr/local/lib/python3.8/dist-packages/keras/utils/traceback_utils.py", line 67, in error_handler
    raise e.with_traceback(filtered_tb) from None
  File "/usr/local/lib/python3.8/dist-packages/keras/utils/traceback_utils.py", line 64, in error_handler
    return fn(*args, **kwargs)
TypeError: add() got an unexpected keyword argument 'input_shape'
Trial 12 failed because of the following error: TypeError("add() got an unexpected keyword argument 'input_shape'")
Traceback (most recent call last):
  File "/usr/local/lib/python3.8/dist-packages/optuna/study/_optimize.py", line 196, in _run_trial
    value_or_values = func(trial)
  File "/tmp/ipykernel_76101/1401318789.py", line 53, in __call__
    model.fit(tr_x=train_explanatory_variable, tr_y=train_objective_variable,
  File "/tmp/ipykernel_76101/2065902392.py", line 25, in fit
    self.model.add(Dropout(rate=input_dropout), input_shape=(tr_x.shape[1],))
  File "/usr/local/lib/python3.8/dist-packages/tensorflow/python/training/tracking/base.py", line 587, in _method_wrapper
    result = method(self, *args, **kwargs)
  File "/usr/local/lib/python3.8/dist-packages/keras/utils/traceback_utils.py", line 67, in error_handler
    raise e.with_traceback(filtered_tb) from None
  File "/usr/local/lib/python3.8/dist-packages/keras/utils/traceback_utils.py", line 64, in error_handler
    return fn(*args, **kwargs)
TypeError: add() got an unexpected keyword argument 'input_shape'
Trial 16 failed because of the following error: TypeError("add() got an unexpected keyword argument 'input_shape'")
Traceback (most recent call last):
  File "/usr/local/lib/python3.8/dist-packages/optuna/study/_optimize.py", line 196, in _run_trial
    value_or_values = func(trial)
  File "/tmp/ipykernel_76101/1401318789.py", line 53, in __call__
    model.fit(tr_x=train_explanatory_variable, tr_y=train_objective_variable,
  File "/tmp/ipykernel_76101/2065902392.py", line 25, in fit
    self.model.add(Dropout(rate=input_dropout), input_shape=(tr_x.shape[1],))
  File "/usr/local/lib/python3.8/dist-packages/tensorflow/python/training/tracking/base.py", line 587, in _method_wrapper
    result = method(self, *args, **kwargs)
  File "/usr/local/lib/python3.8/dist-packages/keras/utils/traceback_utils.py", line 67, in error_handler
    raise e.with_traceback(filtered_tb) from None
  File "/usr/local/lib/python3.8/dist-packages/keras/utils/traceback_utils.py", line 64, in error_handler
    return fn(*args, **kwargs)
TypeError: add() got an unexpected keyword argument 'input_shape'
Trial 4 failed because of the following error: TypeError("add() got an unexpected keyword argument 'input_shape'")
Traceback (most recent call last):
  File "/usr/local/lib/python3.8/dist-packages/optuna/study/_optimize.py", line 196, in _run_trial
    value_or_values = func(trial)
  File "/tmp/ipykernel_76101/1401318789.py", line 53, in __call__
    model.fit(tr_x=train_explanatory_variable, tr_y=train_objective_variable,
  File "/tmp/ipykernel_76101/2065902392.py", line 25, in fit
    self.model.add(Dropout(rate=input_dropout), input_shape=(tr_x.shape[1],))
  File "/usr/local/lib/python3.8/dist-packages/tensorflow/python/training/tracking/base.py", line 587, in _method_wrapper
    result = method(self, *args, **kwargs)
  File "/usr/local/lib/python3.8/dist-packages/keras/utils/traceback_utils.py", line 67, in error_handler
    raise e.with_traceback(filtered_tb) from None
  File "/usr/local/lib/python3.8/dist-packages/keras/utils/traceback_utils.py", line 64, in error_handler
    return fn(*args, **kwargs)
TypeError: add() got an unexpected keyword argument 'input_shape'
Trial 6 failed because of the following error: TypeError("add() got an unexpected keyword argument 'input_shape'")
Traceback (most recent call last):
  File "/usr/local/lib/python3.8/dist-packages/optuna/study/_optimize.py", line 196, in _run_trial
    value_or_values = func(trial)
  File "/tmp/ipykernel_76101/1401318789.py", line 53, in __call__
    model.fit(tr_x=train_explanatory_variable, tr_y=train_objective_variable,
  File "/tmp/ipykernel_76101/2065902392.py", line 25, in fit
    self.model.add(Dropout(rate=input_dropout), input_shape=(tr_x.shape[1],))
  File "/usr/local/lib/python3.8/dist-packages/tensorflow/python/training/tracking/base.py", line 587, in _method_wrapper
    result = method(self, *args, **kwargs)
  File "/usr/local/lib/python3.8/dist-packages/keras/utils/traceback_utils.py", line 67, in error_handler
    raise e.with_traceback(filtered_tb) from None
  File "/usr/local/lib/python3.8/dist-packages/keras/utils/traceback_utils.py", line 64, in error_handler
    return fn(*args, **kwargs)
TypeError: add() got an unexpected keyword argument 'input_shape'
Trial 13 failed because of the following error: TypeError("add() got an unexpected keyword argument 'input_shape'")
Traceback (most recent call last):
  File "/usr/local/lib/python3.8/dist-packages/optuna/study/_optimize.py", line 196, in _run_trial
    value_or_values = func(trial)
  File "/tmp/ipykernel_76101/1401318789.py", line 53, in __call__
    model.fit(tr_x=train_explanatory_variable, tr_y=train_objective_variable,
  File "/tmp/ipykernel_76101/2065902392.py", line 25, in fit
    self.model.add(Dropout(rate=input_dropout), input_shape=(tr_x.shape[1],))
  File "/usr/local/lib/python3.8/dist-packages/tensorflow/python/training/tracking/base.py", line 587, in _method_wrapper
    result = method(self, *args, **kwargs)
  File "/usr/local/lib/python3.8/dist-packages/keras/utils/traceback_utils.py", line 67, in error_handler
    raise e.with_traceback(filtered_tb) from None
  File "/usr/local/lib/python3.8/dist-packages/keras/utils/traceback_utils.py", line 64, in error_handler
    return fn(*args, **kwargs)
TypeError: add() got an unexpected keyword argument 'input_shape'
Trial 22 failed because of the following error: TypeError("add() got an unexpected keyword argument 'input_shape'")
Traceback (most recent call last):
  File "/usr/local/lib/python3.8/dist-packages/optuna/study/_optimize.py", line 196, in _run_trial
    value_or_values = func(trial)
  File "/tmp/ipykernel_76101/1401318789.py", line 53, in __call__
    model.fit(tr_x=train_explanatory_variable, tr_y=train_objective_variable,
  File "/tmp/ipykernel_76101/2065902392.py", line 25, in fit
    self.model.add(Dropout(rate=input_dropout), input_shape=(tr_x.shape[1],))
  File "/usr/local/lib/python3.8/dist-packages/tensorflow/python/training/tracking/base.py", line 587, in _method_wrapper
    result = method(self, *args, **kwargs)
  File "/usr/local/lib/python3.8/dist-packages/keras/utils/traceback_utils.py", line 67, in error_handler
    raise e.with_traceback(filtered_tb) from None
  File "/usr/local/lib/python3.8/dist-packages/keras/utils/traceback_utils.py", line 64, in error_handler
    return fn(*args, **kwargs)
TypeError: add() got an unexpected keyword argument 'input_shape'
