A new study created in RDB with name: MLP_84324
Trial 0 failed because of the following error: KeyboardInterrupt()
Traceback (most recent call last):
  File "/usr/local/lib/python3.8/dist-packages/optuna/study/_optimize.py", line 196, in _run_trial
    value_or_values = func(trial)
  File "/tmp/ipykernel_76101/2662274010.py", line 53, in __call__
    model.fit(tr_x=train_explanatory_variable, tr_y=train_objective_variable,
  File "/tmp/ipykernel_76101/2896663436.py", line 71, in fit
    history = self.model.fit(
  File "/usr/local/lib/python3.8/dist-packages/keras/utils/traceback_utils.py", line 64, in error_handler
    return fn(*args, **kwargs)
  File "/usr/local/lib/python3.8/dist-packages/keras/engine/training.py", line 1445, in fit
    val_logs = self.evaluate(
  File "/usr/local/lib/python3.8/dist-packages/keras/utils/traceback_utils.py", line 64, in error_handler
    return fn(*args, **kwargs)
  File "/usr/local/lib/python3.8/dist-packages/keras/engine/training.py", line 1750, in evaluate
    for _, iterator in data_handler.enumerate_epochs():  # Single epoch.
  File "/usr/local/lib/python3.8/dist-packages/keras/engine/data_adapter.py", line 1193, in enumerate_epochs
    data_iterator = iter(self._dataset)
  File "/usr/local/lib/python3.8/dist-packages/tensorflow/python/data/ops/dataset_ops.py", line 494, in __iter__
    return iterator_ops.OwnedIterator(self)
  File "/usr/local/lib/python3.8/dist-packages/tensorflow/python/data/ops/iterator_ops.py", line 696, in __init__
    self._create_iterator(dataset)
  File "/usr/local/lib/python3.8/dist-packages/tensorflow/python/data/ops/iterator_ops.py", line 721, in _create_iterator
    gen_dataset_ops.make_iterator(ds_variant, self._iterator_resource)
  File "/usr/local/lib/python3.8/dist-packages/tensorflow/python/ops/gen_dataset_ops.py", line 3409, in make_iterator
    _result = pywrap_tfe.TFE_Py_FastPathExecute(
KeyboardInterrupt
