A new study created in RDB with name: Poly_linear_95347
Trial 10 failed because of the following error: AttributeError("'list' object has no attribute 'mean'")
Traceback (most recent call last):
  File "/usr/local/lib/python3.8/dist-packages/optuna/study/_optimize.py", line 196, in _run_trial
    value_or_values = func(trial)
  File "/tmp/ipykernel_42977/361837279.py", line 51, in __call__
    return scores.mean()
AttributeError: 'list' object has no attribute 'mean'
Trial 0 failed because of the following error: AttributeError("'list' object has no attribute 'mean'")
Traceback (most recent call last):
  File "/usr/local/lib/python3.8/dist-packages/optuna/study/_optimize.py", line 196, in _run_trial
    value_or_values = func(trial)
  File "/tmp/ipykernel_42977/361837279.py", line 51, in __call__
    return scores.mean()
AttributeError: 'list' object has no attribute 'mean'
Trial 14 failed because of the following error: AttributeError("'list' object has no attribute 'mean'")
Traceback (most recent call last):
  File "/usr/local/lib/python3.8/dist-packages/optuna/study/_optimize.py", line 196, in _run_trial
    value_or_values = func(trial)
  File "/tmp/ipykernel_42977/361837279.py", line 51, in __call__
    return scores.mean()
AttributeError: 'list' object has no attribute 'mean'
Trial 18 failed because of the following error: AttributeError("'list' object has no attribute 'mean'")
Traceback (most recent call last):
  File "/usr/local/lib/python3.8/dist-packages/optuna/study/_optimize.py", line 196, in _run_trial
    value_or_values = func(trial)
  File "/tmp/ipykernel_42977/361837279.py", line 51, in __call__
    return scores.mean()
AttributeError: 'list' object has no attribute 'mean'
Trial 12 failed because of the following error: AttributeError("'list' object has no attribute 'mean'")
Traceback (most recent call last):
  File "/usr/local/lib/python3.8/dist-packages/optuna/study/_optimize.py", line 196, in _run_trial
    value_or_values = func(trial)
  File "/tmp/ipykernel_42977/361837279.py", line 51, in __call__
    return scores.mean()
AttributeError: 'list' object has no attribute 'mean'
Trial 1 failed because of the following error: AttributeError("'list' object has no attribute 'mean'")
Traceback (most recent call last):
  File "/usr/local/lib/python3.8/dist-packages/optuna/study/_optimize.py", line 196, in _run_trial
    value_or_values = func(trial)
  File "/tmp/ipykernel_42977/361837279.py", line 51, in __call__
    return scores.mean()
AttributeError: 'list' object has no attribute 'mean'
Trial 6 failed because of the following error: AttributeError("'list' object has no attribute 'mean'")
Traceback (most recent call last):
  File "/usr/local/lib/python3.8/dist-packages/optuna/study/_optimize.py", line 196, in _run_trial
    value_or_values = func(trial)
  File "/tmp/ipykernel_42977/361837279.py", line 51, in __call__
    return scores.mean()
AttributeError: 'list' object has no attribute 'mean'
Trial 13 failed because of the following error: AttributeError("'list' object has no attribute 'mean'")
Traceback (most recent call last):
  File "/usr/local/lib/python3.8/dist-packages/optuna/study/_optimize.py", line 196, in _run_trial
    value_or_values = func(trial)
  File "/tmp/ipykernel_42977/361837279.py", line 51, in __call__
    return scores.mean()
AttributeError: 'list' object has no attribute 'mean'
Trial 20 failed because of the following error: AttributeError("'list' object has no attribute 'mean'")
Traceback (most recent call last):
  File "/usr/local/lib/python3.8/dist-packages/optuna/study/_optimize.py", line 196, in _run_trial
    value_or_values = func(trial)
  File "/tmp/ipykernel_42977/361837279.py", line 51, in __call__
    return scores.mean()
AttributeError: 'list' object has no attribute 'mean'
Trial 2 failed because of the following error: AttributeError("'list' object has no attribute 'mean'")
Traceback (most recent call last):
  File "/usr/local/lib/python3.8/dist-packages/optuna/study/_optimize.py", line 196, in _run_trial
    value_or_values = func(trial)
  File "/tmp/ipykernel_42977/361837279.py", line 51, in __call__
    return scores.mean()
AttributeError: 'list' object has no attribute 'mean'
Trial 22 failed because of the following error: AttributeError("'list' object has no attribute 'mean'")
Traceback (most recent call last):
  File "/usr/local/lib/python3.8/dist-packages/optuna/study/_optimize.py", line 196, in _run_trial
    value_or_values = func(trial)
  File "/tmp/ipykernel_42977/361837279.py", line 51, in __call__
    return scores.mean()
AttributeError: 'list' object has no attribute 'mean'
Trial 9 failed because of the following error: AttributeError("'list' object has no attribute 'mean'")
Traceback (most recent call last):
  File "/usr/local/lib/python3.8/dist-packages/optuna/study/_optimize.py", line 196, in _run_trial
    value_or_values = func(trial)
  File "/tmp/ipykernel_42977/361837279.py", line 51, in __call__
    return scores.mean()
AttributeError: 'list' object has no attribute 'mean'
Trial 7 failed because of the following error: AttributeError("'list' object has no attribute 'mean'")
Traceback (most recent call last):
  File "/usr/local/lib/python3.8/dist-packages/optuna/study/_optimize.py", line 196, in _run_trial
    value_or_values = func(trial)
  File "/tmp/ipykernel_42977/361837279.py", line 51, in __call__
    return scores.mean()
AttributeError: 'list' object has no attribute 'mean'
Trial 4 failed because of the following error: AttributeError("'list' object has no attribute 'mean'")
Traceback (most recent call last):
  File "/usr/local/lib/python3.8/dist-packages/optuna/study/_optimize.py", line 196, in _run_trial
    value_or_values = func(trial)
  File "/tmp/ipykernel_42977/361837279.py", line 51, in __call__
    return scores.mean()
AttributeError: 'list' object has no attribute 'mean'
Trial 11 failed because of the following error: AttributeError("'list' object has no attribute 'mean'")
Traceback (most recent call last):
  File "/usr/local/lib/python3.8/dist-packages/optuna/study/_optimize.py", line 196, in _run_trial
    value_or_values = func(trial)
  File "/tmp/ipykernel_42977/361837279.py", line 51, in __call__
    return scores.mean()
AttributeError: 'list' object has no attribute 'mean'
Trial 8 failed because of the following error: AttributeError("'list' object has no attribute 'mean'")
Traceback (most recent call last):
  File "/usr/local/lib/python3.8/dist-packages/optuna/study/_optimize.py", line 196, in _run_trial
    value_or_values = func(trial)
  File "/tmp/ipykernel_42977/361837279.py", line 51, in __call__
    return scores.mean()
AttributeError: 'list' object has no attribute 'mean'
Trial 17 failed because of the following error: AttributeError("'list' object has no attribute 'mean'")
Traceback (most recent call last):
  File "/usr/local/lib/python3.8/dist-packages/optuna/study/_optimize.py", line 196, in _run_trial
    value_or_values = func(trial)
  File "/tmp/ipykernel_42977/361837279.py", line 51, in __call__
    return scores.mean()
AttributeError: 'list' object has no attribute 'mean'
Trial 16 failed because of the following error: AttributeError("'list' object has no attribute 'mean'")
Traceback (most recent call last):
  File "/usr/local/lib/python3.8/dist-packages/optuna/study/_optimize.py", line 196, in _run_trial
    value_or_values = func(trial)
  File "/tmp/ipykernel_42977/361837279.py", line 51, in __call__
    return scores.mean()
AttributeError: 'list' object has no attribute 'mean'
Trial 5 failed because of the following error: AttributeError("'list' object has no attribute 'mean'")
Traceback (most recent call last):
  File "/usr/local/lib/python3.8/dist-packages/optuna/study/_optimize.py", line 196, in _run_trial
    value_or_values = func(trial)
  File "/tmp/ipykernel_42977/361837279.py", line 51, in __call__
    return scores.mean()
AttributeError: 'list' object has no attribute 'mean'
Trial 15 failed because of the following error: AttributeError("'list' object has no attribute 'mean'")
Traceback (most recent call last):
  File "/usr/local/lib/python3.8/dist-packages/optuna/study/_optimize.py", line 196, in _run_trial
    value_or_values = func(trial)
  File "/tmp/ipykernel_42977/361837279.py", line 51, in __call__
    return scores.mean()
AttributeError: 'list' object has no attribute 'mean'
Trial 3 failed because of the following error: AttributeError("'list' object has no attribute 'mean'")
Traceback (most recent call last):
  File "/usr/local/lib/python3.8/dist-packages/optuna/study/_optimize.py", line 196, in _run_trial
    value_or_values = func(trial)
  File "/tmp/ipykernel_42977/361837279.py", line 51, in __call__
    return scores.mean()
AttributeError: 'list' object has no attribute 'mean'
Trial 23 failed because of the following error: AttributeError("'list' object has no attribute 'mean'")
Traceback (most recent call last):
  File "/usr/local/lib/python3.8/dist-packages/optuna/study/_optimize.py", line 196, in _run_trial
    value_or_values = func(trial)
  File "/tmp/ipykernel_42977/361837279.py", line 51, in __call__
    return scores.mean()
AttributeError: 'list' object has no attribute 'mean'
Trial 19 failed because of the following error: AttributeError("'list' object has no attribute 'mean'")
Traceback (most recent call last):
  File "/usr/local/lib/python3.8/dist-packages/optuna/study/_optimize.py", line 196, in _run_trial
    value_or_values = func(trial)
  File "/tmp/ipykernel_42977/361837279.py", line 51, in __call__
    return scores.mean()
AttributeError: 'list' object has no attribute 'mean'
Trial 21 failed because of the following error: AttributeError("'list' object has no attribute 'mean'")
Traceback (most recent call last):
  File "/usr/local/lib/python3.8/dist-packages/optuna/study/_optimize.py", line 196, in _run_trial
    value_or_values = func(trial)
  File "/tmp/ipykernel_42977/361837279.py", line 51, in __call__
    return scores.mean()
AttributeError: 'list' object has no attribute 'mean'
