A new study created in RDB with name: Poly_Linear_911
Trial 2 failed because of the following error: TypeError('PolynomialRegression() argument after * must be an iterable, not int')
Traceback (most recent call last):
  File "/usr/local/lib/python3.8/dist-packages/optuna/study/_optimize.py", line 196, in _run_trial
    value_or_values = func(trial)
  File "/tmp/ipykernel_7443/3357385256.py", line 14, in __call__
    model = PolynomialRegression(*args, **kwargs)
TypeError: PolynomialRegression() argument after * must be an iterable, not int
Trial 4 failed because of the following error: TypeError('PolynomialRegression() argument after * must be an iterable, not int')
Traceback (most recent call last):
  File "/usr/local/lib/python3.8/dist-packages/optuna/study/_optimize.py", line 196, in _run_trial
    value_or_values = func(trial)
  File "/tmp/ipykernel_7443/3357385256.py", line 14, in __call__
    model = PolynomialRegression(*args, **kwargs)
TypeError: PolynomialRegression() argument after * must be an iterable, not int
Trial 14 failed because of the following error: TypeError('PolynomialRegression() argument after * must be an iterable, not int')
Traceback (most recent call last):
  File "/usr/local/lib/python3.8/dist-packages/optuna/study/_optimize.py", line 196, in _run_trial
    value_or_values = func(trial)
  File "/tmp/ipykernel_7443/3357385256.py", line 14, in __call__
    model = PolynomialRegression(*args, **kwargs)
TypeError: PolynomialRegression() argument after * must be an iterable, not int
Trial 22 failed because of the following error: TypeError('PolynomialRegression() argument after * must be an iterable, not int')
Traceback (most recent call last):
  File "/usr/local/lib/python3.8/dist-packages/optuna/study/_optimize.py", line 196, in _run_trial
    value_or_values = func(trial)
  File "/tmp/ipykernel_7443/3357385256.py", line 14, in __call__
    model = PolynomialRegression(*args, **kwargs)
TypeError: PolynomialRegression() argument after * must be an iterable, not int
Trial 21 failed because of the following error: TypeError('PolynomialRegression() argument after * must be an iterable, not int')
Traceback (most recent call last):
  File "/usr/local/lib/python3.8/dist-packages/optuna/study/_optimize.py", line 196, in _run_trial
    value_or_values = func(trial)
  File "/tmp/ipykernel_7443/3357385256.py", line 14, in __call__
    model = PolynomialRegression(*args, **kwargs)
TypeError: PolynomialRegression() argument after * must be an iterable, not int
Trial 16 failed because of the following error: TypeError('PolynomialRegression() argument after * must be an iterable, not int')
Traceback (most recent call last):
  File "/usr/local/lib/python3.8/dist-packages/optuna/study/_optimize.py", line 196, in _run_trial
    value_or_values = func(trial)
  File "/tmp/ipykernel_7443/3357385256.py", line 14, in __call__
    model = PolynomialRegression(*args, **kwargs)
TypeError: PolynomialRegression() argument after * must be an iterable, not int
Trial 20 failed because of the following error: TypeError('PolynomialRegression() argument after * must be an iterable, not int')
Traceback (most recent call last):
  File "/usr/local/lib/python3.8/dist-packages/optuna/study/_optimize.py", line 196, in _run_trial
    value_or_values = func(trial)
  File "/tmp/ipykernel_7443/3357385256.py", line 14, in __call__
    model = PolynomialRegression(*args, **kwargs)
TypeError: PolynomialRegression() argument after * must be an iterable, not int
Trial 19 failed because of the following error: TypeError('PolynomialRegression() argument after * must be an iterable, not int')
Traceback (most recent call last):
  File "/usr/local/lib/python3.8/dist-packages/optuna/study/_optimize.py", line 196, in _run_trial
    value_or_values = func(trial)
  File "/tmp/ipykernel_7443/3357385256.py", line 14, in __call__
    model = PolynomialRegression(*args, **kwargs)
TypeError: PolynomialRegression() argument after * must be an iterable, not int
Trial 1 failed because of the following error: TypeError('PolynomialRegression() argument after * must be an iterable, not int')
Traceback (most recent call last):
  File "/usr/local/lib/python3.8/dist-packages/optuna/study/_optimize.py", line 196, in _run_trial
    value_or_values = func(trial)
  File "/tmp/ipykernel_7443/3357385256.py", line 14, in __call__
    model = PolynomialRegression(*args, **kwargs)
TypeError: PolynomialRegression() argument after * must be an iterable, not int
Trial 0 failed because of the following error: TypeError('PolynomialRegression() argument after * must be an iterable, not int')
Traceback (most recent call last):
  File "/usr/local/lib/python3.8/dist-packages/optuna/study/_optimize.py", line 196, in _run_trial
    value_or_values = func(trial)
  File "/tmp/ipykernel_7443/3357385256.py", line 14, in __call__
    model = PolynomialRegression(*args, **kwargs)
TypeError: PolynomialRegression() argument after * must be an iterable, not int
Trial 18 failed because of the following error: TypeError('PolynomialRegression() argument after * must be an iterable, not int')
Traceback (most recent call last):
  File "/usr/local/lib/python3.8/dist-packages/optuna/study/_optimize.py", line 196, in _run_trial
    value_or_values = func(trial)
  File "/tmp/ipykernel_7443/3357385256.py", line 14, in __call__
    model = PolynomialRegression(*args, **kwargs)
TypeError: PolynomialRegression() argument after * must be an iterable, not int
Trial 5 failed because of the following error: TypeError('PolynomialRegression() argument after * must be an iterable, not int')
Traceback (most recent call last):
  File "/usr/local/lib/python3.8/dist-packages/optuna/study/_optimize.py", line 196, in _run_trial
    value_or_values = func(trial)
  File "/tmp/ipykernel_7443/3357385256.py", line 14, in __call__
    model = PolynomialRegression(*args, **kwargs)
TypeError: PolynomialRegression() argument after * must be an iterable, not int
Trial 6 failed because of the following error: TypeError('PolynomialRegression() argument after * must be an iterable, not int')
Traceback (most recent call last):
  File "/usr/local/lib/python3.8/dist-packages/optuna/study/_optimize.py", line 196, in _run_trial
    value_or_values = func(trial)
  File "/tmp/ipykernel_7443/3357385256.py", line 14, in __call__
    model = PolynomialRegression(*args, **kwargs)
TypeError: PolynomialRegression() argument after * must be an iterable, not int
Trial 9 failed because of the following error: TypeError('PolynomialRegression() argument after * must be an iterable, not int')
Traceback (most recent call last):
  File "/usr/local/lib/python3.8/dist-packages/optuna/study/_optimize.py", line 196, in _run_trial
    value_or_values = func(trial)
  File "/tmp/ipykernel_7443/3357385256.py", line 14, in __call__
    model = PolynomialRegression(*args, **kwargs)
TypeError: PolynomialRegression() argument after * must be an iterable, not int
Trial 12 failed because of the following error: TypeError('PolynomialRegression() argument after * must be an iterable, not int')
Traceback (most recent call last):
  File "/usr/local/lib/python3.8/dist-packages/optuna/study/_optimize.py", line 196, in _run_trial
    value_or_values = func(trial)
  File "/tmp/ipykernel_7443/3357385256.py", line 14, in __call__
    model = PolynomialRegression(*args, **kwargs)
TypeError: PolynomialRegression() argument after * must be an iterable, not int
Trial 10 failed because of the following error: TypeError('PolynomialRegression() argument after * must be an iterable, not int')
Traceback (most recent call last):
  File "/usr/local/lib/python3.8/dist-packages/optuna/study/_optimize.py", line 196, in _run_trial
    value_or_values = func(trial)
  File "/tmp/ipykernel_7443/3357385256.py", line 14, in __call__
    model = PolynomialRegression(*args, **kwargs)
TypeError: PolynomialRegression() argument after * must be an iterable, not int
Trial 11 failed because of the following error: TypeError('PolynomialRegression() argument after * must be an iterable, not int')
Traceback (most recent call last):
  File "/usr/local/lib/python3.8/dist-packages/optuna/study/_optimize.py", line 196, in _run_trial
    value_or_values = func(trial)
  File "/tmp/ipykernel_7443/3357385256.py", line 14, in __call__
    model = PolynomialRegression(*args, **kwargs)
TypeError: PolynomialRegression() argument after * must be an iterable, not int
Trial 23 failed because of the following error: TypeError('PolynomialRegression() argument after * must be an iterable, not int')
Traceback (most recent call last):
  File "/usr/local/lib/python3.8/dist-packages/optuna/study/_optimize.py", line 196, in _run_trial
    value_or_values = func(trial)
  File "/tmp/ipykernel_7443/3357385256.py", line 14, in __call__
    model = PolynomialRegression(*args, **kwargs)
TypeError: PolynomialRegression() argument after * must be an iterable, not int
Trial 13 failed because of the following error: TypeError('PolynomialRegression() argument after * must be an iterable, not int')
Traceback (most recent call last):
  File "/usr/local/lib/python3.8/dist-packages/optuna/study/_optimize.py", line 196, in _run_trial
    value_or_values = func(trial)
  File "/tmp/ipykernel_7443/3357385256.py", line 14, in __call__
    model = PolynomialRegression(*args, **kwargs)
TypeError: PolynomialRegression() argument after * must be an iterable, not int
Trial 7 failed because of the following error: TypeError('PolynomialRegression() argument after * must be an iterable, not int')
Traceback (most recent call last):
  File "/usr/local/lib/python3.8/dist-packages/optuna/study/_optimize.py", line 196, in _run_trial
    value_or_values = func(trial)
  File "/tmp/ipykernel_7443/3357385256.py", line 14, in __call__
    model = PolynomialRegression(*args, **kwargs)
TypeError: PolynomialRegression() argument after * must be an iterable, not int
Trial 15 failed because of the following error: TypeError('PolynomialRegression() argument after * must be an iterable, not int')
Traceback (most recent call last):
  File "/usr/local/lib/python3.8/dist-packages/optuna/study/_optimize.py", line 196, in _run_trial
    value_or_values = func(trial)
  File "/tmp/ipykernel_7443/3357385256.py", line 14, in __call__
    model = PolynomialRegression(*args, **kwargs)
TypeError: PolynomialRegression() argument after * must be an iterable, not int
Trial 3 failed because of the following error: TypeError('PolynomialRegression() argument after * must be an iterable, not int')
Traceback (most recent call last):
  File "/usr/local/lib/python3.8/dist-packages/optuna/study/_optimize.py", line 196, in _run_trial
    value_or_values = func(trial)
  File "/tmp/ipykernel_7443/3357385256.py", line 14, in __call__
    model = PolynomialRegression(*args, **kwargs)
TypeError: PolynomialRegression() argument after * must be an iterable, not int
Trial 8 failed because of the following error: TypeError('PolynomialRegression() argument after * must be an iterable, not int')
Traceback (most recent call last):
  File "/usr/local/lib/python3.8/dist-packages/optuna/study/_optimize.py", line 196, in _run_trial
    value_or_values = func(trial)
  File "/tmp/ipykernel_7443/3357385256.py", line 14, in __call__
    model = PolynomialRegression(*args, **kwargs)
TypeError: PolynomialRegression() argument after * must be an iterable, not int
Trial 17 failed because of the following error: TypeError('PolynomialRegression() argument after * must be an iterable, not int')
Traceback (most recent call last):
  File "/usr/local/lib/python3.8/dist-packages/optuna/study/_optimize.py", line 196, in _run_trial
    value_or_values = func(trial)
  File "/tmp/ipykernel_7443/3357385256.py", line 14, in __call__
    model = PolynomialRegression(*args, **kwargs)
TypeError: PolynomialRegression() argument after * must be an iterable, not int
A new study created in RDB with name: Poly_Linear_9238
Trial 3 failed because of the following error: TypeError("suggest_int() missing 1 required positional argument: 'high'")
Traceback (most recent call last):
  File "/usr/local/lib/python3.8/dist-packages/optuna/study/_optimize.py", line 196, in _run_trial
    value_or_values = func(trial)
  File "/tmp/ipykernel_7443/3653713586.py", line 8, in __call__
    args = trial.suggest_int(1, 100)
TypeError: suggest_int() missing 1 required positional argument: 'high'
Trial 7 failed because of the following error: TypeError("suggest_int() missing 1 required positional argument: 'high'")
Traceback (most recent call last):
  File "/usr/local/lib/python3.8/dist-packages/optuna/study/_optimize.py", line 196, in _run_trial
    value_or_values = func(trial)
  File "/tmp/ipykernel_7443/3653713586.py", line 8, in __call__
    args = trial.suggest_int(1, 100)
TypeError: suggest_int() missing 1 required positional argument: 'high'
Trial 11 failed because of the following error: TypeError("suggest_int() missing 1 required positional argument: 'high'")
Traceback (most recent call last):
  File "/usr/local/lib/python3.8/dist-packages/optuna/study/_optimize.py", line 196, in _run_trial
    value_or_values = func(trial)
  File "/tmp/ipykernel_7443/3653713586.py", line 8, in __call__
    args = trial.suggest_int(1, 100)
TypeError: suggest_int() missing 1 required positional argument: 'high'
Trial 18 failed because of the following error: TypeError("suggest_int() missing 1 required positional argument: 'high'")
Traceback (most recent call last):
  File "/usr/local/lib/python3.8/dist-packages/optuna/study/_optimize.py", line 196, in _run_trial
    value_or_values = func(trial)
  File "/tmp/ipykernel_7443/3653713586.py", line 8, in __call__
    args = trial.suggest_int(1, 100)
TypeError: suggest_int() missing 1 required positional argument: 'high'
Trial 1 failed because of the following error: TypeError("suggest_int() missing 1 required positional argument: 'high'")
Traceback (most recent call last):
  File "/usr/local/lib/python3.8/dist-packages/optuna/study/_optimize.py", line 196, in _run_trial
    value_or_values = func(trial)
  File "/tmp/ipykernel_7443/3653713586.py", line 8, in __call__
    args = trial.suggest_int(1, 100)
TypeError: suggest_int() missing 1 required positional argument: 'high'
Trial 14 failed because of the following error: TypeError("suggest_int() missing 1 required positional argument: 'high'")
Traceback (most recent call last):
  File "/usr/local/lib/python3.8/dist-packages/optuna/study/_optimize.py", line 196, in _run_trial
    value_or_values = func(trial)
  File "/tmp/ipykernel_7443/3653713586.py", line 8, in __call__
    args = trial.suggest_int(1, 100)
TypeError: suggest_int() missing 1 required positional argument: 'high'
Trial 12 failed because of the following error: TypeError("suggest_int() missing 1 required positional argument: 'high'")
Traceback (most recent call last):
  File "/usr/local/lib/python3.8/dist-packages/optuna/study/_optimize.py", line 196, in _run_trial
    value_or_values = func(trial)
  File "/tmp/ipykernel_7443/3653713586.py", line 8, in __call__
    args = trial.suggest_int(1, 100)
TypeError: suggest_int() missing 1 required positional argument: 'high'
Trial 6 failed because of the following error: TypeError("suggest_int() missing 1 required positional argument: 'high'")
Traceback (most recent call last):
  File "/usr/local/lib/python3.8/dist-packages/optuna/study/_optimize.py", line 196, in _run_trial
    value_or_values = func(trial)
  File "/tmp/ipykernel_7443/3653713586.py", line 8, in __call__
    args = trial.suggest_int(1, 100)
TypeError: suggest_int() missing 1 required positional argument: 'high'
Trial 8 failed because of the following error: TypeError("suggest_int() missing 1 required positional argument: 'high'")
Traceback (most recent call last):
  File "/usr/local/lib/python3.8/dist-packages/optuna/study/_optimize.py", line 196, in _run_trial
    value_or_values = func(trial)
  File "/tmp/ipykernel_7443/3653713586.py", line 8, in __call__
    args = trial.suggest_int(1, 100)
TypeError: suggest_int() missing 1 required positional argument: 'high'
Trial 2 failed because of the following error: TypeError("suggest_int() missing 1 required positional argument: 'high'")
Traceback (most recent call last):
  File "/usr/local/lib/python3.8/dist-packages/optuna/study/_optimize.py", line 196, in _run_trial
    value_or_values = func(trial)
  File "/tmp/ipykernel_7443/3653713586.py", line 8, in __call__
    args = trial.suggest_int(1, 100)
TypeError: suggest_int() missing 1 required positional argument: 'high'
Trial 13 failed because of the following error: TypeError("suggest_int() missing 1 required positional argument: 'high'")
Traceback (most recent call last):
  File "/usr/local/lib/python3.8/dist-packages/optuna/study/_optimize.py", line 196, in _run_trial
    value_or_values = func(trial)
  File "/tmp/ipykernel_7443/3653713586.py", line 8, in __call__
    args = trial.suggest_int(1, 100)
TypeError: suggest_int() missing 1 required positional argument: 'high'
Trial 15 failed because of the following error: TypeError("suggest_int() missing 1 required positional argument: 'high'")
Traceback (most recent call last):
  File "/usr/local/lib/python3.8/dist-packages/optuna/study/_optimize.py", line 196, in _run_trial
    value_or_values = func(trial)
  File "/tmp/ipykernel_7443/3653713586.py", line 8, in __call__
    args = trial.suggest_int(1, 100)
TypeError: suggest_int() missing 1 required positional argument: 'high'
Trial 0 failed because of the following error: TypeError("suggest_int() missing 1 required positional argument: 'high'")
Traceback (most recent call last):
  File "/usr/local/lib/python3.8/dist-packages/optuna/study/_optimize.py", line 196, in _run_trial
    value_or_values = func(trial)
  File "/tmp/ipykernel_7443/3653713586.py", line 8, in __call__
    args = trial.suggest_int(1, 100)
TypeError: suggest_int() missing 1 required positional argument: 'high'
Trial 5 failed because of the following error: TypeError("suggest_int() missing 1 required positional argument: 'high'")
Traceback (most recent call last):
  File "/usr/local/lib/python3.8/dist-packages/optuna/study/_optimize.py", line 196, in _run_trial
    value_or_values = func(trial)
  File "/tmp/ipykernel_7443/3653713586.py", line 8, in __call__
    args = trial.suggest_int(1, 100)
TypeError: suggest_int() missing 1 required positional argument: 'high'
Trial 16 failed because of the following error: TypeError("suggest_int() missing 1 required positional argument: 'high'")
Traceback (most recent call last):
  File "/usr/local/lib/python3.8/dist-packages/optuna/study/_optimize.py", line 196, in _run_trial
    value_or_values = func(trial)
  File "/tmp/ipykernel_7443/3653713586.py", line 8, in __call__
    args = trial.suggest_int(1, 100)
TypeError: suggest_int() missing 1 required positional argument: 'high'
Trial 17 failed because of the following error: TypeError("suggest_int() missing 1 required positional argument: 'high'")
Traceback (most recent call last):
  File "/usr/local/lib/python3.8/dist-packages/optuna/study/_optimize.py", line 196, in _run_trial
    value_or_values = func(trial)
  File "/tmp/ipykernel_7443/3653713586.py", line 8, in __call__
    args = trial.suggest_int(1, 100)
TypeError: suggest_int() missing 1 required positional argument: 'high'
Trial 22 failed because of the following error: TypeError("suggest_int() missing 1 required positional argument: 'high'")
Traceback (most recent call last):
  File "/usr/local/lib/python3.8/dist-packages/optuna/study/_optimize.py", line 196, in _run_trial
    value_or_values = func(trial)
  File "/tmp/ipykernel_7443/3653713586.py", line 8, in __call__
    args = trial.suggest_int(1, 100)
TypeError: suggest_int() missing 1 required positional argument: 'high'
Trial 9 failed because of the following error: TypeError("suggest_int() missing 1 required positional argument: 'high'")
Traceback (most recent call last):
  File "/usr/local/lib/python3.8/dist-packages/optuna/study/_optimize.py", line 196, in _run_trial
    value_or_values = func(trial)
  File "/tmp/ipykernel_7443/3653713586.py", line 8, in __call__
    args = trial.suggest_int(1, 100)
TypeError: suggest_int() missing 1 required positional argument: 'high'
Trial 21 failed because of the following error: TypeError("suggest_int() missing 1 required positional argument: 'high'")
Traceback (most recent call last):
  File "/usr/local/lib/python3.8/dist-packages/optuna/study/_optimize.py", line 196, in _run_trial
    value_or_values = func(trial)
  File "/tmp/ipykernel_7443/3653713586.py", line 8, in __call__
    args = trial.suggest_int(1, 100)
TypeError: suggest_int() missing 1 required positional argument: 'high'
Trial 19 failed because of the following error: TypeError("suggest_int() missing 1 required positional argument: 'high'")
Traceback (most recent call last):
  File "/usr/local/lib/python3.8/dist-packages/optuna/study/_optimize.py", line 196, in _run_trial
    value_or_values = func(trial)
  File "/tmp/ipykernel_7443/3653713586.py", line 8, in __call__
    args = trial.suggest_int(1, 100)
TypeError: suggest_int() missing 1 required positional argument: 'high'
Trial 10 failed because of the following error: TypeError("suggest_int() missing 1 required positional argument: 'high'")
Traceback (most recent call last):
  File "/usr/local/lib/python3.8/dist-packages/optuna/study/_optimize.py", line 196, in _run_trial
    value_or_values = func(trial)
  File "/tmp/ipykernel_7443/3653713586.py", line 8, in __call__
    args = trial.suggest_int(1, 100)
TypeError: suggest_int() missing 1 required positional argument: 'high'
Trial 20 failed because of the following error: TypeError("suggest_int() missing 1 required positional argument: 'high'")
Traceback (most recent call last):
  File "/usr/local/lib/python3.8/dist-packages/optuna/study/_optimize.py", line 196, in _run_trial
    value_or_values = func(trial)
  File "/tmp/ipykernel_7443/3653713586.py", line 8, in __call__
    args = trial.suggest_int(1, 100)
TypeError: suggest_int() missing 1 required positional argument: 'high'
Trial 4 failed because of the following error: TypeError("suggest_int() missing 1 required positional argument: 'high'")
Traceback (most recent call last):
  File "/usr/local/lib/python3.8/dist-packages/optuna/study/_optimize.py", line 196, in _run_trial
    value_or_values = func(trial)
  File "/tmp/ipykernel_7443/3653713586.py", line 8, in __call__
    args = trial.suggest_int(1, 100)
TypeError: suggest_int() missing 1 required positional argument: 'high'
Trial 23 failed because of the following error: TypeError("suggest_int() missing 1 required positional argument: 'high'")
Traceback (most recent call last):
  File "/usr/local/lib/python3.8/dist-packages/optuna/study/_optimize.py", line 196, in _run_trial
    value_or_values = func(trial)
  File "/tmp/ipykernel_7443/3653713586.py", line 8, in __call__
    args = trial.suggest_int(1, 100)
TypeError: suggest_int() missing 1 required positional argument: 'high'
A new study created in RDB with name: Poly_Linear_936
Trial 7 failed because of the following error: TypeError('PolynomialRegression() argument after * must be an iterable, not int')
Traceback (most recent call last):
  File "/usr/local/lib/python3.8/dist-packages/optuna/study/_optimize.py", line 196, in _run_trial
    value_or_values = func(trial)
  File "/tmp/ipykernel_7443/3357385256.py", line 14, in __call__
    model = PolynomialRegression(*args, **kwargs)
TypeError: PolynomialRegression() argument after * must be an iterable, not int
Trial 12 failed because of the following error: TypeError('PolynomialRegression() argument after * must be an iterable, not int')
Traceback (most recent call last):
  File "/usr/local/lib/python3.8/dist-packages/optuna/study/_optimize.py", line 196, in _run_trial
    value_or_values = func(trial)
  File "/tmp/ipykernel_7443/3357385256.py", line 14, in __call__
    model = PolynomialRegression(*args, **kwargs)
TypeError: PolynomialRegression() argument after * must be an iterable, not int
Trial 16 failed because of the following error: TypeError('PolynomialRegression() argument after * must be an iterable, not int')
Traceback (most recent call last):
  File "/usr/local/lib/python3.8/dist-packages/optuna/study/_optimize.py", line 196, in _run_trial
    value_or_values = func(trial)
  File "/tmp/ipykernel_7443/3357385256.py", line 14, in __call__
    model = PolynomialRegression(*args, **kwargs)
TypeError: PolynomialRegression() argument after * must be an iterable, not int
Trial 19 failed because of the following error: TypeError('PolynomialRegression() argument after * must be an iterable, not int')
Traceback (most recent call last):
  File "/usr/local/lib/python3.8/dist-packages/optuna/study/_optimize.py", line 196, in _run_trial
    value_or_values = func(trial)
  File "/tmp/ipykernel_7443/3357385256.py", line 14, in __call__
    model = PolynomialRegression(*args, **kwargs)
TypeError: PolynomialRegression() argument after * must be an iterable, not int
Trial 10 failed because of the following error: TypeError('PolynomialRegression() argument after * must be an iterable, not int')
Traceback (most recent call last):
  File "/usr/local/lib/python3.8/dist-packages/optuna/study/_optimize.py", line 196, in _run_trial
    value_or_values = func(trial)
  File "/tmp/ipykernel_7443/3357385256.py", line 14, in __call__
    model = PolynomialRegression(*args, **kwargs)
TypeError: PolynomialRegression() argument after * must be an iterable, not int
Trial 1 failed because of the following error: TypeError('PolynomialRegression() argument after * must be an iterable, not int')
Traceback (most recent call last):
  File "/usr/local/lib/python3.8/dist-packages/optuna/study/_optimize.py", line 196, in _run_trial
    value_or_values = func(trial)
  File "/tmp/ipykernel_7443/3357385256.py", line 14, in __call__
    model = PolynomialRegression(*args, **kwargs)
TypeError: PolynomialRegression() argument after * must be an iterable, not int
Trial 8 failed because of the following error: TypeError('PolynomialRegression() argument after * must be an iterable, not int')
Traceback (most recent call last):
  File "/usr/local/lib/python3.8/dist-packages/optuna/study/_optimize.py", line 196, in _run_trial
    value_or_values = func(trial)
  File "/tmp/ipykernel_7443/3357385256.py", line 14, in __call__
    model = PolynomialRegression(*args, **kwargs)
TypeError: PolynomialRegression() argument after * must be an iterable, not int
Trial 0 failed because of the following error: TypeError('PolynomialRegression() argument after * must be an iterable, not int')
Traceback (most recent call last):
  File "/usr/local/lib/python3.8/dist-packages/optuna/study/_optimize.py", line 196, in _run_trial
    value_or_values = func(trial)
  File "/tmp/ipykernel_7443/3357385256.py", line 14, in __call__
    model = PolynomialRegression(*args, **kwargs)
TypeError: PolynomialRegression() argument after * must be an iterable, not int
Trial 13 failed because of the following error: TypeError('PolynomialRegression() argument after * must be an iterable, not int')
Traceback (most recent call last):
  File "/usr/local/lib/python3.8/dist-packages/optuna/study/_optimize.py", line 196, in _run_trial
    value_or_values = func(trial)
  File "/tmp/ipykernel_7443/3357385256.py", line 14, in __call__
    model = PolynomialRegression(*args, **kwargs)
TypeError: PolynomialRegression() argument after * must be an iterable, not int
Trial 2 failed because of the following error: TypeError('PolynomialRegression() argument after * must be an iterable, not int')
Traceback (most recent call last):
  File "/usr/local/lib/python3.8/dist-packages/optuna/study/_optimize.py", line 196, in _run_trial
    value_or_values = func(trial)
  File "/tmp/ipykernel_7443/3357385256.py", line 14, in __call__
    model = PolynomialRegression(*args, **kwargs)
TypeError: PolynomialRegression() argument after * must be an iterable, not int
Trial 5 failed because of the following error: TypeError('PolynomialRegression() argument after * must be an iterable, not int')
Traceback (most recent call last):
  File "/usr/local/lib/python3.8/dist-packages/optuna/study/_optimize.py", line 196, in _run_trial
    value_or_values = func(trial)
  File "/tmp/ipykernel_7443/3357385256.py", line 14, in __call__
    model = PolynomialRegression(*args, **kwargs)
TypeError: PolynomialRegression() argument after * must be an iterable, not int
Trial 4 failed because of the following error: TypeError('PolynomialRegression() argument after * must be an iterable, not int')
Traceback (most recent call last):
  File "/usr/local/lib/python3.8/dist-packages/optuna/study/_optimize.py", line 196, in _run_trial
    value_or_values = func(trial)
  File "/tmp/ipykernel_7443/3357385256.py", line 14, in __call__
    model = PolynomialRegression(*args, **kwargs)
TypeError: PolynomialRegression() argument after * must be an iterable, not int
Trial 6 failed because of the following error: TypeError('PolynomialRegression() argument after * must be an iterable, not int')
Traceback (most recent call last):
  File "/usr/local/lib/python3.8/dist-packages/optuna/study/_optimize.py", line 196, in _run_trial
    value_or_values = func(trial)
  File "/tmp/ipykernel_7443/3357385256.py", line 14, in __call__
    model = PolynomialRegression(*args, **kwargs)
TypeError: PolynomialRegression() argument after * must be an iterable, not int
Trial 20 failed because of the following error: TypeError('PolynomialRegression() argument after * must be an iterable, not int')
Traceback (most recent call last):
  File "/usr/local/lib/python3.8/dist-packages/optuna/study/_optimize.py", line 196, in _run_trial
    value_or_values = func(trial)
  File "/tmp/ipykernel_7443/3357385256.py", line 14, in __call__
    model = PolynomialRegression(*args, **kwargs)
TypeError: PolynomialRegression() argument after * must be an iterable, not int
Trial 11 failed because of the following error: TypeError('PolynomialRegression() argument after * must be an iterable, not int')
Traceback (most recent call last):
  File "/usr/local/lib/python3.8/dist-packages/optuna/study/_optimize.py", line 196, in _run_trial
    value_or_values = func(trial)
  File "/tmp/ipykernel_7443/3357385256.py", line 14, in __call__
    model = PolynomialRegression(*args, **kwargs)
TypeError: PolynomialRegression() argument after * must be an iterable, not int
Trial 14 failed because of the following error: TypeError('PolynomialRegression() argument after * must be an iterable, not int')
Traceback (most recent call last):
  File "/usr/local/lib/python3.8/dist-packages/optuna/study/_optimize.py", line 196, in _run_trial
    value_or_values = func(trial)
  File "/tmp/ipykernel_7443/3357385256.py", line 14, in __call__
    model = PolynomialRegression(*args, **kwargs)
TypeError: PolynomialRegression() argument after * must be an iterable, not int
Trial 17 failed because of the following error: TypeError('PolynomialRegression() argument after * must be an iterable, not int')
Traceback (most recent call last):
  File "/usr/local/lib/python3.8/dist-packages/optuna/study/_optimize.py", line 196, in _run_trial
    value_or_values = func(trial)
  File "/tmp/ipykernel_7443/3357385256.py", line 14, in __call__
    model = PolynomialRegression(*args, **kwargs)
TypeError: PolynomialRegression() argument after * must be an iterable, not int
Trial 15 failed because of the following error: TypeError('PolynomialRegression() argument after * must be an iterable, not int')
Traceback (most recent call last):
  File "/usr/local/lib/python3.8/dist-packages/optuna/study/_optimize.py", line 196, in _run_trial
    value_or_values = func(trial)
  File "/tmp/ipykernel_7443/3357385256.py", line 14, in __call__
    model = PolynomialRegression(*args, **kwargs)
TypeError: PolynomialRegression() argument after * must be an iterable, not int
Trial 3 failed because of the following error: TypeError('PolynomialRegression() argument after * must be an iterable, not int')
Traceback (most recent call last):
  File "/usr/local/lib/python3.8/dist-packages/optuna/study/_optimize.py", line 196, in _run_trial
    value_or_values = func(trial)
  File "/tmp/ipykernel_7443/3357385256.py", line 14, in __call__
    model = PolynomialRegression(*args, **kwargs)
TypeError: PolynomialRegression() argument after * must be an iterable, not int
Trial 9 failed because of the following error: TypeError('PolynomialRegression() argument after * must be an iterable, not int')
Traceback (most recent call last):
  File "/usr/local/lib/python3.8/dist-packages/optuna/study/_optimize.py", line 196, in _run_trial
    value_or_values = func(trial)
  File "/tmp/ipykernel_7443/3357385256.py", line 14, in __call__
    model = PolynomialRegression(*args, **kwargs)
TypeError: PolynomialRegression() argument after * must be an iterable, not int
Trial 23 failed because of the following error: TypeError('PolynomialRegression() argument after * must be an iterable, not int')
Traceback (most recent call last):
  File "/usr/local/lib/python3.8/dist-packages/optuna/study/_optimize.py", line 196, in _run_trial
    value_or_values = func(trial)
  File "/tmp/ipykernel_7443/3357385256.py", line 14, in __call__
    model = PolynomialRegression(*args, **kwargs)
TypeError: PolynomialRegression() argument after * must be an iterable, not int
Trial 18 failed because of the following error: TypeError('PolynomialRegression() argument after * must be an iterable, not int')
Traceback (most recent call last):
  File "/usr/local/lib/python3.8/dist-packages/optuna/study/_optimize.py", line 196, in _run_trial
    value_or_values = func(trial)
  File "/tmp/ipykernel_7443/3357385256.py", line 14, in __call__
    model = PolynomialRegression(*args, **kwargs)
TypeError: PolynomialRegression() argument after * must be an iterable, not int
Trial 22 failed because of the following error: TypeError('PolynomialRegression() argument after * must be an iterable, not int')
Traceback (most recent call last):
  File "/usr/local/lib/python3.8/dist-packages/optuna/study/_optimize.py", line 196, in _run_trial
    value_or_values = func(trial)
  File "/tmp/ipykernel_7443/3357385256.py", line 14, in __call__
    model = PolynomialRegression(*args, **kwargs)
TypeError: PolynomialRegression() argument after * must be an iterable, not int
Trial 21 failed because of the following error: TypeError('PolynomialRegression() argument after * must be an iterable, not int')
Traceback (most recent call last):
  File "/usr/local/lib/python3.8/dist-packages/optuna/study/_optimize.py", line 196, in _run_trial
    value_or_values = func(trial)
  File "/tmp/ipykernel_7443/3357385256.py", line 14, in __call__
    model = PolynomialRegression(*args, **kwargs)
TypeError: PolynomialRegression() argument after * must be an iterable, not int
A new study created in RDB with name: Poly_Linear_9645
Trial 9 failed because of the following error: TypeError("__init__() got an unexpected keyword argument 'degree'")
Traceback (most recent call last):
  File "/usr/local/lib/python3.8/dist-packages/optuna/study/_optimize.py", line 196, in _run_trial
    value_or_values = func(trial)
  File "/tmp/ipykernel_7443/1910424133.py", line 18, in __call__
    model = PolynomialRegression(**params1, **params2)
  File "/tmp/ipykernel_7443/827320159.py", line 2, in PolynomialRegression
    return make_pipeline(preprocessing.PolynomialFeatures(*args), LinearRegression(**kwargs))
TypeError: __init__() got an unexpected keyword argument 'degree'
Trial 10 failed because of the following error: TypeError("__init__() got an unexpected keyword argument 'degree'")
Traceback (most recent call last):
  File "/usr/local/lib/python3.8/dist-packages/optuna/study/_optimize.py", line 196, in _run_trial
    value_or_values = func(trial)
  File "/tmp/ipykernel_7443/1910424133.py", line 18, in __call__
    model = PolynomialRegression(**params1, **params2)
  File "/tmp/ipykernel_7443/827320159.py", line 2, in PolynomialRegression
    return make_pipeline(preprocessing.PolynomialFeatures(*args), LinearRegression(**kwargs))
TypeError: __init__() got an unexpected keyword argument 'degree'
Trial 19 failed because of the following error: TypeError("__init__() got an unexpected keyword argument 'degree'")
Traceback (most recent call last):
  File "/usr/local/lib/python3.8/dist-packages/optuna/study/_optimize.py", line 196, in _run_trial
    value_or_values = func(trial)
  File "/tmp/ipykernel_7443/1910424133.py", line 18, in __call__
    model = PolynomialRegression(**params1, **params2)
  File "/tmp/ipykernel_7443/827320159.py", line 2, in PolynomialRegression
    return make_pipeline(preprocessing.PolynomialFeatures(*args), LinearRegression(**kwargs))
TypeError: __init__() got an unexpected keyword argument 'degree'
Trial 5 failed because of the following error: TypeError("__init__() got an unexpected keyword argument 'degree'")
Traceback (most recent call last):
  File "/usr/local/lib/python3.8/dist-packages/optuna/study/_optimize.py", line 196, in _run_trial
    value_or_values = func(trial)
  File "/tmp/ipykernel_7443/1910424133.py", line 18, in __call__
    model = PolynomialRegression(**params1, **params2)
  File "/tmp/ipykernel_7443/827320159.py", line 2, in PolynomialRegression
    return make_pipeline(preprocessing.PolynomialFeatures(*args), LinearRegression(**kwargs))
TypeError: __init__() got an unexpected keyword argument 'degree'
Trial 18 failed because of the following error: TypeError("__init__() got an unexpected keyword argument 'degree'")
Traceback (most recent call last):
  File "/usr/local/lib/python3.8/dist-packages/optuna/study/_optimize.py", line 196, in _run_trial
    value_or_values = func(trial)
  File "/tmp/ipykernel_7443/1910424133.py", line 18, in __call__
    model = PolynomialRegression(**params1, **params2)
  File "/tmp/ipykernel_7443/827320159.py", line 2, in PolynomialRegression
    return make_pipeline(preprocessing.PolynomialFeatures(*args), LinearRegression(**kwargs))
TypeError: __init__() got an unexpected keyword argument 'degree'
Trial 2 failed because of the following error: TypeError("__init__() got an unexpected keyword argument 'degree'")
Traceback (most recent call last):
  File "/usr/local/lib/python3.8/dist-packages/optuna/study/_optimize.py", line 196, in _run_trial
    value_or_values = func(trial)
  File "/tmp/ipykernel_7443/1910424133.py", line 18, in __call__
    model = PolynomialRegression(**params1, **params2)
  File "/tmp/ipykernel_7443/827320159.py", line 2, in PolynomialRegression
    return make_pipeline(preprocessing.PolynomialFeatures(*args), LinearRegression(**kwargs))
TypeError: __init__() got an unexpected keyword argument 'degree'
Trial 3 failed because of the following error: TypeError("__init__() got an unexpected keyword argument 'degree'")
Traceback (most recent call last):
  File "/usr/local/lib/python3.8/dist-packages/optuna/study/_optimize.py", line 196, in _run_trial
    value_or_values = func(trial)
  File "/tmp/ipykernel_7443/1910424133.py", line 18, in __call__
    model = PolynomialRegression(**params1, **params2)
  File "/tmp/ipykernel_7443/827320159.py", line 2, in PolynomialRegression
    return make_pipeline(preprocessing.PolynomialFeatures(*args), LinearRegression(**kwargs))
TypeError: __init__() got an unexpected keyword argument 'degree'
Trial 22 failed because of the following error: TypeError("__init__() got an unexpected keyword argument 'degree'")
Traceback (most recent call last):
  File "/usr/local/lib/python3.8/dist-packages/optuna/study/_optimize.py", line 196, in _run_trial
    value_or_values = func(trial)
  File "/tmp/ipykernel_7443/1910424133.py", line 18, in __call__
    model = PolynomialRegression(**params1, **params2)
  File "/tmp/ipykernel_7443/827320159.py", line 2, in PolynomialRegression
    return make_pipeline(preprocessing.PolynomialFeatures(*args), LinearRegression(**kwargs))
TypeError: __init__() got an unexpected keyword argument 'degree'
Trial 4 failed because of the following error: TypeError("__init__() got an unexpected keyword argument 'degree'")
Traceback (most recent call last):
  File "/usr/local/lib/python3.8/dist-packages/optuna/study/_optimize.py", line 196, in _run_trial
    value_or_values = func(trial)
  File "/tmp/ipykernel_7443/1910424133.py", line 18, in __call__
    model = PolynomialRegression(**params1, **params2)
  File "/tmp/ipykernel_7443/827320159.py", line 2, in PolynomialRegression
    return make_pipeline(preprocessing.PolynomialFeatures(*args), LinearRegression(**kwargs))
TypeError: __init__() got an unexpected keyword argument 'degree'
Trial 11 failed because of the following error: TypeError("__init__() got an unexpected keyword argument 'degree'")
Traceback (most recent call last):
  File "/usr/local/lib/python3.8/dist-packages/optuna/study/_optimize.py", line 196, in _run_trial
    value_or_values = func(trial)
  File "/tmp/ipykernel_7443/1910424133.py", line 18, in __call__
    model = PolynomialRegression(**params1, **params2)
  File "/tmp/ipykernel_7443/827320159.py", line 2, in PolynomialRegression
    return make_pipeline(preprocessing.PolynomialFeatures(*args), LinearRegression(**kwargs))
TypeError: __init__() got an unexpected keyword argument 'degree'
Trial 0 failed because of the following error: TypeError("__init__() got an unexpected keyword argument 'degree'")
Traceback (most recent call last):
  File "/usr/local/lib/python3.8/dist-packages/optuna/study/_optimize.py", line 196, in _run_trial
    value_or_values = func(trial)
  File "/tmp/ipykernel_7443/1910424133.py", line 18, in __call__
    model = PolynomialRegression(**params1, **params2)
  File "/tmp/ipykernel_7443/827320159.py", line 2, in PolynomialRegression
    return make_pipeline(preprocessing.PolynomialFeatures(*args), LinearRegression(**kwargs))
TypeError: __init__() got an unexpected keyword argument 'degree'
Trial 14 failed because of the following error: TypeError("__init__() got an unexpected keyword argument 'degree'")
Traceback (most recent call last):
  File "/usr/local/lib/python3.8/dist-packages/optuna/study/_optimize.py", line 196, in _run_trial
    value_or_values = func(trial)
  File "/tmp/ipykernel_7443/1910424133.py", line 18, in __call__
    model = PolynomialRegression(**params1, **params2)
  File "/tmp/ipykernel_7443/827320159.py", line 2, in PolynomialRegression
    return make_pipeline(preprocessing.PolynomialFeatures(*args), LinearRegression(**kwargs))
TypeError: __init__() got an unexpected keyword argument 'degree'
Trial 17 failed because of the following error: TypeError("__init__() got an unexpected keyword argument 'degree'")
Traceback (most recent call last):
  File "/usr/local/lib/python3.8/dist-packages/optuna/study/_optimize.py", line 196, in _run_trial
    value_or_values = func(trial)
  File "/tmp/ipykernel_7443/1910424133.py", line 18, in __call__
    model = PolynomialRegression(**params1, **params2)
  File "/tmp/ipykernel_7443/827320159.py", line 2, in PolynomialRegression
    return make_pipeline(preprocessing.PolynomialFeatures(*args), LinearRegression(**kwargs))
TypeError: __init__() got an unexpected keyword argument 'degree'
Trial 8 failed because of the following error: TypeError("__init__() got an unexpected keyword argument 'degree'")
Traceback (most recent call last):
  File "/usr/local/lib/python3.8/dist-packages/optuna/study/_optimize.py", line 196, in _run_trial
    value_or_values = func(trial)
  File "/tmp/ipykernel_7443/1910424133.py", line 18, in __call__
    model = PolynomialRegression(**params1, **params2)
  File "/tmp/ipykernel_7443/827320159.py", line 2, in PolynomialRegression
    return make_pipeline(preprocessing.PolynomialFeatures(*args), LinearRegression(**kwargs))
TypeError: __init__() got an unexpected keyword argument 'degree'
Trial 7 failed because of the following error: TypeError("__init__() got an unexpected keyword argument 'degree'")
Traceback (most recent call last):
  File "/usr/local/lib/python3.8/dist-packages/optuna/study/_optimize.py", line 196, in _run_trial
    value_or_values = func(trial)
  File "/tmp/ipykernel_7443/1910424133.py", line 18, in __call__
    model = PolynomialRegression(**params1, **params2)
  File "/tmp/ipykernel_7443/827320159.py", line 2, in PolynomialRegression
    return make_pipeline(preprocessing.PolynomialFeatures(*args), LinearRegression(**kwargs))
TypeError: __init__() got an unexpected keyword argument 'degree'
Trial 6 failed because of the following error: TypeError("__init__() got an unexpected keyword argument 'degree'")
Traceback (most recent call last):
  File "/usr/local/lib/python3.8/dist-packages/optuna/study/_optimize.py", line 196, in _run_trial
    value_or_values = func(trial)
  File "/tmp/ipykernel_7443/1910424133.py", line 18, in __call__
    model = PolynomialRegression(**params1, **params2)
  File "/tmp/ipykernel_7443/827320159.py", line 2, in PolynomialRegression
    return make_pipeline(preprocessing.PolynomialFeatures(*args), LinearRegression(**kwargs))
TypeError: __init__() got an unexpected keyword argument 'degree'
Trial 1 failed because of the following error: TypeError("__init__() got an unexpected keyword argument 'degree'")
Traceback (most recent call last):
  File "/usr/local/lib/python3.8/dist-packages/optuna/study/_optimize.py", line 196, in _run_trial
    value_or_values = func(trial)
  File "/tmp/ipykernel_7443/1910424133.py", line 18, in __call__
    model = PolynomialRegression(**params1, **params2)
  File "/tmp/ipykernel_7443/827320159.py", line 2, in PolynomialRegression
    return make_pipeline(preprocessing.PolynomialFeatures(*args), LinearRegression(**kwargs))
TypeError: __init__() got an unexpected keyword argument 'degree'
Trial 12 failed because of the following error: TypeError("__init__() got an unexpected keyword argument 'degree'")
Traceback (most recent call last):
  File "/usr/local/lib/python3.8/dist-packages/optuna/study/_optimize.py", line 196, in _run_trial
    value_or_values = func(trial)
  File "/tmp/ipykernel_7443/1910424133.py", line 18, in __call__
    model = PolynomialRegression(**params1, **params2)
  File "/tmp/ipykernel_7443/827320159.py", line 2, in PolynomialRegression
    return make_pipeline(preprocessing.PolynomialFeatures(*args), LinearRegression(**kwargs))
TypeError: __init__() got an unexpected keyword argument 'degree'
Trial 13 failed because of the following error: TypeError("__init__() got an unexpected keyword argument 'degree'")
Traceback (most recent call last):
  File "/usr/local/lib/python3.8/dist-packages/optuna/study/_optimize.py", line 196, in _run_trial
    value_or_values = func(trial)
  File "/tmp/ipykernel_7443/1910424133.py", line 18, in __call__
    model = PolynomialRegression(**params1, **params2)
  File "/tmp/ipykernel_7443/827320159.py", line 2, in PolynomialRegression
    return make_pipeline(preprocessing.PolynomialFeatures(*args), LinearRegression(**kwargs))
TypeError: __init__() got an unexpected keyword argument 'degree'
Trial 20 failed because of the following error: TypeError("__init__() got an unexpected keyword argument 'degree'")
Traceback (most recent call last):
  File "/usr/local/lib/python3.8/dist-packages/optuna/study/_optimize.py", line 196, in _run_trial
    value_or_values = func(trial)
  File "/tmp/ipykernel_7443/1910424133.py", line 18, in __call__
    model = PolynomialRegression(**params1, **params2)
  File "/tmp/ipykernel_7443/827320159.py", line 2, in PolynomialRegression
    return make_pipeline(preprocessing.PolynomialFeatures(*args), LinearRegression(**kwargs))
TypeError: __init__() got an unexpected keyword argument 'degree'
Trial 15 failed because of the following error: TypeError("__init__() got an unexpected keyword argument 'degree'")
Traceback (most recent call last):
  File "/usr/local/lib/python3.8/dist-packages/optuna/study/_optimize.py", line 196, in _run_trial
    value_or_values = func(trial)
  File "/tmp/ipykernel_7443/1910424133.py", line 18, in __call__
    model = PolynomialRegression(**params1, **params2)
  File "/tmp/ipykernel_7443/827320159.py", line 2, in PolynomialRegression
    return make_pipeline(preprocessing.PolynomialFeatures(*args), LinearRegression(**kwargs))
TypeError: __init__() got an unexpected keyword argument 'degree'
Trial 16 failed because of the following error: TypeError("__init__() got an unexpected keyword argument 'degree'")
Traceback (most recent call last):
  File "/usr/local/lib/python3.8/dist-packages/optuna/study/_optimize.py", line 196, in _run_trial
    value_or_values = func(trial)
  File "/tmp/ipykernel_7443/1910424133.py", line 18, in __call__
    model = PolynomialRegression(**params1, **params2)
  File "/tmp/ipykernel_7443/827320159.py", line 2, in PolynomialRegression
    return make_pipeline(preprocessing.PolynomialFeatures(*args), LinearRegression(**kwargs))
TypeError: __init__() got an unexpected keyword argument 'degree'
Trial 21 failed because of the following error: TypeError("__init__() got an unexpected keyword argument 'degree'")
Traceback (most recent call last):
  File "/usr/local/lib/python3.8/dist-packages/optuna/study/_optimize.py", line 196, in _run_trial
    value_or_values = func(trial)
  File "/tmp/ipykernel_7443/1910424133.py", line 18, in __call__
    model = PolynomialRegression(**params1, **params2)
  File "/tmp/ipykernel_7443/827320159.py", line 2, in PolynomialRegression
    return make_pipeline(preprocessing.PolynomialFeatures(*args), LinearRegression(**kwargs))
TypeError: __init__() got an unexpected keyword argument 'degree'
Trial 23 failed because of the following error: TypeError("__init__() got an unexpected keyword argument 'degree'")
Traceback (most recent call last):
  File "/usr/local/lib/python3.8/dist-packages/optuna/study/_optimize.py", line 196, in _run_trial
    value_or_values = func(trial)
  File "/tmp/ipykernel_7443/1910424133.py", line 18, in __call__
    model = PolynomialRegression(**params1, **params2)
  File "/tmp/ipykernel_7443/827320159.py", line 2, in PolynomialRegression
    return make_pipeline(preprocessing.PolynomialFeatures(*args), LinearRegression(**kwargs))
TypeError: __init__() got an unexpected keyword argument 'degree'
A new study created in RDB with name: Poly_Linear_91337
Trial 6 failed because of the following error: TypeError('PolynomialRegression() argument after * must be an iterable, not int')
Traceback (most recent call last):
  File "/usr/local/lib/python3.8/dist-packages/optuna/study/_optimize.py", line 196, in _run_trial
    value_or_values = func(trial)
  File "/tmp/ipykernel_7443/4290265912.py", line 13, in __call__
    model = PolynomialRegression(*args, **kwargs)
TypeError: PolynomialRegression() argument after * must be an iterable, not int
Trial 17 failed because of the following error: TypeError('PolynomialRegression() argument after * must be an iterable, not int')
Traceback (most recent call last):
  File "/usr/local/lib/python3.8/dist-packages/optuna/study/_optimize.py", line 196, in _run_trial
    value_or_values = func(trial)
  File "/tmp/ipykernel_7443/4290265912.py", line 13, in __call__
    model = PolynomialRegression(*args, **kwargs)
TypeError: PolynomialRegression() argument after * must be an iterable, not int
Trial 5 failed because of the following error: TypeError('PolynomialRegression() argument after * must be an iterable, not int')
Traceback (most recent call last):
  File "/usr/local/lib/python3.8/dist-packages/optuna/study/_optimize.py", line 196, in _run_trial
    value_or_values = func(trial)
  File "/tmp/ipykernel_7443/4290265912.py", line 13, in __call__
    model = PolynomialRegression(*args, **kwargs)
TypeError: PolynomialRegression() argument after * must be an iterable, not int
Trial 2 failed because of the following error: TypeError('PolynomialRegression() argument after * must be an iterable, not int')
Traceback (most recent call last):
  File "/usr/local/lib/python3.8/dist-packages/optuna/study/_optimize.py", line 196, in _run_trial
    value_or_values = func(trial)
  File "/tmp/ipykernel_7443/4290265912.py", line 13, in __call__
    model = PolynomialRegression(*args, **kwargs)
TypeError: PolynomialRegression() argument after * must be an iterable, not int
Trial 7 failed because of the following error: TypeError('PolynomialRegression() argument after * must be an iterable, not int')
Traceback (most recent call last):
  File "/usr/local/lib/python3.8/dist-packages/optuna/study/_optimize.py", line 196, in _run_trial
    value_or_values = func(trial)
  File "/tmp/ipykernel_7443/4290265912.py", line 13, in __call__
    model = PolynomialRegression(*args, **kwargs)
TypeError: PolynomialRegression() argument after * must be an iterable, not int
Trial 13 failed because of the following error: TypeError('PolynomialRegression() argument after * must be an iterable, not int')
Traceback (most recent call last):
  File "/usr/local/lib/python3.8/dist-packages/optuna/study/_optimize.py", line 196, in _run_trial
    value_or_values = func(trial)
  File "/tmp/ipykernel_7443/4290265912.py", line 13, in __call__
    model = PolynomialRegression(*args, **kwargs)
TypeError: PolynomialRegression() argument after * must be an iterable, not int
Trial 22 failed because of the following error: TypeError('PolynomialRegression() argument after * must be an iterable, not int')
Traceback (most recent call last):
  File "/usr/local/lib/python3.8/dist-packages/optuna/study/_optimize.py", line 196, in _run_trial
    value_or_values = func(trial)
  File "/tmp/ipykernel_7443/4290265912.py", line 13, in __call__
    model = PolynomialRegression(*args, **kwargs)
TypeError: PolynomialRegression() argument after * must be an iterable, not int
Trial 16 failed because of the following error: TypeError('PolynomialRegression() argument after * must be an iterable, not int')
Traceback (most recent call last):
  File "/usr/local/lib/python3.8/dist-packages/optuna/study/_optimize.py", line 196, in _run_trial
    value_or_values = func(trial)
  File "/tmp/ipykernel_7443/4290265912.py", line 13, in __call__
    model = PolynomialRegression(*args, **kwargs)
TypeError: PolynomialRegression() argument after * must be an iterable, not int
Trial 1 failed because of the following error: TypeError('PolynomialRegression() argument after * must be an iterable, not int')
Traceback (most recent call last):
  File "/usr/local/lib/python3.8/dist-packages/optuna/study/_optimize.py", line 196, in _run_trial
    value_or_values = func(trial)
  File "/tmp/ipykernel_7443/4290265912.py", line 13, in __call__
    model = PolynomialRegression(*args, **kwargs)
TypeError: PolynomialRegression() argument after * must be an iterable, not int
Trial 9 failed because of the following error: TypeError('PolynomialRegression() argument after * must be an iterable, not int')
Traceback (most recent call last):
  File "/usr/local/lib/python3.8/dist-packages/optuna/study/_optimize.py", line 196, in _run_trial
    value_or_values = func(trial)
  File "/tmp/ipykernel_7443/4290265912.py", line 13, in __call__
    model = PolynomialRegression(*args, **kwargs)
TypeError: PolynomialRegression() argument after * must be an iterable, not int
Trial 10 failed because of the following error: TypeError('PolynomialRegression() argument after * must be an iterable, not int')
Traceback (most recent call last):
  File "/usr/local/lib/python3.8/dist-packages/optuna/study/_optimize.py", line 196, in _run_trial
    value_or_values = func(trial)
  File "/tmp/ipykernel_7443/4290265912.py", line 13, in __call__
    model = PolynomialRegression(*args, **kwargs)
TypeError: PolynomialRegression() argument after * must be an iterable, not int
Trial 11 failed because of the following error: TypeError('PolynomialRegression() argument after * must be an iterable, not int')
Traceback (most recent call last):
  File "/usr/local/lib/python3.8/dist-packages/optuna/study/_optimize.py", line 196, in _run_trial
    value_or_values = func(trial)
  File "/tmp/ipykernel_7443/4290265912.py", line 13, in __call__
    model = PolynomialRegression(*args, **kwargs)
TypeError: PolynomialRegression() argument after * must be an iterable, not int
Trial 0 failed because of the following error: TypeError('PolynomialRegression() argument after * must be an iterable, not int')
Traceback (most recent call last):
  File "/usr/local/lib/python3.8/dist-packages/optuna/study/_optimize.py", line 196, in _run_trial
    value_or_values = func(trial)
  File "/tmp/ipykernel_7443/4290265912.py", line 13, in __call__
    model = PolynomialRegression(*args, **kwargs)
TypeError: PolynomialRegression() argument after * must be an iterable, not int
Trial 20 failed because of the following error: TypeError('PolynomialRegression() argument after * must be an iterable, not int')
Traceback (most recent call last):
  File "/usr/local/lib/python3.8/dist-packages/optuna/study/_optimize.py", line 196, in _run_trial
    value_or_values = func(trial)
  File "/tmp/ipykernel_7443/4290265912.py", line 13, in __call__
    model = PolynomialRegression(*args, **kwargs)
TypeError: PolynomialRegression() argument after * must be an iterable, not int
Trial 8 failed because of the following error: TypeError('PolynomialRegression() argument after * must be an iterable, not int')
Traceback (most recent call last):
  File "/usr/local/lib/python3.8/dist-packages/optuna/study/_optimize.py", line 196, in _run_trial
    value_or_values = func(trial)
  File "/tmp/ipykernel_7443/4290265912.py", line 13, in __call__
    model = PolynomialRegression(*args, **kwargs)
TypeError: PolynomialRegression() argument after * must be an iterable, not int
Trial 3 failed because of the following error: TypeError('PolynomialRegression() argument after * must be an iterable, not int')
Traceback (most recent call last):
  File "/usr/local/lib/python3.8/dist-packages/optuna/study/_optimize.py", line 196, in _run_trial
    value_or_values = func(trial)
  File "/tmp/ipykernel_7443/4290265912.py", line 13, in __call__
    model = PolynomialRegression(*args, **kwargs)
TypeError: PolynomialRegression() argument after * must be an iterable, not int
Trial 19 failed because of the following error: TypeError('PolynomialRegression() argument after * must be an iterable, not int')
Traceback (most recent call last):
  File "/usr/local/lib/python3.8/dist-packages/optuna/study/_optimize.py", line 196, in _run_trial
    value_or_values = func(trial)
  File "/tmp/ipykernel_7443/4290265912.py", line 13, in __call__
    model = PolynomialRegression(*args, **kwargs)
TypeError: PolynomialRegression() argument after * must be an iterable, not int
Trial 15 failed because of the following error: TypeError('PolynomialRegression() argument after * must be an iterable, not int')
Traceback (most recent call last):
  File "/usr/local/lib/python3.8/dist-packages/optuna/study/_optimize.py", line 196, in _run_trial
    value_or_values = func(trial)
  File "/tmp/ipykernel_7443/4290265912.py", line 13, in __call__
    model = PolynomialRegression(*args, **kwargs)
TypeError: PolynomialRegression() argument after * must be an iterable, not int
Trial 21 failed because of the following error: TypeError('PolynomialRegression() argument after * must be an iterable, not int')
Traceback (most recent call last):
  File "/usr/local/lib/python3.8/dist-packages/optuna/study/_optimize.py", line 196, in _run_trial
    value_or_values = func(trial)
  File "/tmp/ipykernel_7443/4290265912.py", line 13, in __call__
    model = PolynomialRegression(*args, **kwargs)
TypeError: PolynomialRegression() argument after * must be an iterable, not int
Trial 18 failed because of the following error: TypeError('PolynomialRegression() argument after * must be an iterable, not int')
Traceback (most recent call last):
  File "/usr/local/lib/python3.8/dist-packages/optuna/study/_optimize.py", line 196, in _run_trial
    value_or_values = func(trial)
  File "/tmp/ipykernel_7443/4290265912.py", line 13, in __call__
    model = PolynomialRegression(*args, **kwargs)
TypeError: PolynomialRegression() argument after * must be an iterable, not int
Trial 4 failed because of the following error: TypeError('PolynomialRegression() argument after * must be an iterable, not int')
Traceback (most recent call last):
  File "/usr/local/lib/python3.8/dist-packages/optuna/study/_optimize.py", line 196, in _run_trial
    value_or_values = func(trial)
  File "/tmp/ipykernel_7443/4290265912.py", line 13, in __call__
    model = PolynomialRegression(*args, **kwargs)
TypeError: PolynomialRegression() argument after * must be an iterable, not int
Trial 14 failed because of the following error: TypeError('PolynomialRegression() argument after * must be an iterable, not int')
Traceback (most recent call last):
  File "/usr/local/lib/python3.8/dist-packages/optuna/study/_optimize.py", line 196, in _run_trial
    value_or_values = func(trial)
  File "/tmp/ipykernel_7443/4290265912.py", line 13, in __call__
    model = PolynomialRegression(*args, **kwargs)
TypeError: PolynomialRegression() argument after * must be an iterable, not int
Trial 12 failed because of the following error: TypeError('PolynomialRegression() argument after * must be an iterable, not int')
Traceback (most recent call last):
  File "/usr/local/lib/python3.8/dist-packages/optuna/study/_optimize.py", line 196, in _run_trial
    value_or_values = func(trial)
  File "/tmp/ipykernel_7443/4290265912.py", line 13, in __call__
    model = PolynomialRegression(*args, **kwargs)
TypeError: PolynomialRegression() argument after * must be an iterable, not int
Trial 23 failed because of the following error: TypeError('PolynomialRegression() argument after * must be an iterable, not int')
Traceback (most recent call last):
  File "/usr/local/lib/python3.8/dist-packages/optuna/study/_optimize.py", line 196, in _run_trial
    value_or_values = func(trial)
  File "/tmp/ipykernel_7443/4290265912.py", line 13, in __call__
    model = PolynomialRegression(*args, **kwargs)
TypeError: PolynomialRegression() argument after * must be an iterable, not int
A new study created in RDB with name: Poly_Linear_91435
Trial 14 failed because of the following error: TypeError('PolynomialRegression() argument after * must be an iterable, not int')
Traceback (most recent call last):
  File "/usr/local/lib/python3.8/dist-packages/optuna/study/_optimize.py", line 196, in _run_trial
    value_or_values = func(trial)
  File "/tmp/ipykernel_7443/4170630255.py", line 14, in __call__
    model = PolynomialRegression(*args, **kwargs)
TypeError: PolynomialRegression() argument after * must be an iterable, not int
Trial 7 failed because of the following error: TypeError('PolynomialRegression() argument after * must be an iterable, not int')
Traceback (most recent call last):
  File "/usr/local/lib/python3.8/dist-packages/optuna/study/_optimize.py", line 196, in _run_trial
    value_or_values = func(trial)
  File "/tmp/ipykernel_7443/4170630255.py", line 14, in __call__
    model = PolynomialRegression(*args, **kwargs)
TypeError: PolynomialRegression() argument after * must be an iterable, not int
Trial 3 failed because of the following error: TypeError('PolynomialRegression() argument after * must be an iterable, not int')
Traceback (most recent call last):
  File "/usr/local/lib/python3.8/dist-packages/optuna/study/_optimize.py", line 196, in _run_trial
    value_or_values = func(trial)
  File "/tmp/ipykernel_7443/4170630255.py", line 14, in __call__
    model = PolynomialRegression(*args, **kwargs)
TypeError: PolynomialRegression() argument after * must be an iterable, not int
Trial 0 failed because of the following error: TypeError('PolynomialRegression() argument after * must be an iterable, not int')
Traceback (most recent call last):
  File "/usr/local/lib/python3.8/dist-packages/optuna/study/_optimize.py", line 196, in _run_trial
    value_or_values = func(trial)
  File "/tmp/ipykernel_7443/4170630255.py", line 14, in __call__
    model = PolynomialRegression(*args, **kwargs)
TypeError: PolynomialRegression() argument after * must be an iterable, not int
Trial 1 failed because of the following error: TypeError('PolynomialRegression() argument after * must be an iterable, not int')
Traceback (most recent call last):
  File "/usr/local/lib/python3.8/dist-packages/optuna/study/_optimize.py", line 196, in _run_trial
    value_or_values = func(trial)
  File "/tmp/ipykernel_7443/4170630255.py", line 14, in __call__
    model = PolynomialRegression(*args, **kwargs)
TypeError: PolynomialRegression() argument after * must be an iterable, not int
Trial 4 failed because of the following error: TypeError('PolynomialRegression() argument after * must be an iterable, not int')
Traceback (most recent call last):
  File "/usr/local/lib/python3.8/dist-packages/optuna/study/_optimize.py", line 196, in _run_trial
    value_or_values = func(trial)
  File "/tmp/ipykernel_7443/4170630255.py", line 14, in __call__
    model = PolynomialRegression(*args, **kwargs)
TypeError: PolynomialRegression() argument after * must be an iterable, not int
Trial 16 failed because of the following error: TypeError('PolynomialRegression() argument after * must be an iterable, not int')
Traceback (most recent call last):
  File "/usr/local/lib/python3.8/dist-packages/optuna/study/_optimize.py", line 196, in _run_trial
    value_or_values = func(trial)
  File "/tmp/ipykernel_7443/4170630255.py", line 14, in __call__
    model = PolynomialRegression(*args, **kwargs)
TypeError: PolynomialRegression() argument after * must be an iterable, not int
Trial 11 failed because of the following error: TypeError('PolynomialRegression() argument after * must be an iterable, not int')
Traceback (most recent call last):
  File "/usr/local/lib/python3.8/dist-packages/optuna/study/_optimize.py", line 196, in _run_trial
    value_or_values = func(trial)
  File "/tmp/ipykernel_7443/4170630255.py", line 14, in __call__
    model = PolynomialRegression(*args, **kwargs)
TypeError: PolynomialRegression() argument after * must be an iterable, not int
Trial 13 failed because of the following error: TypeError('PolynomialRegression() argument after * must be an iterable, not int')
Traceback (most recent call last):
  File "/usr/local/lib/python3.8/dist-packages/optuna/study/_optimize.py", line 196, in _run_trial
    value_or_values = func(trial)
  File "/tmp/ipykernel_7443/4170630255.py", line 14, in __call__
    model = PolynomialRegression(*args, **kwargs)
TypeError: PolynomialRegression() argument after * must be an iterable, not int
Trial 6 failed because of the following error: TypeError('PolynomialRegression() argument after * must be an iterable, not int')
Traceback (most recent call last):
  File "/usr/local/lib/python3.8/dist-packages/optuna/study/_optimize.py", line 196, in _run_trial
    value_or_values = func(trial)
  File "/tmp/ipykernel_7443/4170630255.py", line 14, in __call__
    model = PolynomialRegression(*args, **kwargs)
TypeError: PolynomialRegression() argument after * must be an iterable, not int
Trial 8 failed because of the following error: TypeError('PolynomialRegression() argument after * must be an iterable, not int')
Traceback (most recent call last):
  File "/usr/local/lib/python3.8/dist-packages/optuna/study/_optimize.py", line 196, in _run_trial
    value_or_values = func(trial)
  File "/tmp/ipykernel_7443/4170630255.py", line 14, in __call__
    model = PolynomialRegression(*args, **kwargs)
TypeError: PolynomialRegression() argument after * must be an iterable, not int
Trial 20 failed because of the following error: TypeError('PolynomialRegression() argument after * must be an iterable, not int')
Traceback (most recent call last):
  File "/usr/local/lib/python3.8/dist-packages/optuna/study/_optimize.py", line 196, in _run_trial
    value_or_values = func(trial)
  File "/tmp/ipykernel_7443/4170630255.py", line 14, in __call__
    model = PolynomialRegression(*args, **kwargs)
TypeError: PolynomialRegression() argument after * must be an iterable, not int
Trial 5 failed because of the following error: TypeError('PolynomialRegression() argument after * must be an iterable, not int')
Traceback (most recent call last):
  File "/usr/local/lib/python3.8/dist-packages/optuna/study/_optimize.py", line 196, in _run_trial
    value_or_values = func(trial)
  File "/tmp/ipykernel_7443/4170630255.py", line 14, in __call__
    model = PolynomialRegression(*args, **kwargs)
TypeError: PolynomialRegression() argument after * must be an iterable, not int
Trial 10 failed because of the following error: TypeError('PolynomialRegression() argument after * must be an iterable, not int')
Traceback (most recent call last):
  File "/usr/local/lib/python3.8/dist-packages/optuna/study/_optimize.py", line 196, in _run_trial
    value_or_values = func(trial)
  File "/tmp/ipykernel_7443/4170630255.py", line 14, in __call__
    model = PolynomialRegression(*args, **kwargs)
TypeError: PolynomialRegression() argument after * must be an iterable, not int
Trial 23 failed because of the following error: TypeError('PolynomialRegression() argument after * must be an iterable, not int')
Traceback (most recent call last):
  File "/usr/local/lib/python3.8/dist-packages/optuna/study/_optimize.py", line 196, in _run_trial
    value_or_values = func(trial)
  File "/tmp/ipykernel_7443/4170630255.py", line 14, in __call__
    model = PolynomialRegression(*args, **kwargs)
TypeError: PolynomialRegression() argument after * must be an iterable, not int
Trial 9 failed because of the following error: TypeError('PolynomialRegression() argument after * must be an iterable, not int')
Traceback (most recent call last):
  File "/usr/local/lib/python3.8/dist-packages/optuna/study/_optimize.py", line 196, in _run_trial
    value_or_values = func(trial)
  File "/tmp/ipykernel_7443/4170630255.py", line 14, in __call__
    model = PolynomialRegression(*args, **kwargs)
TypeError: PolynomialRegression() argument after * must be an iterable, not int
Trial 21 failed because of the following error: TypeError('PolynomialRegression() argument after * must be an iterable, not int')
Traceback (most recent call last):
  File "/usr/local/lib/python3.8/dist-packages/optuna/study/_optimize.py", line 196, in _run_trial
    value_or_values = func(trial)
  File "/tmp/ipykernel_7443/4170630255.py", line 14, in __call__
    model = PolynomialRegression(*args, **kwargs)
TypeError: PolynomialRegression() argument after * must be an iterable, not int
Trial 22 failed because of the following error: TypeError('PolynomialRegression() argument after * must be an iterable, not int')
Traceback (most recent call last):
  File "/usr/local/lib/python3.8/dist-packages/optuna/study/_optimize.py", line 196, in _run_trial
    value_or_values = func(trial)
  File "/tmp/ipykernel_7443/4170630255.py", line 14, in __call__
    model = PolynomialRegression(*args, **kwargs)
TypeError: PolynomialRegression() argument after * must be an iterable, not int
Trial 2 failed because of the following error: TypeError('PolynomialRegression() argument after * must be an iterable, not int')
Traceback (most recent call last):
  File "/usr/local/lib/python3.8/dist-packages/optuna/study/_optimize.py", line 196, in _run_trial
    value_or_values = func(trial)
  File "/tmp/ipykernel_7443/4170630255.py", line 14, in __call__
    model = PolynomialRegression(*args, **kwargs)
TypeError: PolynomialRegression() argument after * must be an iterable, not int
Trial 19 failed because of the following error: TypeError('PolynomialRegression() argument after * must be an iterable, not int')
Traceback (most recent call last):
  File "/usr/local/lib/python3.8/dist-packages/optuna/study/_optimize.py", line 196, in _run_trial
    value_or_values = func(trial)
  File "/tmp/ipykernel_7443/4170630255.py", line 14, in __call__
    model = PolynomialRegression(*args, **kwargs)
TypeError: PolynomialRegression() argument after * must be an iterable, not int
Trial 12 failed because of the following error: TypeError('PolynomialRegression() argument after * must be an iterable, not int')
Traceback (most recent call last):
  File "/usr/local/lib/python3.8/dist-packages/optuna/study/_optimize.py", line 196, in _run_trial
    value_or_values = func(trial)
  File "/tmp/ipykernel_7443/4170630255.py", line 14, in __call__
    model = PolynomialRegression(*args, **kwargs)
TypeError: PolynomialRegression() argument after * must be an iterable, not int
Trial 18 failed because of the following error: TypeError('PolynomialRegression() argument after * must be an iterable, not int')
Traceback (most recent call last):
  File "/usr/local/lib/python3.8/dist-packages/optuna/study/_optimize.py", line 196, in _run_trial
    value_or_values = func(trial)
  File "/tmp/ipykernel_7443/4170630255.py", line 14, in __call__
    model = PolynomialRegression(*args, **kwargs)
TypeError: PolynomialRegression() argument after * must be an iterable, not int
Trial 17 failed because of the following error: TypeError('PolynomialRegression() argument after * must be an iterable, not int')
Traceback (most recent call last):
  File "/usr/local/lib/python3.8/dist-packages/optuna/study/_optimize.py", line 196, in _run_trial
    value_or_values = func(trial)
  File "/tmp/ipykernel_7443/4170630255.py", line 14, in __call__
    model = PolynomialRegression(*args, **kwargs)
TypeError: PolynomialRegression() argument after * must be an iterable, not int
Trial 15 failed because of the following error: TypeError('PolynomialRegression() argument after * must be an iterable, not int')
Traceback (most recent call last):
  File "/usr/local/lib/python3.8/dist-packages/optuna/study/_optimize.py", line 196, in _run_trial
    value_or_values = func(trial)
  File "/tmp/ipykernel_7443/4170630255.py", line 14, in __call__
    model = PolynomialRegression(*args, **kwargs)
TypeError: PolynomialRegression() argument after * must be an iterable, not int
A new study created in RDB with name: Poly_Linear_91710
Trial 2 failed because of the following error: ValueError('\nAll the 10 fits failed.\nIt is very likely that your model is misconfigured.\nYou can try to debug the error by setting error_score=\'raise\'.\n\nBelow are more details about the failures:\n--------------------------------------------------------------------------------\n10 fits failed with the following error:\nTraceback (most recent call last):\n  File "/usr/local/lib/python3.8/dist-packages/sklearn/model_selection/_validation.py", line 686, in _fit_and_score\n    estimator.fit(X_train, y_train, **fit_params)\n  File "/usr/local/lib/python3.8/dist-packages/sklearn/pipeline.py", line 378, in fit\n    Xt = self._fit(X, y, **fit_params_steps)\n  File "/usr/local/lib/python3.8/dist-packages/sklearn/pipeline.py", line 336, in _fit\n    X, fitted_transformer = fit_transform_one_cached(\n  File "/usr/local/lib/python3.8/dist-packages/joblib/memory.py", line 349, in __call__\n    return self.func(*args, **kwargs)\n  File "/usr/local/lib/python3.8/dist-packages/sklearn/pipeline.py", line 870, in _fit_transform_one\n    res = transformer.fit_transform(X, y, **fit_params)\n  File "/usr/local/lib/python3.8/dist-packages/sklearn/base.py", line 870, in fit_transform\n    return self.fit(X, y, **fit_params).transform(X)\n  File "/usr/local/lib/python3.8/dist-packages/sklearn/preprocessing/_polynomial.py", line 432, in transform\n    XP = np.empty(\nValueError: array is too big; `arr.size * arr.dtype.itemsize` is larger than the maximum possible size.\n')
Traceback (most recent call last):
  File "/usr/local/lib/python3.8/dist-packages/optuna/study/_optimize.py", line 196, in _run_trial
    value_or_values = func(trial)
  File "/tmp/ipykernel_7443/2264325072.py", line 23, in __call__
    scores = cross_validate(estimator=model, scoring=metrics,
  File "/usr/local/lib/python3.8/dist-packages/sklearn/model_selection/_validation.py", line 285, in cross_validate
    _warn_or_raise_about_fit_failures(results, error_score)
  File "/usr/local/lib/python3.8/dist-packages/sklearn/model_selection/_validation.py", line 367, in _warn_or_raise_about_fit_failures
    raise ValueError(all_fits_failed_message)
ValueError: 
All the 10 fits failed.
It is very likely that your model is misconfigured.
You can try to debug the error by setting error_score='raise'.

Below are more details about the failures:
--------------------------------------------------------------------------------
10 fits failed with the following error:
Traceback (most recent call last):
  File "/usr/local/lib/python3.8/dist-packages/sklearn/model_selection/_validation.py", line 686, in _fit_and_score
    estimator.fit(X_train, y_train, **fit_params)
  File "/usr/local/lib/python3.8/dist-packages/sklearn/pipeline.py", line 378, in fit
    Xt = self._fit(X, y, **fit_params_steps)
  File "/usr/local/lib/python3.8/dist-packages/sklearn/pipeline.py", line 336, in _fit
    X, fitted_transformer = fit_transform_one_cached(
  File "/usr/local/lib/python3.8/dist-packages/joblib/memory.py", line 349, in __call__
    return self.func(*args, **kwargs)
  File "/usr/local/lib/python3.8/dist-packages/sklearn/pipeline.py", line 870, in _fit_transform_one
    res = transformer.fit_transform(X, y, **fit_params)
  File "/usr/local/lib/python3.8/dist-packages/sklearn/base.py", line 870, in fit_transform
    return self.fit(X, y, **fit_params).transform(X)
  File "/usr/local/lib/python3.8/dist-packages/sklearn/preprocessing/_polynomial.py", line 432, in transform
    XP = np.empty(
ValueError: array is too big; `arr.size * arr.dtype.itemsize` is larger than the maximum possible size.

Trial 1 failed because of the following error: ValueError('\nAll the 10 fits failed.\nIt is very likely that your model is misconfigured.\nYou can try to debug the error by setting error_score=\'raise\'.\n\nBelow are more details about the failures:\n--------------------------------------------------------------------------------\n5 fits failed with the following error:\nTraceback (most recent call last):\n  File "/usr/local/lib/python3.8/dist-packages/sklearn/model_selection/_validation.py", line 686, in _fit_and_score\n    estimator.fit(X_train, y_train, **fit_params)\n  File "/usr/local/lib/python3.8/dist-packages/sklearn/pipeline.py", line 378, in fit\n    Xt = self._fit(X, y, **fit_params_steps)\n  File "/usr/local/lib/python3.8/dist-packages/sklearn/pipeline.py", line 336, in _fit\n    X, fitted_transformer = fit_transform_one_cached(\n  File "/usr/local/lib/python3.8/dist-packages/joblib/memory.py", line 349, in __call__\n    return self.func(*args, **kwargs)\n  File "/usr/local/lib/python3.8/dist-packages/sklearn/pipeline.py", line 870, in _fit_transform_one\n    res = transformer.fit_transform(X, y, **fit_params)\n  File "/usr/local/lib/python3.8/dist-packages/sklearn/base.py", line 870, in fit_transform\n    return self.fit(X, y, **fit_params).transform(X)\n  File "/usr/local/lib/python3.8/dist-packages/sklearn/preprocessing/_polynomial.py", line 432, in transform\n    XP = np.empty(\nnumpy.core._exceptions._ArrayMemoryError: Unable to allocate 376. TiB for an array with shape (211, 244662670200) and data type float64\n\n--------------------------------------------------------------------------------\n5 fits failed with the following error:\nTraceback (most recent call last):\n  File "/usr/local/lib/python3.8/dist-packages/sklearn/model_selection/_validation.py", line 686, in _fit_and_score\n    estimator.fit(X_train, y_train, **fit_params)\n  File "/usr/local/lib/python3.8/dist-packages/sklearn/pipeline.py", line 378, in fit\n    Xt = self._fit(X, y, **fit_params_steps)\n  File "/usr/local/lib/python3.8/dist-packages/sklearn/pipeline.py", line 336, in _fit\n    X, fitted_transformer = fit_transform_one_cached(\n  File "/usr/local/lib/python3.8/dist-packages/joblib/memory.py", line 349, in __call__\n    return self.func(*args, **kwargs)\n  File "/usr/local/lib/python3.8/dist-packages/sklearn/pipeline.py", line 870, in _fit_transform_one\n    res = transformer.fit_transform(X, y, **fit_params)\n  File "/usr/local/lib/python3.8/dist-packages/sklearn/base.py", line 870, in fit_transform\n    return self.fit(X, y, **fit_params).transform(X)\n  File "/usr/local/lib/python3.8/dist-packages/sklearn/preprocessing/_polynomial.py", line 432, in transform\n    XP = np.empty(\nnumpy.core._exceptions._ArrayMemoryError: Unable to allocate 377. TiB for an array with shape (212, 244662670200) and data type float64\n')
Traceback (most recent call last):
  File "/usr/local/lib/python3.8/dist-packages/optuna/study/_optimize.py", line 196, in _run_trial
    value_or_values = func(trial)
  File "/tmp/ipykernel_7443/2264325072.py", line 23, in __call__
    scores = cross_validate(estimator=model, scoring=metrics,
  File "/usr/local/lib/python3.8/dist-packages/sklearn/model_selection/_validation.py", line 285, in cross_validate
    _warn_or_raise_about_fit_failures(results, error_score)
  File "/usr/local/lib/python3.8/dist-packages/sklearn/model_selection/_validation.py", line 367, in _warn_or_raise_about_fit_failures
    raise ValueError(all_fits_failed_message)
ValueError: 
All the 10 fits failed.
It is very likely that your model is misconfigured.
You can try to debug the error by setting error_score='raise'.

Below are more details about the failures:
--------------------------------------------------------------------------------
5 fits failed with the following error:
Traceback (most recent call last):
  File "/usr/local/lib/python3.8/dist-packages/sklearn/model_selection/_validation.py", line 686, in _fit_and_score
    estimator.fit(X_train, y_train, **fit_params)
  File "/usr/local/lib/python3.8/dist-packages/sklearn/pipeline.py", line 378, in fit
    Xt = self._fit(X, y, **fit_params_steps)
  File "/usr/local/lib/python3.8/dist-packages/sklearn/pipeline.py", line 336, in _fit
    X, fitted_transformer = fit_transform_one_cached(
  File "/usr/local/lib/python3.8/dist-packages/joblib/memory.py", line 349, in __call__
    return self.func(*args, **kwargs)
  File "/usr/local/lib/python3.8/dist-packages/sklearn/pipeline.py", line 870, in _fit_transform_one
    res = transformer.fit_transform(X, y, **fit_params)
  File "/usr/local/lib/python3.8/dist-packages/sklearn/base.py", line 870, in fit_transform
    return self.fit(X, y, **fit_params).transform(X)
  File "/usr/local/lib/python3.8/dist-packages/sklearn/preprocessing/_polynomial.py", line 432, in transform
    XP = np.empty(
numpy.core._exceptions._ArrayMemoryError: Unable to allocate 376. TiB for an array with shape (211, 244662670200) and data type float64

--------------------------------------------------------------------------------
5 fits failed with the following error:
Traceback (most recent call last):
  File "/usr/local/lib/python3.8/dist-packages/sklearn/model_selection/_validation.py", line 686, in _fit_and_score
    estimator.fit(X_train, y_train, **fit_params)
  File "/usr/local/lib/python3.8/dist-packages/sklearn/pipeline.py", line 378, in fit
    Xt = self._fit(X, y, **fit_params_steps)
  File "/usr/local/lib/python3.8/dist-packages/sklearn/pipeline.py", line 336, in _fit
    X, fitted_transformer = fit_transform_one_cached(
  File "/usr/local/lib/python3.8/dist-packages/joblib/memory.py", line 349, in __call__
    return self.func(*args, **kwargs)
  File "/usr/local/lib/python3.8/dist-packages/sklearn/pipeline.py", line 870, in _fit_transform_one
    res = transformer.fit_transform(X, y, **fit_params)
  File "/usr/local/lib/python3.8/dist-packages/sklearn/base.py", line 870, in fit_transform
    return self.fit(X, y, **fit_params).transform(X)
  File "/usr/local/lib/python3.8/dist-packages/sklearn/preprocessing/_polynomial.py", line 432, in transform
    XP = np.empty(
numpy.core._exceptions._ArrayMemoryError: Unable to allocate 377. TiB for an array with shape (212, 244662670200) and data type float64

Trial 12 failed because of the following error: ValueError('\nAll the 10 fits failed.\nIt is very likely that your model is misconfigured.\nYou can try to debug the error by setting error_score=\'raise\'.\n\nBelow are more details about the failures:\n--------------------------------------------------------------------------------\n5 fits failed with the following error:\nTraceback (most recent call last):\n  File "/usr/local/lib/python3.8/dist-packages/sklearn/model_selection/_validation.py", line 686, in _fit_and_score\n    estimator.fit(X_train, y_train, **fit_params)\n  File "/usr/local/lib/python3.8/dist-packages/sklearn/pipeline.py", line 378, in fit\n    Xt = self._fit(X, y, **fit_params_steps)\n  File "/usr/local/lib/python3.8/dist-packages/sklearn/pipeline.py", line 336, in _fit\n    X, fitted_transformer = fit_transform_one_cached(\n  File "/usr/local/lib/python3.8/dist-packages/joblib/memory.py", line 349, in __call__\n    return self.func(*args, **kwargs)\n  File "/usr/local/lib/python3.8/dist-packages/sklearn/pipeline.py", line 870, in _fit_transform_one\n    res = transformer.fit_transform(X, y, **fit_params)\n  File "/usr/local/lib/python3.8/dist-packages/sklearn/base.py", line 870, in fit_transform\n    return self.fit(X, y, **fit_params).transform(X)\n  File "/usr/local/lib/python3.8/dist-packages/sklearn/preprocessing/_polynomial.py", line 432, in transform\n    XP = np.empty(\nnumpy.core._exceptions._ArrayMemoryError: Unable to allocate 2.27 TiB for an array with shape (211, 1476337800) and data type float64\n\n--------------------------------------------------------------------------------\n5 fits failed with the following error:\nTraceback (most recent call last):\n  File "/usr/local/lib/python3.8/dist-packages/sklearn/model_selection/_validation.py", line 686, in _fit_and_score\n    estimator.fit(X_train, y_train, **fit_params)\n  File "/usr/local/lib/python3.8/dist-packages/sklearn/pipeline.py", line 378, in fit\n    Xt = self._fit(X, y, **fit_params_steps)\n  File "/usr/local/lib/python3.8/dist-packages/sklearn/pipeline.py", line 336, in _fit\n    X, fitted_transformer = fit_transform_one_cached(\n  File "/usr/local/lib/python3.8/dist-packages/joblib/memory.py", line 349, in __call__\n    return self.func(*args, **kwargs)\n  File "/usr/local/lib/python3.8/dist-packages/sklearn/pipeline.py", line 870, in _fit_transform_one\n    res = transformer.fit_transform(X, y, **fit_params)\n  File "/usr/local/lib/python3.8/dist-packages/sklearn/base.py", line 870, in fit_transform\n    return self.fit(X, y, **fit_params).transform(X)\n  File "/usr/local/lib/python3.8/dist-packages/sklearn/preprocessing/_polynomial.py", line 432, in transform\n    XP = np.empty(\nnumpy.core._exceptions._ArrayMemoryError: Unable to allocate 2.28 TiB for an array with shape (212, 1476337800) and data type float64\n')
Traceback (most recent call last):
  File "/usr/local/lib/python3.8/dist-packages/optuna/study/_optimize.py", line 196, in _run_trial
    value_or_values = func(trial)
  File "/tmp/ipykernel_7443/2264325072.py", line 23, in __call__
    scores = cross_validate(estimator=model, scoring=metrics,
  File "/usr/local/lib/python3.8/dist-packages/sklearn/model_selection/_validation.py", line 285, in cross_validate
    _warn_or_raise_about_fit_failures(results, error_score)
  File "/usr/local/lib/python3.8/dist-packages/sklearn/model_selection/_validation.py", line 367, in _warn_or_raise_about_fit_failures
    raise ValueError(all_fits_failed_message)
ValueError: 
All the 10 fits failed.
It is very likely that your model is misconfigured.
You can try to debug the error by setting error_score='raise'.

Below are more details about the failures:
--------------------------------------------------------------------------------
5 fits failed with the following error:
Traceback (most recent call last):
  File "/usr/local/lib/python3.8/dist-packages/sklearn/model_selection/_validation.py", line 686, in _fit_and_score
    estimator.fit(X_train, y_train, **fit_params)
  File "/usr/local/lib/python3.8/dist-packages/sklearn/pipeline.py", line 378, in fit
    Xt = self._fit(X, y, **fit_params_steps)
  File "/usr/local/lib/python3.8/dist-packages/sklearn/pipeline.py", line 336, in _fit
    X, fitted_transformer = fit_transform_one_cached(
  File "/usr/local/lib/python3.8/dist-packages/joblib/memory.py", line 349, in __call__
    return self.func(*args, **kwargs)
  File "/usr/local/lib/python3.8/dist-packages/sklearn/pipeline.py", line 870, in _fit_transform_one
    res = transformer.fit_transform(X, y, **fit_params)
  File "/usr/local/lib/python3.8/dist-packages/sklearn/base.py", line 870, in fit_transform
    return self.fit(X, y, **fit_params).transform(X)
  File "/usr/local/lib/python3.8/dist-packages/sklearn/preprocessing/_polynomial.py", line 432, in transform
    XP = np.empty(
numpy.core._exceptions._ArrayMemoryError: Unable to allocate 2.27 TiB for an array with shape (211, 1476337800) and data type float64

--------------------------------------------------------------------------------
5 fits failed with the following error:
Traceback (most recent call last):
  File "/usr/local/lib/python3.8/dist-packages/sklearn/model_selection/_validation.py", line 686, in _fit_and_score
    estimator.fit(X_train, y_train, **fit_params)
  File "/usr/local/lib/python3.8/dist-packages/sklearn/pipeline.py", line 378, in fit
    Xt = self._fit(X, y, **fit_params_steps)
  File "/usr/local/lib/python3.8/dist-packages/sklearn/pipeline.py", line 336, in _fit
    X, fitted_transformer = fit_transform_one_cached(
  File "/usr/local/lib/python3.8/dist-packages/joblib/memory.py", line 349, in __call__
    return self.func(*args, **kwargs)
  File "/usr/local/lib/python3.8/dist-packages/sklearn/pipeline.py", line 870, in _fit_transform_one
    res = transformer.fit_transform(X, y, **fit_params)
  File "/usr/local/lib/python3.8/dist-packages/sklearn/base.py", line 870, in fit_transform
    return self.fit(X, y, **fit_params).transform(X)
  File "/usr/local/lib/python3.8/dist-packages/sklearn/preprocessing/_polynomial.py", line 432, in transform
    XP = np.empty(
numpy.core._exceptions._ArrayMemoryError: Unable to allocate 2.28 TiB for an array with shape (212, 1476337800) and data type float64

Trial 22 failed because of the following error: ValueError('\nAll the 10 fits failed.\nIt is very likely that your model is misconfigured.\nYou can try to debug the error by setting error_score=\'raise\'.\n\nBelow are more details about the failures:\n--------------------------------------------------------------------------------\n10 fits failed with the following error:\nTraceback (most recent call last):\n  File "/usr/local/lib/python3.8/dist-packages/sklearn/model_selection/_validation.py", line 686, in _fit_and_score\n    estimator.fit(X_train, y_train, **fit_params)\n  File "/usr/local/lib/python3.8/dist-packages/sklearn/pipeline.py", line 378, in fit\n    Xt = self._fit(X, y, **fit_params_steps)\n  File "/usr/local/lib/python3.8/dist-packages/sklearn/pipeline.py", line 336, in _fit\n    X, fitted_transformer = fit_transform_one_cached(\n  File "/usr/local/lib/python3.8/dist-packages/joblib/memory.py", line 349, in __call__\n    return self.func(*args, **kwargs)\n  File "/usr/local/lib/python3.8/dist-packages/sklearn/pipeline.py", line 870, in _fit_transform_one\n    res = transformer.fit_transform(X, y, **fit_params)\n  File "/usr/local/lib/python3.8/dist-packages/sklearn/base.py", line 870, in fit_transform\n    return self.fit(X, y, **fit_params).transform(X)\n  File "/usr/local/lib/python3.8/dist-packages/sklearn/preprocessing/_polynomial.py", line 432, in transform\n    XP = np.empty(\nValueError: Maximum allowed dimension exceeded\n')
Traceback (most recent call last):
  File "/usr/local/lib/python3.8/dist-packages/optuna/study/_optimize.py", line 196, in _run_trial
    value_or_values = func(trial)
  File "/tmp/ipykernel_7443/2264325072.py", line 23, in __call__
    scores = cross_validate(estimator=model, scoring=metrics,
  File "/usr/local/lib/python3.8/dist-packages/sklearn/model_selection/_validation.py", line 285, in cross_validate
    _warn_or_raise_about_fit_failures(results, error_score)
  File "/usr/local/lib/python3.8/dist-packages/sklearn/model_selection/_validation.py", line 367, in _warn_or_raise_about_fit_failures
    raise ValueError(all_fits_failed_message)
ValueError: 
All the 10 fits failed.
It is very likely that your model is misconfigured.
You can try to debug the error by setting error_score='raise'.

Below are more details about the failures:
--------------------------------------------------------------------------------
10 fits failed with the following error:
Traceback (most recent call last):
  File "/usr/local/lib/python3.8/dist-packages/sklearn/model_selection/_validation.py", line 686, in _fit_and_score
    estimator.fit(X_train, y_train, **fit_params)
  File "/usr/local/lib/python3.8/dist-packages/sklearn/pipeline.py", line 378, in fit
    Xt = self._fit(X, y, **fit_params_steps)
  File "/usr/local/lib/python3.8/dist-packages/sklearn/pipeline.py", line 336, in _fit
    X, fitted_transformer = fit_transform_one_cached(
  File "/usr/local/lib/python3.8/dist-packages/joblib/memory.py", line 349, in __call__
    return self.func(*args, **kwargs)
  File "/usr/local/lib/python3.8/dist-packages/sklearn/pipeline.py", line 870, in _fit_transform_one
    res = transformer.fit_transform(X, y, **fit_params)
  File "/usr/local/lib/python3.8/dist-packages/sklearn/base.py", line 870, in fit_transform
    return self.fit(X, y, **fit_params).transform(X)
  File "/usr/local/lib/python3.8/dist-packages/sklearn/preprocessing/_polynomial.py", line 432, in transform
    XP = np.empty(
ValueError: Maximum allowed dimension exceeded

Trial 16 failed because of the following error: ValueError('\nAll the 10 fits failed.\nIt is very likely that your model is misconfigured.\nYou can try to debug the error by setting error_score=\'raise\'.\n\nBelow are more details about the failures:\n--------------------------------------------------------------------------------\n10 fits failed with the following error:\nTraceback (most recent call last):\n  File "/usr/local/lib/python3.8/dist-packages/sklearn/model_selection/_validation.py", line 686, in _fit_and_score\n    estimator.fit(X_train, y_train, **fit_params)\n  File "/usr/local/lib/python3.8/dist-packages/sklearn/pipeline.py", line 378, in fit\n    Xt = self._fit(X, y, **fit_params_steps)\n  File "/usr/local/lib/python3.8/dist-packages/sklearn/pipeline.py", line 336, in _fit\n    X, fitted_transformer = fit_transform_one_cached(\n  File "/usr/local/lib/python3.8/dist-packages/joblib/memory.py", line 349, in __call__\n    return self.func(*args, **kwargs)\n  File "/usr/local/lib/python3.8/dist-packages/sklearn/pipeline.py", line 870, in _fit_transform_one\n    res = transformer.fit_transform(X, y, **fit_params)\n  File "/usr/local/lib/python3.8/dist-packages/sklearn/base.py", line 870, in fit_transform\n    return self.fit(X, y, **fit_params).transform(X)\n  File "/usr/local/lib/python3.8/dist-packages/sklearn/preprocessing/_polynomial.py", line 432, in transform\n    XP = np.empty(\nValueError: Maximum allowed dimension exceeded\n')
Traceback (most recent call last):
  File "/usr/local/lib/python3.8/dist-packages/optuna/study/_optimize.py", line 196, in _run_trial
    value_or_values = func(trial)
  File "/tmp/ipykernel_7443/2264325072.py", line 23, in __call__
    scores = cross_validate(estimator=model, scoring=metrics,
  File "/usr/local/lib/python3.8/dist-packages/sklearn/model_selection/_validation.py", line 285, in cross_validate
    _warn_or_raise_about_fit_failures(results, error_score)
  File "/usr/local/lib/python3.8/dist-packages/sklearn/model_selection/_validation.py", line 367, in _warn_or_raise_about_fit_failures
    raise ValueError(all_fits_failed_message)
ValueError: 
All the 10 fits failed.
It is very likely that your model is misconfigured.
You can try to debug the error by setting error_score='raise'.

Below are more details about the failures:
--------------------------------------------------------------------------------
10 fits failed with the following error:
Traceback (most recent call last):
  File "/usr/local/lib/python3.8/dist-packages/sklearn/model_selection/_validation.py", line 686, in _fit_and_score
    estimator.fit(X_train, y_train, **fit_params)
  File "/usr/local/lib/python3.8/dist-packages/sklearn/pipeline.py", line 378, in fit
    Xt = self._fit(X, y, **fit_params_steps)
  File "/usr/local/lib/python3.8/dist-packages/sklearn/pipeline.py", line 336, in _fit
    X, fitted_transformer = fit_transform_one_cached(
  File "/usr/local/lib/python3.8/dist-packages/joblib/memory.py", line 349, in __call__
    return self.func(*args, **kwargs)
  File "/usr/local/lib/python3.8/dist-packages/sklearn/pipeline.py", line 870, in _fit_transform_one
    res = transformer.fit_transform(X, y, **fit_params)
  File "/usr/local/lib/python3.8/dist-packages/sklearn/base.py", line 870, in fit_transform
    return self.fit(X, y, **fit_params).transform(X)
  File "/usr/local/lib/python3.8/dist-packages/sklearn/preprocessing/_polynomial.py", line 432, in transform
    XP = np.empty(
ValueError: Maximum allowed dimension exceeded

Trial 8 failed because of the following error: ValueError('\nAll the 10 fits failed.\nIt is very likely that your model is misconfigured.\nYou can try to debug the error by setting error_score=\'raise\'.\n\nBelow are more details about the failures:\n--------------------------------------------------------------------------------\n5 fits failed with the following error:\nTraceback (most recent call last):\n  File "/usr/local/lib/python3.8/dist-packages/sklearn/model_selection/_validation.py", line 686, in _fit_and_score\n    estimator.fit(X_train, y_train, **fit_params)\n  File "/usr/local/lib/python3.8/dist-packages/sklearn/pipeline.py", line 378, in fit\n    Xt = self._fit(X, y, **fit_params_steps)\n  File "/usr/local/lib/python3.8/dist-packages/sklearn/pipeline.py", line 336, in _fit\n    X, fitted_transformer = fit_transform_one_cached(\n  File "/usr/local/lib/python3.8/dist-packages/joblib/memory.py", line 349, in __call__\n    return self.func(*args, **kwargs)\n  File "/usr/local/lib/python3.8/dist-packages/sklearn/pipeline.py", line 870, in _fit_transform_one\n    res = transformer.fit_transform(X, y, **fit_params)\n  File "/usr/local/lib/python3.8/dist-packages/sklearn/base.py", line 870, in fit_transform\n    return self.fit(X, y, **fit_params).transform(X)\n  File "/usr/local/lib/python3.8/dist-packages/sklearn/preprocessing/_polynomial.py", line 432, in transform\n    XP = np.empty(\nnumpy.core._exceptions._ArrayMemoryError: Unable to allocate 862. GiB for an array with shape (211, 548354040) and data type float64\n\n--------------------------------------------------------------------------------\n5 fits failed with the following error:\nTraceback (most recent call last):\n  File "/usr/local/lib/python3.8/dist-packages/sklearn/model_selection/_validation.py", line 686, in _fit_and_score\n    estimator.fit(X_train, y_train, **fit_params)\n  File "/usr/local/lib/python3.8/dist-packages/sklearn/pipeline.py", line 378, in fit\n    Xt = self._fit(X, y, **fit_params_steps)\n  File "/usr/local/lib/python3.8/dist-packages/sklearn/pipeline.py", line 336, in _fit\n    X, fitted_transformer = fit_transform_one_cached(\n  File "/usr/local/lib/python3.8/dist-packages/joblib/memory.py", line 349, in __call__\n    return self.func(*args, **kwargs)\n  File "/usr/local/lib/python3.8/dist-packages/sklearn/pipeline.py", line 870, in _fit_transform_one\n    res = transformer.fit_transform(X, y, **fit_params)\n  File "/usr/local/lib/python3.8/dist-packages/sklearn/base.py", line 870, in fit_transform\n    return self.fit(X, y, **fit_params).transform(X)\n  File "/usr/local/lib/python3.8/dist-packages/sklearn/preprocessing/_polynomial.py", line 432, in transform\n    XP = np.empty(\nnumpy.core._exceptions._ArrayMemoryError: Unable to allocate 866. GiB for an array with shape (212, 548354040) and data type float64\n')
Traceback (most recent call last):
  File "/usr/local/lib/python3.8/dist-packages/optuna/study/_optimize.py", line 196, in _run_trial
    value_or_values = func(trial)
  File "/tmp/ipykernel_7443/2264325072.py", line 23, in __call__
    scores = cross_validate(estimator=model, scoring=metrics,
  File "/usr/local/lib/python3.8/dist-packages/sklearn/model_selection/_validation.py", line 285, in cross_validate
    _warn_or_raise_about_fit_failures(results, error_score)
  File "/usr/local/lib/python3.8/dist-packages/sklearn/model_selection/_validation.py", line 367, in _warn_or_raise_about_fit_failures
    raise ValueError(all_fits_failed_message)
ValueError: 
All the 10 fits failed.
It is very likely that your model is misconfigured.
You can try to debug the error by setting error_score='raise'.

Below are more details about the failures:
--------------------------------------------------------------------------------
5 fits failed with the following error:
Traceback (most recent call last):
  File "/usr/local/lib/python3.8/dist-packages/sklearn/model_selection/_validation.py", line 686, in _fit_and_score
    estimator.fit(X_train, y_train, **fit_params)
  File "/usr/local/lib/python3.8/dist-packages/sklearn/pipeline.py", line 378, in fit
    Xt = self._fit(X, y, **fit_params_steps)
  File "/usr/local/lib/python3.8/dist-packages/sklearn/pipeline.py", line 336, in _fit
    X, fitted_transformer = fit_transform_one_cached(
  File "/usr/local/lib/python3.8/dist-packages/joblib/memory.py", line 349, in __call__
    return self.func(*args, **kwargs)
  File "/usr/local/lib/python3.8/dist-packages/sklearn/pipeline.py", line 870, in _fit_transform_one
    res = transformer.fit_transform(X, y, **fit_params)
  File "/usr/local/lib/python3.8/dist-packages/sklearn/base.py", line 870, in fit_transform
    return self.fit(X, y, **fit_params).transform(X)
  File "/usr/local/lib/python3.8/dist-packages/sklearn/preprocessing/_polynomial.py", line 432, in transform
    XP = np.empty(
numpy.core._exceptions._ArrayMemoryError: Unable to allocate 862. GiB for an array with shape (211, 548354040) and data type float64

--------------------------------------------------------------------------------
5 fits failed with the following error:
Traceback (most recent call last):
  File "/usr/local/lib/python3.8/dist-packages/sklearn/model_selection/_validation.py", line 686, in _fit_and_score
    estimator.fit(X_train, y_train, **fit_params)
  File "/usr/local/lib/python3.8/dist-packages/sklearn/pipeline.py", line 378, in fit
    Xt = self._fit(X, y, **fit_params_steps)
  File "/usr/local/lib/python3.8/dist-packages/sklearn/pipeline.py", line 336, in _fit
    X, fitted_transformer = fit_transform_one_cached(
  File "/usr/local/lib/python3.8/dist-packages/joblib/memory.py", line 349, in __call__
    return self.func(*args, **kwargs)
  File "/usr/local/lib/python3.8/dist-packages/sklearn/pipeline.py", line 870, in _fit_transform_one
    res = transformer.fit_transform(X, y, **fit_params)
  File "/usr/local/lib/python3.8/dist-packages/sklearn/base.py", line 870, in fit_transform
    return self.fit(X, y, **fit_params).transform(X)
  File "/usr/local/lib/python3.8/dist-packages/sklearn/preprocessing/_polynomial.py", line 432, in transform
    XP = np.empty(
numpy.core._exceptions._ArrayMemoryError: Unable to allocate 866. GiB for an array with shape (212, 548354040) and data type float64

Trial 9 finished with value: 0.7728060333835753 and parameters: {'degree': 1}. Best is trial 9 with value: 0.7728060333835753.
Trial 11 failed because of the following error: ValueError('\nAll the 10 fits failed.\nIt is very likely that your model is misconfigured.\nYou can try to debug the error by setting error_score=\'raise\'.\n\nBelow are more details about the failures:\n--------------------------------------------------------------------------------\n5 fits failed with the following error:\nTraceback (most recent call last):\n  File "/usr/local/lib/python3.8/dist-packages/sklearn/model_selection/_validation.py", line 686, in _fit_and_score\n    estimator.fit(X_train, y_train, **fit_params)\n  File "/usr/local/lib/python3.8/dist-packages/sklearn/pipeline.py", line 378, in fit\n    Xt = self._fit(X, y, **fit_params_steps)\n  File "/usr/local/lib/python3.8/dist-packages/sklearn/pipeline.py", line 336, in _fit\n    X, fitted_transformer = fit_transform_one_cached(\n  File "/usr/local/lib/python3.8/dist-packages/joblib/memory.py", line 349, in __call__\n    return self.func(*args, **kwargs)\n  File "/usr/local/lib/python3.8/dist-packages/sklearn/pipeline.py", line 870, in _fit_transform_one\n    res = transformer.fit_transform(X, y, **fit_params)\n  File "/usr/local/lib/python3.8/dist-packages/sklearn/base.py", line 870, in fit_transform\n    return self.fit(X, y, **fit_params).transform(X)\n  File "/usr/local/lib/python3.8/dist-packages/sklearn/preprocessing/_polynomial.py", line 432, in transform\n    XP = np.empty(\nnumpy.core._exceptions._ArrayMemoryError: Unable to allocate 22.2 PiB for an array with shape (211, 14833897694226) and data type float64\n\n--------------------------------------------------------------------------------\n5 fits failed with the following error:\nTraceback (most recent call last):\n  File "/usr/local/lib/python3.8/dist-packages/sklearn/model_selection/_validation.py", line 686, in _fit_and_score\n    estimator.fit(X_train, y_train, **fit_params)\n  File "/usr/local/lib/python3.8/dist-packages/sklearn/pipeline.py", line 378, in fit\n    Xt = self._fit(X, y, **fit_params_steps)\n  File "/usr/local/lib/python3.8/dist-packages/sklearn/pipeline.py", line 336, in _fit\n    X, fitted_transformer = fit_transform_one_cached(\n  File "/usr/local/lib/python3.8/dist-packages/joblib/memory.py", line 349, in __call__\n    return self.func(*args, **kwargs)\n  File "/usr/local/lib/python3.8/dist-packages/sklearn/pipeline.py", line 870, in _fit_transform_one\n    res = transformer.fit_transform(X, y, **fit_params)\n  File "/usr/local/lib/python3.8/dist-packages/sklearn/base.py", line 870, in fit_transform\n    return self.fit(X, y, **fit_params).transform(X)\n  File "/usr/local/lib/python3.8/dist-packages/sklearn/preprocessing/_polynomial.py", line 432, in transform\n    XP = np.empty(\nnumpy.core._exceptions._ArrayMemoryError: Unable to allocate 22.3 PiB for an array with shape (212, 14833897694226) and data type float64\n')
Traceback (most recent call last):
  File "/usr/local/lib/python3.8/dist-packages/optuna/study/_optimize.py", line 196, in _run_trial
    value_or_values = func(trial)
  File "/tmp/ipykernel_7443/2264325072.py", line 23, in __call__
    scores = cross_validate(estimator=model, scoring=metrics,
  File "/usr/local/lib/python3.8/dist-packages/sklearn/model_selection/_validation.py", line 285, in cross_validate
    _warn_or_raise_about_fit_failures(results, error_score)
  File "/usr/local/lib/python3.8/dist-packages/sklearn/model_selection/_validation.py", line 367, in _warn_or_raise_about_fit_failures
    raise ValueError(all_fits_failed_message)
ValueError: 
All the 10 fits failed.
It is very likely that your model is misconfigured.
You can try to debug the error by setting error_score='raise'.

Below are more details about the failures:
--------------------------------------------------------------------------------
5 fits failed with the following error:
Traceback (most recent call last):
  File "/usr/local/lib/python3.8/dist-packages/sklearn/model_selection/_validation.py", line 686, in _fit_and_score
    estimator.fit(X_train, y_train, **fit_params)
  File "/usr/local/lib/python3.8/dist-packages/sklearn/pipeline.py", line 378, in fit
    Xt = self._fit(X, y, **fit_params_steps)
  File "/usr/local/lib/python3.8/dist-packages/sklearn/pipeline.py", line 336, in _fit
    X, fitted_transformer = fit_transform_one_cached(
  File "/usr/local/lib/python3.8/dist-packages/joblib/memory.py", line 349, in __call__
    return self.func(*args, **kwargs)
  File "/usr/local/lib/python3.8/dist-packages/sklearn/pipeline.py", line 870, in _fit_transform_one
    res = transformer.fit_transform(X, y, **fit_params)
  File "/usr/local/lib/python3.8/dist-packages/sklearn/base.py", line 870, in fit_transform
    return self.fit(X, y, **fit_params).transform(X)
  File "/usr/local/lib/python3.8/dist-packages/sklearn/preprocessing/_polynomial.py", line 432, in transform
    XP = np.empty(
numpy.core._exceptions._ArrayMemoryError: Unable to allocate 22.2 PiB for an array with shape (211, 14833897694226) and data type float64

--------------------------------------------------------------------------------
5 fits failed with the following error:
Traceback (most recent call last):
  File "/usr/local/lib/python3.8/dist-packages/sklearn/model_selection/_validation.py", line 686, in _fit_and_score
    estimator.fit(X_train, y_train, **fit_params)
  File "/usr/local/lib/python3.8/dist-packages/sklearn/pipeline.py", line 378, in fit
    Xt = self._fit(X, y, **fit_params_steps)
  File "/usr/local/lib/python3.8/dist-packages/sklearn/pipeline.py", line 336, in _fit
    X, fitted_transformer = fit_transform_one_cached(
  File "/usr/local/lib/python3.8/dist-packages/joblib/memory.py", line 349, in __call__
    return self.func(*args, **kwargs)
  File "/usr/local/lib/python3.8/dist-packages/sklearn/pipeline.py", line 870, in _fit_transform_one
    res = transformer.fit_transform(X, y, **fit_params)
  File "/usr/local/lib/python3.8/dist-packages/sklearn/base.py", line 870, in fit_transform
    return self.fit(X, y, **fit_params).transform(X)
  File "/usr/local/lib/python3.8/dist-packages/sklearn/preprocessing/_polynomial.py", line 432, in transform
    XP = np.empty(
numpy.core._exceptions._ArrayMemoryError: Unable to allocate 22.3 PiB for an array with shape (212, 14833897694226) and data type float64

Trial 10 failed because of the following error: ValueError('\nAll the 10 fits failed.\nIt is very likely that your model is misconfigured.\nYou can try to debug the error by setting error_score=\'raise\'.\n\nBelow are more details about the failures:\n--------------------------------------------------------------------------------\n10 fits failed with the following error:\nTraceback (most recent call last):\n  File "/usr/local/lib/python3.8/dist-packages/sklearn/model_selection/_validation.py", line 686, in _fit_and_score\n    estimator.fit(X_train, y_train, **fit_params)\n  File "/usr/local/lib/python3.8/dist-packages/sklearn/pipeline.py", line 378, in fit\n    Xt = self._fit(X, y, **fit_params_steps)\n  File "/usr/local/lib/python3.8/dist-packages/sklearn/pipeline.py", line 336, in _fit\n    X, fitted_transformer = fit_transform_one_cached(\n  File "/usr/local/lib/python3.8/dist-packages/joblib/memory.py", line 349, in __call__\n    return self.func(*args, **kwargs)\n  File "/usr/local/lib/python3.8/dist-packages/sklearn/pipeline.py", line 870, in _fit_transform_one\n    res = transformer.fit_transform(X, y, **fit_params)\n  File "/usr/local/lib/python3.8/dist-packages/sklearn/base.py", line 870, in fit_transform\n    return self.fit(X, y, **fit_params).transform(X)\n  File "/usr/local/lib/python3.8/dist-packages/sklearn/preprocessing/_polynomial.py", line 432, in transform\n    XP = np.empty(\nValueError: array is too big; `arr.size * arr.dtype.itemsize` is larger than the maximum possible size.\n')
Traceback (most recent call last):
  File "/usr/local/lib/python3.8/dist-packages/optuna/study/_optimize.py", line 196, in _run_trial
    value_or_values = func(trial)
  File "/tmp/ipykernel_7443/2264325072.py", line 23, in __call__
    scores = cross_validate(estimator=model, scoring=metrics,
  File "/usr/local/lib/python3.8/dist-packages/sklearn/model_selection/_validation.py", line 285, in cross_validate
    _warn_or_raise_about_fit_failures(results, error_score)
  File "/usr/local/lib/python3.8/dist-packages/sklearn/model_selection/_validation.py", line 367, in _warn_or_raise_about_fit_failures
    raise ValueError(all_fits_failed_message)
ValueError: 
All the 10 fits failed.
It is very likely that your model is misconfigured.
You can try to debug the error by setting error_score='raise'.

Below are more details about the failures:
--------------------------------------------------------------------------------
10 fits failed with the following error:
Traceback (most recent call last):
  File "/usr/local/lib/python3.8/dist-packages/sklearn/model_selection/_validation.py", line 686, in _fit_and_score
    estimator.fit(X_train, y_train, **fit_params)
  File "/usr/local/lib/python3.8/dist-packages/sklearn/pipeline.py", line 378, in fit
    Xt = self._fit(X, y, **fit_params_steps)
  File "/usr/local/lib/python3.8/dist-packages/sklearn/pipeline.py", line 336, in _fit
    X, fitted_transformer = fit_transform_one_cached(
  File "/usr/local/lib/python3.8/dist-packages/joblib/memory.py", line 349, in __call__
    return self.func(*args, **kwargs)
  File "/usr/local/lib/python3.8/dist-packages/sklearn/pipeline.py", line 870, in _fit_transform_one
    res = transformer.fit_transform(X, y, **fit_params)
  File "/usr/local/lib/python3.8/dist-packages/sklearn/base.py", line 870, in fit_transform
    return self.fit(X, y, **fit_params).transform(X)
  File "/usr/local/lib/python3.8/dist-packages/sklearn/preprocessing/_polynomial.py", line 432, in transform
    XP = np.empty(
ValueError: array is too big; `arr.size * arr.dtype.itemsize` is larger than the maximum possible size.

Trial 15 failed because of the following error: ValueError('\nAll the 10 fits failed.\nIt is very likely that your model is misconfigured.\nYou can try to debug the error by setting error_score=\'raise\'.\n\nBelow are more details about the failures:\n--------------------------------------------------------------------------------\n10 fits failed with the following error:\nTraceback (most recent call last):\n  File "/usr/local/lib/python3.8/dist-packages/sklearn/model_selection/_validation.py", line 686, in _fit_and_score\n    estimator.fit(X_train, y_train, **fit_params)\n  File "/usr/local/lib/python3.8/dist-packages/sklearn/pipeline.py", line 378, in fit\n    Xt = self._fit(X, y, **fit_params_steps)\n  File "/usr/local/lib/python3.8/dist-packages/sklearn/pipeline.py", line 336, in _fit\n    X, fitted_transformer = fit_transform_one_cached(\n  File "/usr/local/lib/python3.8/dist-packages/joblib/memory.py", line 349, in __call__\n    return self.func(*args, **kwargs)\n  File "/usr/local/lib/python3.8/dist-packages/sklearn/pipeline.py", line 870, in _fit_transform_one\n    res = transformer.fit_transform(X, y, **fit_params)\n  File "/usr/local/lib/python3.8/dist-packages/sklearn/base.py", line 870, in fit_transform\n    return self.fit(X, y, **fit_params).transform(X)\n  File "/usr/local/lib/python3.8/dist-packages/sklearn/preprocessing/_polynomial.py", line 432, in transform\n    XP = np.empty(\nValueError: array is too big; `arr.size * arr.dtype.itemsize` is larger than the maximum possible size.\n')
Traceback (most recent call last):
  File "/usr/local/lib/python3.8/dist-packages/optuna/study/_optimize.py", line 196, in _run_trial
    value_or_values = func(trial)
  File "/tmp/ipykernel_7443/2264325072.py", line 23, in __call__
    scores = cross_validate(estimator=model, scoring=metrics,
  File "/usr/local/lib/python3.8/dist-packages/sklearn/model_selection/_validation.py", line 285, in cross_validate
    _warn_or_raise_about_fit_failures(results, error_score)
  File "/usr/local/lib/python3.8/dist-packages/sklearn/model_selection/_validation.py", line 367, in _warn_or_raise_about_fit_failures
    raise ValueError(all_fits_failed_message)
ValueError: 
All the 10 fits failed.
It is very likely that your model is misconfigured.
You can try to debug the error by setting error_score='raise'.

Below are more details about the failures:
--------------------------------------------------------------------------------
10 fits failed with the following error:
Traceback (most recent call last):
  File "/usr/local/lib/python3.8/dist-packages/sklearn/model_selection/_validation.py", line 686, in _fit_and_score
    estimator.fit(X_train, y_train, **fit_params)
  File "/usr/local/lib/python3.8/dist-packages/sklearn/pipeline.py", line 378, in fit
    Xt = self._fit(X, y, **fit_params_steps)
  File "/usr/local/lib/python3.8/dist-packages/sklearn/pipeline.py", line 336, in _fit
    X, fitted_transformer = fit_transform_one_cached(
  File "/usr/local/lib/python3.8/dist-packages/joblib/memory.py", line 349, in __call__
    return self.func(*args, **kwargs)
  File "/usr/local/lib/python3.8/dist-packages/sklearn/pipeline.py", line 870, in _fit_transform_one
    res = transformer.fit_transform(X, y, **fit_params)
  File "/usr/local/lib/python3.8/dist-packages/sklearn/base.py", line 870, in fit_transform
    return self.fit(X, y, **fit_params).transform(X)
  File "/usr/local/lib/python3.8/dist-packages/sklearn/preprocessing/_polynomial.py", line 432, in transform
    XP = np.empty(
ValueError: array is too big; `arr.size * arr.dtype.itemsize` is larger than the maximum possible size.

Trial 13 failed because of the following error: ValueError('\nAll the 10 fits failed.\nIt is very likely that your model is misconfigured.\nYou can try to debug the error by setting error_score=\'raise\'.\n\nBelow are more details about the failures:\n--------------------------------------------------------------------------------\n10 fits failed with the following error:\nTraceback (most recent call last):\n  File "/usr/local/lib/python3.8/dist-packages/sklearn/model_selection/_validation.py", line 686, in _fit_and_score\n    estimator.fit(X_train, y_train, **fit_params)\n  File "/usr/local/lib/python3.8/dist-packages/sklearn/pipeline.py", line 378, in fit\n    Xt = self._fit(X, y, **fit_params_steps)\n  File "/usr/local/lib/python3.8/dist-packages/sklearn/pipeline.py", line 336, in _fit\n    X, fitted_transformer = fit_transform_one_cached(\n  File "/usr/local/lib/python3.8/dist-packages/joblib/memory.py", line 349, in __call__\n    return self.func(*args, **kwargs)\n  File "/usr/local/lib/python3.8/dist-packages/sklearn/pipeline.py", line 870, in _fit_transform_one\n    res = transformer.fit_transform(X, y, **fit_params)\n  File "/usr/local/lib/python3.8/dist-packages/sklearn/base.py", line 870, in fit_transform\n    return self.fit(X, y, **fit_params).transform(X)\n  File "/usr/local/lib/python3.8/dist-packages/sklearn/preprocessing/_polynomial.py", line 432, in transform\n    XP = np.empty(\nValueError: Maximum allowed dimension exceeded\n')
Traceback (most recent call last):
  File "/usr/local/lib/python3.8/dist-packages/optuna/study/_optimize.py", line 196, in _run_trial
    value_or_values = func(trial)
  File "/tmp/ipykernel_7443/2264325072.py", line 23, in __call__
    scores = cross_validate(estimator=model, scoring=metrics,
  File "/usr/local/lib/python3.8/dist-packages/sklearn/model_selection/_validation.py", line 285, in cross_validate
    _warn_or_raise_about_fit_failures(results, error_score)
  File "/usr/local/lib/python3.8/dist-packages/sklearn/model_selection/_validation.py", line 367, in _warn_or_raise_about_fit_failures
    raise ValueError(all_fits_failed_message)
ValueError: 
All the 10 fits failed.
It is very likely that your model is misconfigured.
You can try to debug the error by setting error_score='raise'.

Below are more details about the failures:
--------------------------------------------------------------------------------
10 fits failed with the following error:
Traceback (most recent call last):
  File "/usr/local/lib/python3.8/dist-packages/sklearn/model_selection/_validation.py", line 686, in _fit_and_score
    estimator.fit(X_train, y_train, **fit_params)
  File "/usr/local/lib/python3.8/dist-packages/sklearn/pipeline.py", line 378, in fit
    Xt = self._fit(X, y, **fit_params_steps)
  File "/usr/local/lib/python3.8/dist-packages/sklearn/pipeline.py", line 336, in _fit
    X, fitted_transformer = fit_transform_one_cached(
  File "/usr/local/lib/python3.8/dist-packages/joblib/memory.py", line 349, in __call__
    return self.func(*args, **kwargs)
  File "/usr/local/lib/python3.8/dist-packages/sklearn/pipeline.py", line 870, in _fit_transform_one
    res = transformer.fit_transform(X, y, **fit_params)
  File "/usr/local/lib/python3.8/dist-packages/sklearn/base.py", line 870, in fit_transform
    return self.fit(X, y, **fit_params).transform(X)
  File "/usr/local/lib/python3.8/dist-packages/sklearn/preprocessing/_polynomial.py", line 432, in transform
    XP = np.empty(
ValueError: Maximum allowed dimension exceeded

Trial 19 failed because of the following error: ValueError('\nAll the 10 fits failed.\nIt is very likely that your model is misconfigured.\nYou can try to debug the error by setting error_score=\'raise\'.\n\nBelow are more details about the failures:\n--------------------------------------------------------------------------------\n10 fits failed with the following error:\nTraceback (most recent call last):\n  File "/usr/local/lib/python3.8/dist-packages/sklearn/model_selection/_validation.py", line 686, in _fit_and_score\n    estimator.fit(X_train, y_train, **fit_params)\n  File "/usr/local/lib/python3.8/dist-packages/sklearn/pipeline.py", line 378, in fit\n    Xt = self._fit(X, y, **fit_params_steps)\n  File "/usr/local/lib/python3.8/dist-packages/sklearn/pipeline.py", line 336, in _fit\n    X, fitted_transformer = fit_transform_one_cached(\n  File "/usr/local/lib/python3.8/dist-packages/joblib/memory.py", line 349, in __call__\n    return self.func(*args, **kwargs)\n  File "/usr/local/lib/python3.8/dist-packages/sklearn/pipeline.py", line 870, in _fit_transform_one\n    res = transformer.fit_transform(X, y, **fit_params)\n  File "/usr/local/lib/python3.8/dist-packages/sklearn/base.py", line 870, in fit_transform\n    return self.fit(X, y, **fit_params).transform(X)\n  File "/usr/local/lib/python3.8/dist-packages/sklearn/preprocessing/_polynomial.py", line 432, in transform\n    XP = np.empty(\nValueError: array is too big; `arr.size * arr.dtype.itemsize` is larger than the maximum possible size.\n')
Traceback (most recent call last):
  File "/usr/local/lib/python3.8/dist-packages/optuna/study/_optimize.py", line 196, in _run_trial
    value_or_values = func(trial)
  File "/tmp/ipykernel_7443/2264325072.py", line 23, in __call__
    scores = cross_validate(estimator=model, scoring=metrics,
  File "/usr/local/lib/python3.8/dist-packages/sklearn/model_selection/_validation.py", line 285, in cross_validate
    _warn_or_raise_about_fit_failures(results, error_score)
  File "/usr/local/lib/python3.8/dist-packages/sklearn/model_selection/_validation.py", line 367, in _warn_or_raise_about_fit_failures
    raise ValueError(all_fits_failed_message)
ValueError: 
All the 10 fits failed.
It is very likely that your model is misconfigured.
You can try to debug the error by setting error_score='raise'.

Below are more details about the failures:
--------------------------------------------------------------------------------
10 fits failed with the following error:
Traceback (most recent call last):
  File "/usr/local/lib/python3.8/dist-packages/sklearn/model_selection/_validation.py", line 686, in _fit_and_score
    estimator.fit(X_train, y_train, **fit_params)
  File "/usr/local/lib/python3.8/dist-packages/sklearn/pipeline.py", line 378, in fit
    Xt = self._fit(X, y, **fit_params_steps)
  File "/usr/local/lib/python3.8/dist-packages/sklearn/pipeline.py", line 336, in _fit
    X, fitted_transformer = fit_transform_one_cached(
  File "/usr/local/lib/python3.8/dist-packages/joblib/memory.py", line 349, in __call__
    return self.func(*args, **kwargs)
  File "/usr/local/lib/python3.8/dist-packages/sklearn/pipeline.py", line 870, in _fit_transform_one
    res = transformer.fit_transform(X, y, **fit_params)
  File "/usr/local/lib/python3.8/dist-packages/sklearn/base.py", line 870, in fit_transform
    return self.fit(X, y, **fit_params).transform(X)
  File "/usr/local/lib/python3.8/dist-packages/sklearn/preprocessing/_polynomial.py", line 432, in transform
    XP = np.empty(
ValueError: array is too big; `arr.size * arr.dtype.itemsize` is larger than the maximum possible size.

Trial 20 failed because of the following error: ValueError('\nAll the 10 fits failed.\nIt is very likely that your model is misconfigured.\nYou can try to debug the error by setting error_score=\'raise\'.\n\nBelow are more details about the failures:\n--------------------------------------------------------------------------------\n10 fits failed with the following error:\nTraceback (most recent call last):\n  File "/usr/local/lib/python3.8/dist-packages/sklearn/model_selection/_validation.py", line 686, in _fit_and_score\n    estimator.fit(X_train, y_train, **fit_params)\n  File "/usr/local/lib/python3.8/dist-packages/sklearn/pipeline.py", line 378, in fit\n    Xt = self._fit(X, y, **fit_params_steps)\n  File "/usr/local/lib/python3.8/dist-packages/sklearn/pipeline.py", line 336, in _fit\n    X, fitted_transformer = fit_transform_one_cached(\n  File "/usr/local/lib/python3.8/dist-packages/joblib/memory.py", line 349, in __call__\n    return self.func(*args, **kwargs)\n  File "/usr/local/lib/python3.8/dist-packages/sklearn/pipeline.py", line 870, in _fit_transform_one\n    res = transformer.fit_transform(X, y, **fit_params)\n  File "/usr/local/lib/python3.8/dist-packages/sklearn/base.py", line 870, in fit_transform\n    return self.fit(X, y, **fit_params).transform(X)\n  File "/usr/local/lib/python3.8/dist-packages/sklearn/preprocessing/_polynomial.py", line 432, in transform\n    XP = np.empty(\nValueError: Maximum allowed dimension exceeded\n')
Traceback (most recent call last):
  File "/usr/local/lib/python3.8/dist-packages/optuna/study/_optimize.py", line 196, in _run_trial
    value_or_values = func(trial)
  File "/tmp/ipykernel_7443/2264325072.py", line 23, in __call__
    scores = cross_validate(estimator=model, scoring=metrics,
  File "/usr/local/lib/python3.8/dist-packages/sklearn/model_selection/_validation.py", line 285, in cross_validate
    _warn_or_raise_about_fit_failures(results, error_score)
  File "/usr/local/lib/python3.8/dist-packages/sklearn/model_selection/_validation.py", line 367, in _warn_or_raise_about_fit_failures
    raise ValueError(all_fits_failed_message)
ValueError: 
All the 10 fits failed.
It is very likely that your model is misconfigured.
You can try to debug the error by setting error_score='raise'.

Below are more details about the failures:
--------------------------------------------------------------------------------
10 fits failed with the following error:
Traceback (most recent call last):
  File "/usr/local/lib/python3.8/dist-packages/sklearn/model_selection/_validation.py", line 686, in _fit_and_score
    estimator.fit(X_train, y_train, **fit_params)
  File "/usr/local/lib/python3.8/dist-packages/sklearn/pipeline.py", line 378, in fit
    Xt = self._fit(X, y, **fit_params_steps)
  File "/usr/local/lib/python3.8/dist-packages/sklearn/pipeline.py", line 336, in _fit
    X, fitted_transformer = fit_transform_one_cached(
  File "/usr/local/lib/python3.8/dist-packages/joblib/memory.py", line 349, in __call__
    return self.func(*args, **kwargs)
  File "/usr/local/lib/python3.8/dist-packages/sklearn/pipeline.py", line 870, in _fit_transform_one
    res = transformer.fit_transform(X, y, **fit_params)
  File "/usr/local/lib/python3.8/dist-packages/sklearn/base.py", line 870, in fit_transform
    return self.fit(X, y, **fit_params).transform(X)
  File "/usr/local/lib/python3.8/dist-packages/sklearn/preprocessing/_polynomial.py", line 432, in transform
    XP = np.empty(
ValueError: Maximum allowed dimension exceeded

Trial 6 failed because of the following error: ValueError('\nAll the 10 fits failed.\nIt is very likely that your model is misconfigured.\nYou can try to debug the error by setting error_score=\'raise\'.\n\nBelow are more details about the failures:\n--------------------------------------------------------------------------------\n10 fits failed with the following error:\nTraceback (most recent call last):\n  File "/usr/local/lib/python3.8/dist-packages/sklearn/model_selection/_validation.py", line 686, in _fit_and_score\n    estimator.fit(X_train, y_train, **fit_params)\n  File "/usr/local/lib/python3.8/dist-packages/sklearn/pipeline.py", line 378, in fit\n    Xt = self._fit(X, y, **fit_params_steps)\n  File "/usr/local/lib/python3.8/dist-packages/sklearn/pipeline.py", line 336, in _fit\n    X, fitted_transformer = fit_transform_one_cached(\n  File "/usr/local/lib/python3.8/dist-packages/joblib/memory.py", line 349, in __call__\n    return self.func(*args, **kwargs)\n  File "/usr/local/lib/python3.8/dist-packages/sklearn/pipeline.py", line 870, in _fit_transform_one\n    res = transformer.fit_transform(X, y, **fit_params)\n  File "/usr/local/lib/python3.8/dist-packages/sklearn/base.py", line 870, in fit_transform\n    return self.fit(X, y, **fit_params).transform(X)\n  File "/usr/local/lib/python3.8/dist-packages/sklearn/preprocessing/_polynomial.py", line 432, in transform\n    XP = np.empty(\nValueError: Maximum allowed dimension exceeded\n')
Traceback (most recent call last):
  File "/usr/local/lib/python3.8/dist-packages/optuna/study/_optimize.py", line 196, in _run_trial
    value_or_values = func(trial)
  File "/tmp/ipykernel_7443/2264325072.py", line 23, in __call__
    scores = cross_validate(estimator=model, scoring=metrics,
  File "/usr/local/lib/python3.8/dist-packages/sklearn/model_selection/_validation.py", line 285, in cross_validate
    _warn_or_raise_about_fit_failures(results, error_score)
  File "/usr/local/lib/python3.8/dist-packages/sklearn/model_selection/_validation.py", line 367, in _warn_or_raise_about_fit_failures
    raise ValueError(all_fits_failed_message)
ValueError: 
All the 10 fits failed.
It is very likely that your model is misconfigured.
You can try to debug the error by setting error_score='raise'.

Below are more details about the failures:
--------------------------------------------------------------------------------
10 fits failed with the following error:
Traceback (most recent call last):
  File "/usr/local/lib/python3.8/dist-packages/sklearn/model_selection/_validation.py", line 686, in _fit_and_score
    estimator.fit(X_train, y_train, **fit_params)
  File "/usr/local/lib/python3.8/dist-packages/sklearn/pipeline.py", line 378, in fit
    Xt = self._fit(X, y, **fit_params_steps)
  File "/usr/local/lib/python3.8/dist-packages/sklearn/pipeline.py", line 336, in _fit
    X, fitted_transformer = fit_transform_one_cached(
  File "/usr/local/lib/python3.8/dist-packages/joblib/memory.py", line 349, in __call__
    return self.func(*args, **kwargs)
  File "/usr/local/lib/python3.8/dist-packages/sklearn/pipeline.py", line 870, in _fit_transform_one
    res = transformer.fit_transform(X, y, **fit_params)
  File "/usr/local/lib/python3.8/dist-packages/sklearn/base.py", line 870, in fit_transform
    return self.fit(X, y, **fit_params).transform(X)
  File "/usr/local/lib/python3.8/dist-packages/sklearn/preprocessing/_polynomial.py", line 432, in transform
    XP = np.empty(
ValueError: Maximum allowed dimension exceeded

Trial 23 failed because of the following error: ValueError('\nAll the 10 fits failed.\nIt is very likely that your model is misconfigured.\nYou can try to debug the error by setting error_score=\'raise\'.\n\nBelow are more details about the failures:\n--------------------------------------------------------------------------------\n10 fits failed with the following error:\nTraceback (most recent call last):\n  File "/usr/local/lib/python3.8/dist-packages/sklearn/model_selection/_validation.py", line 686, in _fit_and_score\n    estimator.fit(X_train, y_train, **fit_params)\n  File "/usr/local/lib/python3.8/dist-packages/sklearn/pipeline.py", line 378, in fit\n    Xt = self._fit(X, y, **fit_params_steps)\n  File "/usr/local/lib/python3.8/dist-packages/sklearn/pipeline.py", line 336, in _fit\n    X, fitted_transformer = fit_transform_one_cached(\n  File "/usr/local/lib/python3.8/dist-packages/joblib/memory.py", line 349, in __call__\n    return self.func(*args, **kwargs)\n  File "/usr/local/lib/python3.8/dist-packages/sklearn/pipeline.py", line 870, in _fit_transform_one\n    res = transformer.fit_transform(X, y, **fit_params)\n  File "/usr/local/lib/python3.8/dist-packages/sklearn/base.py", line 870, in fit_transform\n    return self.fit(X, y, **fit_params).transform(X)\n  File "/usr/local/lib/python3.8/dist-packages/sklearn/preprocessing/_polynomial.py", line 432, in transform\n    XP = np.empty(\nValueError: Maximum allowed dimension exceeded\n')
Traceback (most recent call last):
  File "/usr/local/lib/python3.8/dist-packages/optuna/study/_optimize.py", line 196, in _run_trial
    value_or_values = func(trial)
  File "/tmp/ipykernel_7443/2264325072.py", line 23, in __call__
    scores = cross_validate(estimator=model, scoring=metrics,
  File "/usr/local/lib/python3.8/dist-packages/sklearn/model_selection/_validation.py", line 285, in cross_validate
    _warn_or_raise_about_fit_failures(results, error_score)
  File "/usr/local/lib/python3.8/dist-packages/sklearn/model_selection/_validation.py", line 367, in _warn_or_raise_about_fit_failures
    raise ValueError(all_fits_failed_message)
ValueError: 
All the 10 fits failed.
It is very likely that your model is misconfigured.
You can try to debug the error by setting error_score='raise'.

Below are more details about the failures:
--------------------------------------------------------------------------------
10 fits failed with the following error:
Traceback (most recent call last):
  File "/usr/local/lib/python3.8/dist-packages/sklearn/model_selection/_validation.py", line 686, in _fit_and_score
    estimator.fit(X_train, y_train, **fit_params)
  File "/usr/local/lib/python3.8/dist-packages/sklearn/pipeline.py", line 378, in fit
    Xt = self._fit(X, y, **fit_params_steps)
  File "/usr/local/lib/python3.8/dist-packages/sklearn/pipeline.py", line 336, in _fit
    X, fitted_transformer = fit_transform_one_cached(
  File "/usr/local/lib/python3.8/dist-packages/joblib/memory.py", line 349, in __call__
    return self.func(*args, **kwargs)
  File "/usr/local/lib/python3.8/dist-packages/sklearn/pipeline.py", line 870, in _fit_transform_one
    res = transformer.fit_transform(X, y, **fit_params)
  File "/usr/local/lib/python3.8/dist-packages/sklearn/base.py", line 870, in fit_transform
    return self.fit(X, y, **fit_params).transform(X)
  File "/usr/local/lib/python3.8/dist-packages/sklearn/preprocessing/_polynomial.py", line 432, in transform
    XP = np.empty(
ValueError: Maximum allowed dimension exceeded

Trial 21 failed because of the following error: ValueError('\nAll the 10 fits failed.\nIt is very likely that your model is misconfigured.\nYou can try to debug the error by setting error_score=\'raise\'.\n\nBelow are more details about the failures:\n--------------------------------------------------------------------------------\n5 fits failed with the following error:\nTraceback (most recent call last):\n  File "/usr/local/lib/python3.8/dist-packages/sklearn/model_selection/_validation.py", line 686, in _fit_and_score\n    estimator.fit(X_train, y_train, **fit_params)\n  File "/usr/local/lib/python3.8/dist-packages/sklearn/pipeline.py", line 378, in fit\n    Xt = self._fit(X, y, **fit_params_steps)\n  File "/usr/local/lib/python3.8/dist-packages/sklearn/pipeline.py", line 336, in _fit\n    X, fitted_transformer = fit_transform_one_cached(\n  File "/usr/local/lib/python3.8/dist-packages/joblib/memory.py", line 349, in __call__\n    return self.func(*args, **kwargs)\n  File "/usr/local/lib/python3.8/dist-packages/sklearn/pipeline.py", line 870, in _fit_transform_one\n    res = transformer.fit_transform(X, y, **fit_params)\n  File "/usr/local/lib/python3.8/dist-packages/sklearn/base.py", line 870, in fit_transform\n    return self.fit(X, y, **fit_params).transform(X)\n  File "/usr/local/lib/python3.8/dist-packages/sklearn/preprocessing/_polynomial.py", line 432, in transform\n    XP = np.empty(\nnumpy.core._exceptions._ArrayMemoryError: Unable to allocate 41.1 PiB for an array with shape (211, 27385657281648) and data type float64\n\n--------------------------------------------------------------------------------\n5 fits failed with the following error:\nTraceback (most recent call last):\n  File "/usr/local/lib/python3.8/dist-packages/sklearn/model_selection/_validation.py", line 686, in _fit_and_score\n    estimator.fit(X_train, y_train, **fit_params)\n  File "/usr/local/lib/python3.8/dist-packages/sklearn/pipeline.py", line 378, in fit\n    Xt = self._fit(X, y, **fit_params_steps)\n  File "/usr/local/lib/python3.8/dist-packages/sklearn/pipeline.py", line 336, in _fit\n    X, fitted_transformer = fit_transform_one_cached(\n  File "/usr/local/lib/python3.8/dist-packages/joblib/memory.py", line 349, in __call__\n    return self.func(*args, **kwargs)\n  File "/usr/local/lib/python3.8/dist-packages/sklearn/pipeline.py", line 870, in _fit_transform_one\n    res = transformer.fit_transform(X, y, **fit_params)\n  File "/usr/local/lib/python3.8/dist-packages/sklearn/base.py", line 870, in fit_transform\n    return self.fit(X, y, **fit_params).transform(X)\n  File "/usr/local/lib/python3.8/dist-packages/sklearn/preprocessing/_polynomial.py", line 432, in transform\n    XP = np.empty(\nnumpy.core._exceptions._ArrayMemoryError: Unable to allocate 41.3 PiB for an array with shape (212, 27385657281648) and data type float64\n')
Traceback (most recent call last):
  File "/usr/local/lib/python3.8/dist-packages/optuna/study/_optimize.py", line 196, in _run_trial
    value_or_values = func(trial)
  File "/tmp/ipykernel_7443/2264325072.py", line 23, in __call__
    scores = cross_validate(estimator=model, scoring=metrics,
  File "/usr/local/lib/python3.8/dist-packages/sklearn/model_selection/_validation.py", line 285, in cross_validate
    _warn_or_raise_about_fit_failures(results, error_score)
  File "/usr/local/lib/python3.8/dist-packages/sklearn/model_selection/_validation.py", line 367, in _warn_or_raise_about_fit_failures
    raise ValueError(all_fits_failed_message)
ValueError: 
All the 10 fits failed.
It is very likely that your model is misconfigured.
You can try to debug the error by setting error_score='raise'.

Below are more details about the failures:
--------------------------------------------------------------------------------
5 fits failed with the following error:
Traceback (most recent call last):
  File "/usr/local/lib/python3.8/dist-packages/sklearn/model_selection/_validation.py", line 686, in _fit_and_score
    estimator.fit(X_train, y_train, **fit_params)
  File "/usr/local/lib/python3.8/dist-packages/sklearn/pipeline.py", line 378, in fit
    Xt = self._fit(X, y, **fit_params_steps)
  File "/usr/local/lib/python3.8/dist-packages/sklearn/pipeline.py", line 336, in _fit
    X, fitted_transformer = fit_transform_one_cached(
  File "/usr/local/lib/python3.8/dist-packages/joblib/memory.py", line 349, in __call__
    return self.func(*args, **kwargs)
  File "/usr/local/lib/python3.8/dist-packages/sklearn/pipeline.py", line 870, in _fit_transform_one
    res = transformer.fit_transform(X, y, **fit_params)
  File "/usr/local/lib/python3.8/dist-packages/sklearn/base.py", line 870, in fit_transform
    return self.fit(X, y, **fit_params).transform(X)
  File "/usr/local/lib/python3.8/dist-packages/sklearn/preprocessing/_polynomial.py", line 432, in transform
    XP = np.empty(
numpy.core._exceptions._ArrayMemoryError: Unable to allocate 41.1 PiB for an array with shape (211, 27385657281648) and data type float64

--------------------------------------------------------------------------------
5 fits failed with the following error:
Traceback (most recent call last):
  File "/usr/local/lib/python3.8/dist-packages/sklearn/model_selection/_validation.py", line 686, in _fit_and_score
    estimator.fit(X_train, y_train, **fit_params)
  File "/usr/local/lib/python3.8/dist-packages/sklearn/pipeline.py", line 378, in fit
    Xt = self._fit(X, y, **fit_params_steps)
  File "/usr/local/lib/python3.8/dist-packages/sklearn/pipeline.py", line 336, in _fit
    X, fitted_transformer = fit_transform_one_cached(
  File "/usr/local/lib/python3.8/dist-packages/joblib/memory.py", line 349, in __call__
    return self.func(*args, **kwargs)
  File "/usr/local/lib/python3.8/dist-packages/sklearn/pipeline.py", line 870, in _fit_transform_one
    res = transformer.fit_transform(X, y, **fit_params)
  File "/usr/local/lib/python3.8/dist-packages/sklearn/base.py", line 870, in fit_transform
    return self.fit(X, y, **fit_params).transform(X)
  File "/usr/local/lib/python3.8/dist-packages/sklearn/preprocessing/_polynomial.py", line 432, in transform
    XP = np.empty(
numpy.core._exceptions._ArrayMemoryError: Unable to allocate 41.3 PiB for an array with shape (212, 27385657281648) and data type float64

Trial 17 failed because of the following error: ValueError('\nAll the 10 fits failed.\nIt is very likely that your model is misconfigured.\nYou can try to debug the error by setting error_score=\'raise\'.\n\nBelow are more details about the failures:\n--------------------------------------------------------------------------------\n5 fits failed with the following error:\nTraceback (most recent call last):\n  File "/usr/local/lib/python3.8/dist-packages/sklearn/model_selection/_validation.py", line 686, in _fit_and_score\n    estimator.fit(X_train, y_train, **fit_params)\n  File "/usr/local/lib/python3.8/dist-packages/sklearn/pipeline.py", line 378, in fit\n    Xt = self._fit(X, y, **fit_params_steps)\n  File "/usr/local/lib/python3.8/dist-packages/sklearn/pipeline.py", line 336, in _fit\n    X, fitted_transformer = fit_transform_one_cached(\n  File "/usr/local/lib/python3.8/dist-packages/joblib/memory.py", line 349, in __call__\n    return self.func(*args, **kwargs)\n  File "/usr/local/lib/python3.8/dist-packages/sklearn/pipeline.py", line 870, in _fit_transform_one\n    res = transformer.fit_transform(X, y, **fit_params)\n  File "/usr/local/lib/python3.8/dist-packages/sklearn/base.py", line 870, in fit_transform\n    return self.fit(X, y, **fit_params).transform(X)\n  File "/usr/local/lib/python3.8/dist-packages/sklearn/preprocessing/_polynomial.py", line 432, in transform\n    XP = np.empty(\nnumpy.core._exceptions._ArrayMemoryError: Unable to allocate 101. GiB for an array with shape (211, 64512240) and data type float64\n\n--------------------------------------------------------------------------------\n5 fits failed with the following error:\nTraceback (most recent call last):\n  File "/usr/local/lib/python3.8/dist-packages/sklearn/model_selection/_validation.py", line 686, in _fit_and_score\n    estimator.fit(X_train, y_train, **fit_params)\n  File "/usr/local/lib/python3.8/dist-packages/sklearn/pipeline.py", line 378, in fit\n    Xt = self._fit(X, y, **fit_params_steps)\n  File "/usr/local/lib/python3.8/dist-packages/sklearn/pipeline.py", line 336, in _fit\n    X, fitted_transformer = fit_transform_one_cached(\n  File "/usr/local/lib/python3.8/dist-packages/joblib/memory.py", line 349, in __call__\n    return self.func(*args, **kwargs)\n  File "/usr/local/lib/python3.8/dist-packages/sklearn/pipeline.py", line 870, in _fit_transform_one\n    res = transformer.fit_transform(X, y, **fit_params)\n  File "/usr/local/lib/python3.8/dist-packages/sklearn/base.py", line 870, in fit_transform\n    return self.fit(X, y, **fit_params).transform(X)\n  File "/usr/local/lib/python3.8/dist-packages/sklearn/preprocessing/_polynomial.py", line 432, in transform\n    XP = np.empty(\nnumpy.core._exceptions._ArrayMemoryError: Unable to allocate 102. GiB for an array with shape (212, 64512240) and data type float64\n')
Traceback (most recent call last):
  File "/usr/local/lib/python3.8/dist-packages/optuna/study/_optimize.py", line 196, in _run_trial
    value_or_values = func(trial)
  File "/tmp/ipykernel_7443/2264325072.py", line 23, in __call__
    scores = cross_validate(estimator=model, scoring=metrics,
  File "/usr/local/lib/python3.8/dist-packages/sklearn/model_selection/_validation.py", line 285, in cross_validate
    _warn_or_raise_about_fit_failures(results, error_score)
  File "/usr/local/lib/python3.8/dist-packages/sklearn/model_selection/_validation.py", line 367, in _warn_or_raise_about_fit_failures
    raise ValueError(all_fits_failed_message)
ValueError: 
All the 10 fits failed.
It is very likely that your model is misconfigured.
You can try to debug the error by setting error_score='raise'.

Below are more details about the failures:
--------------------------------------------------------------------------------
5 fits failed with the following error:
Traceback (most recent call last):
  File "/usr/local/lib/python3.8/dist-packages/sklearn/model_selection/_validation.py", line 686, in _fit_and_score
    estimator.fit(X_train, y_train, **fit_params)
  File "/usr/local/lib/python3.8/dist-packages/sklearn/pipeline.py", line 378, in fit
    Xt = self._fit(X, y, **fit_params_steps)
  File "/usr/local/lib/python3.8/dist-packages/sklearn/pipeline.py", line 336, in _fit
    X, fitted_transformer = fit_transform_one_cached(
  File "/usr/local/lib/python3.8/dist-packages/joblib/memory.py", line 349, in __call__
    return self.func(*args, **kwargs)
  File "/usr/local/lib/python3.8/dist-packages/sklearn/pipeline.py", line 870, in _fit_transform_one
    res = transformer.fit_transform(X, y, **fit_params)
  File "/usr/local/lib/python3.8/dist-packages/sklearn/base.py", line 870, in fit_transform
    return self.fit(X, y, **fit_params).transform(X)
  File "/usr/local/lib/python3.8/dist-packages/sklearn/preprocessing/_polynomial.py", line 432, in transform
    XP = np.empty(
numpy.core._exceptions._ArrayMemoryError: Unable to allocate 101. GiB for an array with shape (211, 64512240) and data type float64

--------------------------------------------------------------------------------
5 fits failed with the following error:
Traceback (most recent call last):
  File "/usr/local/lib/python3.8/dist-packages/sklearn/model_selection/_validation.py", line 686, in _fit_and_score
    estimator.fit(X_train, y_train, **fit_params)
  File "/usr/local/lib/python3.8/dist-packages/sklearn/pipeline.py", line 378, in fit
    Xt = self._fit(X, y, **fit_params_steps)
  File "/usr/local/lib/python3.8/dist-packages/sklearn/pipeline.py", line 336, in _fit
    X, fitted_transformer = fit_transform_one_cached(
  File "/usr/local/lib/python3.8/dist-packages/joblib/memory.py", line 349, in __call__
    return self.func(*args, **kwargs)
  File "/usr/local/lib/python3.8/dist-packages/sklearn/pipeline.py", line 870, in _fit_transform_one
    res = transformer.fit_transform(X, y, **fit_params)
  File "/usr/local/lib/python3.8/dist-packages/sklearn/base.py", line 870, in fit_transform
    return self.fit(X, y, **fit_params).transform(X)
  File "/usr/local/lib/python3.8/dist-packages/sklearn/preprocessing/_polynomial.py", line 432, in transform
    XP = np.empty(
numpy.core._exceptions._ArrayMemoryError: Unable to allocate 102. GiB for an array with shape (212, 64512240) and data type float64

Trial 7 failed because of the following error: ValueError('\nAll the 10 fits failed.\nIt is very likely that your model is misconfigured.\nYou can try to debug the error by setting error_score=\'raise\'.\n\nBelow are more details about the failures:\n--------------------------------------------------------------------------------\n5 fits failed with the following error:\nTraceback (most recent call last):\n  File "/usr/local/lib/python3.8/dist-packages/sklearn/model_selection/_validation.py", line 686, in _fit_and_score\n    estimator.fit(X_train, y_train, **fit_params)\n  File "/usr/local/lib/python3.8/dist-packages/sklearn/pipeline.py", line 378, in fit\n    Xt = self._fit(X, y, **fit_params_steps)\n  File "/usr/local/lib/python3.8/dist-packages/sklearn/pipeline.py", line 336, in _fit\n    X, fitted_transformer = fit_transform_one_cached(\n  File "/usr/local/lib/python3.8/dist-packages/joblib/memory.py", line 349, in __call__\n    return self.func(*args, **kwargs)\n  File "/usr/local/lib/python3.8/dist-packages/sklearn/pipeline.py", line 870, in _fit_transform_one\n    res = transformer.fit_transform(X, y, **fit_params)\n  File "/usr/local/lib/python3.8/dist-packages/sklearn/base.py", line 870, in fit_transform\n    return self.fit(X, y, **fit_params).transform(X)\n  File "/usr/local/lib/python3.8/dist-packages/sklearn/preprocessing/_polynomial.py", line 432, in transform\n    XP = np.empty(\nnumpy.core._exceptions._ArrayMemoryError: Unable to allocate 2.27 TiB for an array with shape (211, 1476337800) and data type float64\n\n--------------------------------------------------------------------------------\n5 fits failed with the following error:\nTraceback (most recent call last):\n  File "/usr/local/lib/python3.8/dist-packages/sklearn/model_selection/_validation.py", line 686, in _fit_and_score\n    estimator.fit(X_train, y_train, **fit_params)\n  File "/usr/local/lib/python3.8/dist-packages/sklearn/pipeline.py", line 378, in fit\n    Xt = self._fit(X, y, **fit_params_steps)\n  File "/usr/local/lib/python3.8/dist-packages/sklearn/pipeline.py", line 336, in _fit\n    X, fitted_transformer = fit_transform_one_cached(\n  File "/usr/local/lib/python3.8/dist-packages/joblib/memory.py", line 349, in __call__\n    return self.func(*args, **kwargs)\n  File "/usr/local/lib/python3.8/dist-packages/sklearn/pipeline.py", line 870, in _fit_transform_one\n    res = transformer.fit_transform(X, y, **fit_params)\n  File "/usr/local/lib/python3.8/dist-packages/sklearn/base.py", line 870, in fit_transform\n    return self.fit(X, y, **fit_params).transform(X)\n  File "/usr/local/lib/python3.8/dist-packages/sklearn/preprocessing/_polynomial.py", line 432, in transform\n    XP = np.empty(\nnumpy.core._exceptions._ArrayMemoryError: Unable to allocate 2.28 TiB for an array with shape (212, 1476337800) and data type float64\n')
Traceback (most recent call last):
  File "/usr/local/lib/python3.8/dist-packages/optuna/study/_optimize.py", line 196, in _run_trial
    value_or_values = func(trial)
  File "/tmp/ipykernel_7443/2264325072.py", line 23, in __call__
    scores = cross_validate(estimator=model, scoring=metrics,
  File "/usr/local/lib/python3.8/dist-packages/sklearn/model_selection/_validation.py", line 285, in cross_validate
    _warn_or_raise_about_fit_failures(results, error_score)
  File "/usr/local/lib/python3.8/dist-packages/sklearn/model_selection/_validation.py", line 367, in _warn_or_raise_about_fit_failures
    raise ValueError(all_fits_failed_message)
ValueError: 
All the 10 fits failed.
It is very likely that your model is misconfigured.
You can try to debug the error by setting error_score='raise'.

Below are more details about the failures:
--------------------------------------------------------------------------------
5 fits failed with the following error:
Traceback (most recent call last):
  File "/usr/local/lib/python3.8/dist-packages/sklearn/model_selection/_validation.py", line 686, in _fit_and_score
    estimator.fit(X_train, y_train, **fit_params)
  File "/usr/local/lib/python3.8/dist-packages/sklearn/pipeline.py", line 378, in fit
    Xt = self._fit(X, y, **fit_params_steps)
  File "/usr/local/lib/python3.8/dist-packages/sklearn/pipeline.py", line 336, in _fit
    X, fitted_transformer = fit_transform_one_cached(
  File "/usr/local/lib/python3.8/dist-packages/joblib/memory.py", line 349, in __call__
    return self.func(*args, **kwargs)
  File "/usr/local/lib/python3.8/dist-packages/sklearn/pipeline.py", line 870, in _fit_transform_one
    res = transformer.fit_transform(X, y, **fit_params)
  File "/usr/local/lib/python3.8/dist-packages/sklearn/base.py", line 870, in fit_transform
    return self.fit(X, y, **fit_params).transform(X)
  File "/usr/local/lib/python3.8/dist-packages/sklearn/preprocessing/_polynomial.py", line 432, in transform
    XP = np.empty(
numpy.core._exceptions._ArrayMemoryError: Unable to allocate 2.27 TiB for an array with shape (211, 1476337800) and data type float64

--------------------------------------------------------------------------------
5 fits failed with the following error:
Traceback (most recent call last):
  File "/usr/local/lib/python3.8/dist-packages/sklearn/model_selection/_validation.py", line 686, in _fit_and_score
    estimator.fit(X_train, y_train, **fit_params)
  File "/usr/local/lib/python3.8/dist-packages/sklearn/pipeline.py", line 378, in fit
    Xt = self._fit(X, y, **fit_params_steps)
  File "/usr/local/lib/python3.8/dist-packages/sklearn/pipeline.py", line 336, in _fit
    X, fitted_transformer = fit_transform_one_cached(
  File "/usr/local/lib/python3.8/dist-packages/joblib/memory.py", line 349, in __call__
    return self.func(*args, **kwargs)
  File "/usr/local/lib/python3.8/dist-packages/sklearn/pipeline.py", line 870, in _fit_transform_one
    res = transformer.fit_transform(X, y, **fit_params)
  File "/usr/local/lib/python3.8/dist-packages/sklearn/base.py", line 870, in fit_transform
    return self.fit(X, y, **fit_params).transform(X)
  File "/usr/local/lib/python3.8/dist-packages/sklearn/preprocessing/_polynomial.py", line 432, in transform
    XP = np.empty(
numpy.core._exceptions._ArrayMemoryError: Unable to allocate 2.28 TiB for an array with shape (212, 1476337800) and data type float64

Trial 18 failed because of the following error: ValueError('\nAll the 10 fits failed.\nIt is very likely that your model is misconfigured.\nYou can try to debug the error by setting error_score=\'raise\'.\n\nBelow are more details about the failures:\n--------------------------------------------------------------------------------\n5 fits failed with the following error:\nTraceback (most recent call last):\n  File "/usr/local/lib/python3.8/dist-packages/sklearn/model_selection/_validation.py", line 686, in _fit_and_score\n    estimator.fit(X_train, y_train, **fit_params)\n  File "/usr/local/lib/python3.8/dist-packages/sklearn/pipeline.py", line 378, in fit\n    Xt = self._fit(X, y, **fit_params_steps)\n  File "/usr/local/lib/python3.8/dist-packages/sklearn/pipeline.py", line 336, in _fit\n    X, fitted_transformer = fit_transform_one_cached(\n  File "/usr/local/lib/python3.8/dist-packages/joblib/memory.py", line 349, in __call__\n    return self.func(*args, **kwargs)\n  File "/usr/local/lib/python3.8/dist-packages/sklearn/pipeline.py", line 870, in _fit_transform_one\n    res = transformer.fit_transform(X, y, **fit_params)\n  File "/usr/local/lib/python3.8/dist-packages/sklearn/base.py", line 870, in fit_transform\n    return self.fit(X, y, **fit_params).transform(X)\n  File "/usr/local/lib/python3.8/dist-packages/sklearn/preprocessing/_polynomial.py", line 432, in transform\n    XP = np.empty(\nnumpy.core._exceptions._ArrayMemoryError: Unable to allocate 693. PiB for an array with shape (211, 462525733568080) and data type float64\n\n--------------------------------------------------------------------------------\n5 fits failed with the following error:\nTraceback (most recent call last):\n  File "/usr/local/lib/python3.8/dist-packages/sklearn/model_selection/_validation.py", line 686, in _fit_and_score\n    estimator.fit(X_train, y_train, **fit_params)\n  File "/usr/local/lib/python3.8/dist-packages/sklearn/pipeline.py", line 378, in fit\n    Xt = self._fit(X, y, **fit_params_steps)\n  File "/usr/local/lib/python3.8/dist-packages/sklearn/pipeline.py", line 336, in _fit\n    X, fitted_transformer = fit_transform_one_cached(\n  File "/usr/local/lib/python3.8/dist-packages/joblib/memory.py", line 349, in __call__\n    return self.func(*args, **kwargs)\n  File "/usr/local/lib/python3.8/dist-packages/sklearn/pipeline.py", line 870, in _fit_transform_one\n    res = transformer.fit_transform(X, y, **fit_params)\n  File "/usr/local/lib/python3.8/dist-packages/sklearn/base.py", line 870, in fit_transform\n    return self.fit(X, y, **fit_params).transform(X)\n  File "/usr/local/lib/python3.8/dist-packages/sklearn/preprocessing/_polynomial.py", line 432, in transform\n    XP = np.empty(\nnumpy.core._exceptions._ArrayMemoryError: Unable to allocate 697. PiB for an array with shape (212, 462525733568080) and data type float64\n')
Traceback (most recent call last):
  File "/usr/local/lib/python3.8/dist-packages/optuna/study/_optimize.py", line 196, in _run_trial
    value_or_values = func(trial)
  File "/tmp/ipykernel_7443/2264325072.py", line 23, in __call__
    scores = cross_validate(estimator=model, scoring=metrics,
  File "/usr/local/lib/python3.8/dist-packages/sklearn/model_selection/_validation.py", line 285, in cross_validate
    _warn_or_raise_about_fit_failures(results, error_score)
  File "/usr/local/lib/python3.8/dist-packages/sklearn/model_selection/_validation.py", line 367, in _warn_or_raise_about_fit_failures
    raise ValueError(all_fits_failed_message)
ValueError: 
All the 10 fits failed.
It is very likely that your model is misconfigured.
You can try to debug the error by setting error_score='raise'.

Below are more details about the failures:
--------------------------------------------------------------------------------
5 fits failed with the following error:
Traceback (most recent call last):
  File "/usr/local/lib/python3.8/dist-packages/sklearn/model_selection/_validation.py", line 686, in _fit_and_score
    estimator.fit(X_train, y_train, **fit_params)
  File "/usr/local/lib/python3.8/dist-packages/sklearn/pipeline.py", line 378, in fit
    Xt = self._fit(X, y, **fit_params_steps)
  File "/usr/local/lib/python3.8/dist-packages/sklearn/pipeline.py", line 336, in _fit
    X, fitted_transformer = fit_transform_one_cached(
  File "/usr/local/lib/python3.8/dist-packages/joblib/memory.py", line 349, in __call__
    return self.func(*args, **kwargs)
  File "/usr/local/lib/python3.8/dist-packages/sklearn/pipeline.py", line 870, in _fit_transform_one
    res = transformer.fit_transform(X, y, **fit_params)
  File "/usr/local/lib/python3.8/dist-packages/sklearn/base.py", line 870, in fit_transform
    return self.fit(X, y, **fit_params).transform(X)
  File "/usr/local/lib/python3.8/dist-packages/sklearn/preprocessing/_polynomial.py", line 432, in transform
    XP = np.empty(
numpy.core._exceptions._ArrayMemoryError: Unable to allocate 693. PiB for an array with shape (211, 462525733568080) and data type float64

--------------------------------------------------------------------------------
5 fits failed with the following error:
Traceback (most recent call last):
  File "/usr/local/lib/python3.8/dist-packages/sklearn/model_selection/_validation.py", line 686, in _fit_and_score
    estimator.fit(X_train, y_train, **fit_params)
  File "/usr/local/lib/python3.8/dist-packages/sklearn/pipeline.py", line 378, in fit
    Xt = self._fit(X, y, **fit_params_steps)
  File "/usr/local/lib/python3.8/dist-packages/sklearn/pipeline.py", line 336, in _fit
    X, fitted_transformer = fit_transform_one_cached(
  File "/usr/local/lib/python3.8/dist-packages/joblib/memory.py", line 349, in __call__
    return self.func(*args, **kwargs)
  File "/usr/local/lib/python3.8/dist-packages/sklearn/pipeline.py", line 870, in _fit_transform_one
    res = transformer.fit_transform(X, y, **fit_params)
  File "/usr/local/lib/python3.8/dist-packages/sklearn/base.py", line 870, in fit_transform
    return self.fit(X, y, **fit_params).transform(X)
  File "/usr/local/lib/python3.8/dist-packages/sklearn/preprocessing/_polynomial.py", line 432, in transform
    XP = np.empty(
numpy.core._exceptions._ArrayMemoryError: Unable to allocate 697. PiB for an array with shape (212, 462525733568080) and data type float64

Trial 4 failed because of the following error: ValueError('\nAll the 10 fits failed.\nIt is very likely that your model is misconfigured.\nYou can try to debug the error by setting error_score=\'raise\'.\n\nBelow are more details about the failures:\n--------------------------------------------------------------------------------\n10 fits failed with the following error:\nTraceback (most recent call last):\n  File "/usr/local/lib/python3.8/dist-packages/sklearn/model_selection/_validation.py", line 686, in _fit_and_score\n    estimator.fit(X_train, y_train, **fit_params)\n  File "/usr/local/lib/python3.8/dist-packages/sklearn/pipeline.py", line 378, in fit\n    Xt = self._fit(X, y, **fit_params_steps)\n  File "/usr/local/lib/python3.8/dist-packages/sklearn/pipeline.py", line 336, in _fit\n    X, fitted_transformer = fit_transform_one_cached(\n  File "/usr/local/lib/python3.8/dist-packages/joblib/memory.py", line 349, in __call__\n    return self.func(*args, **kwargs)\n  File "/usr/local/lib/python3.8/dist-packages/sklearn/pipeline.py", line 870, in _fit_transform_one\n    res = transformer.fit_transform(X, y, **fit_params)\n  File "/usr/local/lib/python3.8/dist-packages/sklearn/base.py", line 870, in fit_transform\n    return self.fit(X, y, **fit_params).transform(X)\n  File "/usr/local/lib/python3.8/dist-packages/sklearn/preprocessing/_polynomial.py", line 432, in transform\n    XP = np.empty(\nValueError: Maximum allowed dimension exceeded\n')
Traceback (most recent call last):
  File "/usr/local/lib/python3.8/dist-packages/optuna/study/_optimize.py", line 196, in _run_trial
    value_or_values = func(trial)
  File "/tmp/ipykernel_7443/2264325072.py", line 23, in __call__
    scores = cross_validate(estimator=model, scoring=metrics,
  File "/usr/local/lib/python3.8/dist-packages/sklearn/model_selection/_validation.py", line 285, in cross_validate
    _warn_or_raise_about_fit_failures(results, error_score)
  File "/usr/local/lib/python3.8/dist-packages/sklearn/model_selection/_validation.py", line 367, in _warn_or_raise_about_fit_failures
    raise ValueError(all_fits_failed_message)
ValueError: 
All the 10 fits failed.
It is very likely that your model is misconfigured.
You can try to debug the error by setting error_score='raise'.

Below are more details about the failures:
--------------------------------------------------------------------------------
10 fits failed with the following error:
Traceback (most recent call last):
  File "/usr/local/lib/python3.8/dist-packages/sklearn/model_selection/_validation.py", line 686, in _fit_and_score
    estimator.fit(X_train, y_train, **fit_params)
  File "/usr/local/lib/python3.8/dist-packages/sklearn/pipeline.py", line 378, in fit
    Xt = self._fit(X, y, **fit_params_steps)
  File "/usr/local/lib/python3.8/dist-packages/sklearn/pipeline.py", line 336, in _fit
    X, fitted_transformer = fit_transform_one_cached(
  File "/usr/local/lib/python3.8/dist-packages/joblib/memory.py", line 349, in __call__
    return self.func(*args, **kwargs)
  File "/usr/local/lib/python3.8/dist-packages/sklearn/pipeline.py", line 870, in _fit_transform_one
    res = transformer.fit_transform(X, y, **fit_params)
  File "/usr/local/lib/python3.8/dist-packages/sklearn/base.py", line 870, in fit_transform
    return self.fit(X, y, **fit_params).transform(X)
  File "/usr/local/lib/python3.8/dist-packages/sklearn/preprocessing/_polynomial.py", line 432, in transform
    XP = np.empty(
ValueError: Maximum allowed dimension exceeded

Trial 3 failed because of the following error: ValueError('\nAll the 10 fits failed.\nIt is very likely that your model is misconfigured.\nYou can try to debug the error by setting error_score=\'raise\'.\n\nBelow are more details about the failures:\n--------------------------------------------------------------------------------\n10 fits failed with the following error:\nTraceback (most recent call last):\n  File "/usr/local/lib/python3.8/dist-packages/sklearn/model_selection/_validation.py", line 686, in _fit_and_score\n    estimator.fit(X_train, y_train, **fit_params)\n  File "/usr/local/lib/python3.8/dist-packages/sklearn/pipeline.py", line 378, in fit\n    Xt = self._fit(X, y, **fit_params_steps)\n  File "/usr/local/lib/python3.8/dist-packages/sklearn/pipeline.py", line 336, in _fit\n    X, fitted_transformer = fit_transform_one_cached(\n  File "/usr/local/lib/python3.8/dist-packages/joblib/memory.py", line 349, in __call__\n    return self.func(*args, **kwargs)\n  File "/usr/local/lib/python3.8/dist-packages/sklearn/pipeline.py", line 870, in _fit_transform_one\n    res = transformer.fit_transform(X, y, **fit_params)\n  File "/usr/local/lib/python3.8/dist-packages/sklearn/base.py", line 870, in fit_transform\n    return self.fit(X, y, **fit_params).transform(X)\n  File "/usr/local/lib/python3.8/dist-packages/sklearn/preprocessing/_polynomial.py", line 432, in transform\n    XP = np.empty(\nValueError: Maximum allowed dimension exceeded\n')
Traceback (most recent call last):
  File "/usr/local/lib/python3.8/dist-packages/optuna/study/_optimize.py", line 196, in _run_trial
    value_or_values = func(trial)
  File "/tmp/ipykernel_7443/2264325072.py", line 23, in __call__
    scores = cross_validate(estimator=model, scoring=metrics,
  File "/usr/local/lib/python3.8/dist-packages/sklearn/model_selection/_validation.py", line 285, in cross_validate
    _warn_or_raise_about_fit_failures(results, error_score)
  File "/usr/local/lib/python3.8/dist-packages/sklearn/model_selection/_validation.py", line 367, in _warn_or_raise_about_fit_failures
    raise ValueError(all_fits_failed_message)
ValueError: 
All the 10 fits failed.
It is very likely that your model is misconfigured.
You can try to debug the error by setting error_score='raise'.

Below are more details about the failures:
--------------------------------------------------------------------------------
10 fits failed with the following error:
Traceback (most recent call last):
  File "/usr/local/lib/python3.8/dist-packages/sklearn/model_selection/_validation.py", line 686, in _fit_and_score
    estimator.fit(X_train, y_train, **fit_params)
  File "/usr/local/lib/python3.8/dist-packages/sklearn/pipeline.py", line 378, in fit
    Xt = self._fit(X, y, **fit_params_steps)
  File "/usr/local/lib/python3.8/dist-packages/sklearn/pipeline.py", line 336, in _fit
    X, fitted_transformer = fit_transform_one_cached(
  File "/usr/local/lib/python3.8/dist-packages/joblib/memory.py", line 349, in __call__
    return self.func(*args, **kwargs)
  File "/usr/local/lib/python3.8/dist-packages/sklearn/pipeline.py", line 870, in _fit_transform_one
    res = transformer.fit_transform(X, y, **fit_params)
  File "/usr/local/lib/python3.8/dist-packages/sklearn/base.py", line 870, in fit_transform
    return self.fit(X, y, **fit_params).transform(X)
  File "/usr/local/lib/python3.8/dist-packages/sklearn/preprocessing/_polynomial.py", line 432, in transform
    XP = np.empty(
ValueError: Maximum allowed dimension exceeded

Trial 0 failed because of the following error: ValueError('\nAll the 10 fits failed.\nIt is very likely that your model is misconfigured.\nYou can try to debug the error by setting error_score=\'raise\'.\n\nBelow are more details about the failures:\n--------------------------------------------------------------------------------\n10 fits failed with the following error:\nTraceback (most recent call last):\n  File "/usr/local/lib/python3.8/dist-packages/sklearn/model_selection/_validation.py", line 686, in _fit_and_score\n    estimator.fit(X_train, y_train, **fit_params)\n  File "/usr/local/lib/python3.8/dist-packages/sklearn/pipeline.py", line 378, in fit\n    Xt = self._fit(X, y, **fit_params_steps)\n  File "/usr/local/lib/python3.8/dist-packages/sklearn/pipeline.py", line 336, in _fit\n    X, fitted_transformer = fit_transform_one_cached(\n  File "/usr/local/lib/python3.8/dist-packages/joblib/memory.py", line 349, in __call__\n    return self.func(*args, **kwargs)\n  File "/usr/local/lib/python3.8/dist-packages/sklearn/pipeline.py", line 870, in _fit_transform_one\n    res = transformer.fit_transform(X, y, **fit_params)\n  File "/usr/local/lib/python3.8/dist-packages/sklearn/base.py", line 870, in fit_transform\n    return self.fit(X, y, **fit_params).transform(X)\n  File "/usr/local/lib/python3.8/dist-packages/sklearn/preprocessing/_polynomial.py", line 432, in transform\n    XP = np.empty(\nValueError: Maximum allowed dimension exceeded\n')
Traceback (most recent call last):
  File "/usr/local/lib/python3.8/dist-packages/optuna/study/_optimize.py", line 196, in _run_trial
    value_or_values = func(trial)
  File "/tmp/ipykernel_7443/2264325072.py", line 23, in __call__
    scores = cross_validate(estimator=model, scoring=metrics,
  File "/usr/local/lib/python3.8/dist-packages/sklearn/model_selection/_validation.py", line 285, in cross_validate
    _warn_or_raise_about_fit_failures(results, error_score)
  File "/usr/local/lib/python3.8/dist-packages/sklearn/model_selection/_validation.py", line 367, in _warn_or_raise_about_fit_failures
    raise ValueError(all_fits_failed_message)
ValueError: 
All the 10 fits failed.
It is very likely that your model is misconfigured.
You can try to debug the error by setting error_score='raise'.

Below are more details about the failures:
--------------------------------------------------------------------------------
10 fits failed with the following error:
Traceback (most recent call last):
  File "/usr/local/lib/python3.8/dist-packages/sklearn/model_selection/_validation.py", line 686, in _fit_and_score
    estimator.fit(X_train, y_train, **fit_params)
  File "/usr/local/lib/python3.8/dist-packages/sklearn/pipeline.py", line 378, in fit
    Xt = self._fit(X, y, **fit_params_steps)
  File "/usr/local/lib/python3.8/dist-packages/sklearn/pipeline.py", line 336, in _fit
    X, fitted_transformer = fit_transform_one_cached(
  File "/usr/local/lib/python3.8/dist-packages/joblib/memory.py", line 349, in __call__
    return self.func(*args, **kwargs)
  File "/usr/local/lib/python3.8/dist-packages/sklearn/pipeline.py", line 870, in _fit_transform_one
    res = transformer.fit_transform(X, y, **fit_params)
  File "/usr/local/lib/python3.8/dist-packages/sklearn/base.py", line 870, in fit_transform
    return self.fit(X, y, **fit_params).transform(X)
  File "/usr/local/lib/python3.8/dist-packages/sklearn/preprocessing/_polynomial.py", line 432, in transform
    XP = np.empty(
ValueError: Maximum allowed dimension exceeded

Trial 5 failed because of the following error: ValueError('\nAll the 10 fits failed.\nIt is very likely that your model is misconfigured.\nYou can try to debug the error by setting error_score=\'raise\'.\n\nBelow are more details about the failures:\n--------------------------------------------------------------------------------\n10 fits failed with the following error:\nTraceback (most recent call last):\n  File "/usr/local/lib/python3.8/dist-packages/sklearn/model_selection/_validation.py", line 686, in _fit_and_score\n    estimator.fit(X_train, y_train, **fit_params)\n  File "/usr/local/lib/python3.8/dist-packages/sklearn/pipeline.py", line 378, in fit\n    Xt = self._fit(X, y, **fit_params_steps)\n  File "/usr/local/lib/python3.8/dist-packages/sklearn/pipeline.py", line 336, in _fit\n    X, fitted_transformer = fit_transform_one_cached(\n  File "/usr/local/lib/python3.8/dist-packages/joblib/memory.py", line 349, in __call__\n    return self.func(*args, **kwargs)\n  File "/usr/local/lib/python3.8/dist-packages/sklearn/pipeline.py", line 870, in _fit_transform_one\n    res = transformer.fit_transform(X, y, **fit_params)\n  File "/usr/local/lib/python3.8/dist-packages/sklearn/base.py", line 870, in fit_transform\n    return self.fit(X, y, **fit_params).transform(X)\n  File "/usr/local/lib/python3.8/dist-packages/sklearn/preprocessing/_polynomial.py", line 432, in transform\n    XP = np.empty(\nValueError: Maximum allowed dimension exceeded\n')
Traceback (most recent call last):
  File "/usr/local/lib/python3.8/dist-packages/optuna/study/_optimize.py", line 196, in _run_trial
    value_or_values = func(trial)
  File "/tmp/ipykernel_7443/2264325072.py", line 23, in __call__
    scores = cross_validate(estimator=model, scoring=metrics,
  File "/usr/local/lib/python3.8/dist-packages/sklearn/model_selection/_validation.py", line 285, in cross_validate
    _warn_or_raise_about_fit_failures(results, error_score)
  File "/usr/local/lib/python3.8/dist-packages/sklearn/model_selection/_validation.py", line 367, in _warn_or_raise_about_fit_failures
    raise ValueError(all_fits_failed_message)
ValueError: 
All the 10 fits failed.
It is very likely that your model is misconfigured.
You can try to debug the error by setting error_score='raise'.

Below are more details about the failures:
--------------------------------------------------------------------------------
10 fits failed with the following error:
Traceback (most recent call last):
  File "/usr/local/lib/python3.8/dist-packages/sklearn/model_selection/_validation.py", line 686, in _fit_and_score
    estimator.fit(X_train, y_train, **fit_params)
  File "/usr/local/lib/python3.8/dist-packages/sklearn/pipeline.py", line 378, in fit
    Xt = self._fit(X, y, **fit_params_steps)
  File "/usr/local/lib/python3.8/dist-packages/sklearn/pipeline.py", line 336, in _fit
    X, fitted_transformer = fit_transform_one_cached(
  File "/usr/local/lib/python3.8/dist-packages/joblib/memory.py", line 349, in __call__
    return self.func(*args, **kwargs)
  File "/usr/local/lib/python3.8/dist-packages/sklearn/pipeline.py", line 870, in _fit_transform_one
    res = transformer.fit_transform(X, y, **fit_params)
  File "/usr/local/lib/python3.8/dist-packages/sklearn/base.py", line 870, in fit_transform
    return self.fit(X, y, **fit_params).transform(X)
  File "/usr/local/lib/python3.8/dist-packages/sklearn/preprocessing/_polynomial.py", line 432, in transform
    XP = np.empty(
ValueError: Maximum allowed dimension exceeded

Trial 14 failed because of the following error: ValueError('\nAll the 10 fits failed.\nIt is very likely that your model is misconfigured.\nYou can try to debug the error by setting error_score=\'raise\'.\n\nBelow are more details about the failures:\n--------------------------------------------------------------------------------\n10 fits failed with the following error:\nTraceback (most recent call last):\n  File "/usr/local/lib/python3.8/dist-packages/sklearn/model_selection/_validation.py", line 686, in _fit_and_score\n    estimator.fit(X_train, y_train, **fit_params)\n  File "/usr/local/lib/python3.8/dist-packages/sklearn/pipeline.py", line 378, in fit\n    Xt = self._fit(X, y, **fit_params_steps)\n  File "/usr/local/lib/python3.8/dist-packages/sklearn/pipeline.py", line 336, in _fit\n    X, fitted_transformer = fit_transform_one_cached(\n  File "/usr/local/lib/python3.8/dist-packages/joblib/memory.py", line 349, in __call__\n    return self.func(*args, **kwargs)\n  File "/usr/local/lib/python3.8/dist-packages/sklearn/pipeline.py", line 870, in _fit_transform_one\n    res = transformer.fit_transform(X, y, **fit_params)\n  File "/usr/local/lib/python3.8/dist-packages/sklearn/base.py", line 870, in fit_transform\n    return self.fit(X, y, **fit_params).transform(X)\n  File "/usr/local/lib/python3.8/dist-packages/sklearn/preprocessing/_polynomial.py", line 432, in transform\n    XP = np.empty(\nValueError: Maximum allowed dimension exceeded\n')
Traceback (most recent call last):
  File "/usr/local/lib/python3.8/dist-packages/optuna/study/_optimize.py", line 196, in _run_trial
    value_or_values = func(trial)
  File "/tmp/ipykernel_7443/2264325072.py", line 23, in __call__
    scores = cross_validate(estimator=model, scoring=metrics,
  File "/usr/local/lib/python3.8/dist-packages/sklearn/model_selection/_validation.py", line 285, in cross_validate
    _warn_or_raise_about_fit_failures(results, error_score)
  File "/usr/local/lib/python3.8/dist-packages/sklearn/model_selection/_validation.py", line 367, in _warn_or_raise_about_fit_failures
    raise ValueError(all_fits_failed_message)
ValueError: 
All the 10 fits failed.
It is very likely that your model is misconfigured.
You can try to debug the error by setting error_score='raise'.

Below are more details about the failures:
--------------------------------------------------------------------------------
10 fits failed with the following error:
Traceback (most recent call last):
  File "/usr/local/lib/python3.8/dist-packages/sklearn/model_selection/_validation.py", line 686, in _fit_and_score
    estimator.fit(X_train, y_train, **fit_params)
  File "/usr/local/lib/python3.8/dist-packages/sklearn/pipeline.py", line 378, in fit
    Xt = self._fit(X, y, **fit_params_steps)
  File "/usr/local/lib/python3.8/dist-packages/sklearn/pipeline.py", line 336, in _fit
    X, fitted_transformer = fit_transform_one_cached(
  File "/usr/local/lib/python3.8/dist-packages/joblib/memory.py", line 349, in __call__
    return self.func(*args, **kwargs)
  File "/usr/local/lib/python3.8/dist-packages/sklearn/pipeline.py", line 870, in _fit_transform_one
    res = transformer.fit_transform(X, y, **fit_params)
  File "/usr/local/lib/python3.8/dist-packages/sklearn/base.py", line 870, in fit_transform
    return self.fit(X, y, **fit_params).transform(X)
  File "/usr/local/lib/python3.8/dist-packages/sklearn/preprocessing/_polynomial.py", line 432, in transform
    XP = np.empty(
ValueError: Maximum allowed dimension exceeded

A new study created in RDB with name: Poly_Linear_91810
Trial 18 finished with value: 0.7332903237803265 and parameters: {'degree': 3}. Best is trial 23 with value: 0.7728060333835753.
Trial 3 finished with value: 0.818369494924769 and parameters: {'degree': 2}. Best is trial 20 with value: 0.818369494924769.
Trial 23 finished with value: 0.7728060333835753 and parameters: {'degree': 1}. Best is trial 20 with value: 0.818369494924769.
Trial 0 finished with value: 0.7728060333835753 and parameters: {'degree': 1}. Best is trial 20 with value: 0.818369494924769.
Trial 17 finished with value: 0.7728060333835753 and parameters: {'degree': 1}. Best is trial 20 with value: 0.818369494924769.
Trial 20 finished with value: 0.818369494924769 and parameters: {'degree': 2}. Best is trial 20 with value: 0.818369494924769.
Trial 11 finished with value: 0.818369494924769 and parameters: {'degree': 2}. Best is trial 20 with value: 0.818369494924769.
Trial 5 finished with value: -3.047734147810578e+20 and parameters: {'degree': 4}. Best is trial 20 with value: 0.818369494924769.
Trial 19 finished with value: 0.818369494924769 and parameters: {'degree': 2}. Best is trial 20 with value: 0.818369494924769.
Trial 9 finished with value: 0.818369494924769 and parameters: {'degree': 2}. Best is trial 20 with value: 0.818369494924769.
Trial 21 finished with value: -3.047734147810578e+20 and parameters: {'degree': 4}. Best is trial 20 with value: 0.818369494924769.
Trial 10 finished with value: 0.7332903237803265 and parameters: {'degree': 3}. Best is trial 20 with value: 0.818369494924769.
Trial 1 finished with value: -3.047734147810578e+20 and parameters: {'degree': 4}. Best is trial 20 with value: 0.818369494924769.
Trial 6 finished with value: -3.047734147810578e+20 and parameters: {'degree': 4}. Best is trial 20 with value: 0.818369494924769.
Trial 14 finished with value: -3.047734147810578e+20 and parameters: {'degree': 4}. Best is trial 20 with value: 0.818369494924769.
Trial 8 finished with value: 0.7332903237803265 and parameters: {'degree': 3}. Best is trial 20 with value: 0.818369494924769.
Trial 24 finished with value: 0.818369494924769 and parameters: {'degree': 2}. Best is trial 20 with value: 0.818369494924769.
Trial 4 finished with value: 0.818369494924769 and parameters: {'degree': 2}. Best is trial 20 with value: 0.818369494924769.
Trial 13 finished with value: -3.047734147810578e+20 and parameters: {'degree': 4}. Best is trial 20 with value: 0.818369494924769.
Trial 7 finished with value: -3.047734147810578e+20 and parameters: {'degree': 4}. Best is trial 20 with value: 0.818369494924769.
Trial 31 finished with value: 0.7728060333835753 and parameters: {'degree': 1}. Best is trial 20 with value: 0.818369494924769.
Trial 2 finished with value: -6.5608901133283385e+19 and parameters: {'degree': 5}. Best is trial 20 with value: 0.818369494924769.
Trial 15 finished with value: -6.5608901133283385e+19 and parameters: {'degree': 5}. Best is trial 20 with value: 0.818369494924769.
Trial 29 finished with value: 0.7728060333835753 and parameters: {'degree': 1}. Best is trial 20 with value: 0.818369494924769.
Trial 27 finished with value: 0.818369494924769 and parameters: {'degree': 2}. Best is trial 20 with value: 0.818369494924769.
Trial 16 finished with value: -6.5608901133283385e+19 and parameters: {'degree': 5}. Best is trial 20 with value: 0.818369494924769.
Trial 28 finished with value: 0.7332903237803265 and parameters: {'degree': 3}. Best is trial 20 with value: 0.818369494924769.
Trial 22 finished with value: -6.5608901133283385e+19 and parameters: {'degree': 5}. Best is trial 20 with value: 0.818369494924769.
Trial 25 finished with value: -3.047734147810578e+20 and parameters: {'degree': 4}. Best is trial 20 with value: 0.818369494924769.
Trial 26 finished with value: -3.047734147810578e+20 and parameters: {'degree': 4}. Best is trial 20 with value: 0.818369494924769.
Trial 12 finished with value: -6.5608901133283385e+19 and parameters: {'degree': 5}. Best is trial 20 with value: 0.818369494924769.
Trial 30 finished with value: -6.5608901133283385e+19 and parameters: {'degree': 5}. Best is trial 20 with value: 0.818369494924769.
A new study created in RDB with name: Poly_Linear_92327
Trial 0 failed because of the following error: KeyboardInterrupt()
Traceback (most recent call last):
  File "/usr/local/lib/python3.8/dist-packages/optuna/study/_optimize.py", line 196, in _run_trial
    value_or_values = func(trial)
  File "/tmp/ipykernel_7443/2984828490.py", line 23, in __call__
    scores = cross_validate(estimator=model, scoring=metrics,
  File "/usr/local/lib/python3.8/dist-packages/sklearn/model_selection/_validation.py", line 266, in cross_validate
    results = parallel(
  File "/usr/local/lib/python3.8/dist-packages/joblib/parallel.py", line 1046, in __call__
    while self.dispatch_one_batch(iterator):
  File "/usr/local/lib/python3.8/dist-packages/joblib/parallel.py", line 861, in dispatch_one_batch
    self._dispatch(tasks)
  File "/usr/local/lib/python3.8/dist-packages/joblib/parallel.py", line 779, in _dispatch
    job = self._backend.apply_async(batch, callback=cb)
  File "/usr/local/lib/python3.8/dist-packages/joblib/_parallel_backends.py", line 208, in apply_async
    result = ImmediateResult(func)
  File "/usr/local/lib/python3.8/dist-packages/joblib/_parallel_backends.py", line 572, in __init__
    self.results = batch()
  File "/usr/local/lib/python3.8/dist-packages/joblib/parallel.py", line 262, in __call__
    return [func(*args, **kwargs)
  File "/usr/local/lib/python3.8/dist-packages/joblib/parallel.py", line 262, in <listcomp>
    return [func(*args, **kwargs)
  File "/usr/local/lib/python3.8/dist-packages/sklearn/utils/fixes.py", line 117, in __call__
    return self.function(*args, **kwargs)
  File "/usr/local/lib/python3.8/dist-packages/sklearn/model_selection/_validation.py", line 686, in _fit_and_score
    estimator.fit(X_train, y_train, **fit_params)
  File "/usr/local/lib/python3.8/dist-packages/sklearn/pipeline.py", line 382, in fit
    self._final_estimator.fit(Xt, y, **fit_params_last_step)
  File "/usr/local/lib/python3.8/dist-packages/sklearn/linear_model/_base.py", line 736, in fit
    self.coef_, _, self.rank_, self.singular_ = linalg.lstsq(X, y)
  File "/usr/local/lib/python3.8/dist-packages/scipy/linalg/_basic.py", line 1204, in lstsq
    x, s, rank, info = lapack_func(a1, b1, lwork,
KeyboardInterrupt
A new study created in RDB with name: Poly_Linear_92350
Trial 0 failed because of the following error: TypeError('PolynomialRegression() argument after * must be an iterable, not int')
Traceback (most recent call last):
  File "/usr/local/lib/python3.8/dist-packages/optuna/study/_optimize.py", line 196, in _run_trial
    value_or_values = func(trial)
  File "/tmp/ipykernel_7443/689525279.py", line 13, in __call__
    model = PolynomialRegression(*args, **kwargs)
TypeError: PolynomialRegression() argument after * must be an iterable, not int
A new study created in RDB with name: Poly_Linear_92410
Trial 0 finished with value: 0.7728060333835753 and parameters: {'degree': 1}. Best is trial 0 with value: 0.7728060333835753.
Trial 1 finished with value: 0.7332903237803265 and parameters: {'degree': 3}. Best is trial 0 with value: 0.7728060333835753.
Trial 2 finished with value: 0.7332903237803265 and parameters: {'degree': 3}. Best is trial 0 with value: 0.7728060333835753.
Trial 3 finished with value: 0.7728060333835753 and parameters: {'degree': 1}. Best is trial 0 with value: 0.7728060333835753.
Trial 4 finished with value: -3.047734147810578e+20 and parameters: {'degree': 4}. Best is trial 0 with value: 0.7728060333835753.
Trial 5 finished with value: -3.047734147810578e+20 and parameters: {'degree': 4}. Best is trial 0 with value: 0.7728060333835753.
Trial 6 finished with value: 0.7728060333835753 and parameters: {'degree': 1}. Best is trial 0 with value: 0.7728060333835753.
Trial 7 finished with value: -6.5608901133283385e+19 and parameters: {'degree': 5}. Best is trial 0 with value: 0.7728060333835753.
Trial 8 finished with value: -6.5608901133283385e+19 and parameters: {'degree': 5}. Best is trial 0 with value: 0.7728060333835753.
Trial 9 finished with value: 0.7332903237803265 and parameters: {'degree': 3}. Best is trial 0 with value: 0.7728060333835753.
Trial 10 finished with value: -6.5608901133283385e+19 and parameters: {'degree': 5}. Best is trial 0 with value: 0.7728060333835753.
Trial 11 finished with value: -6.5608901133283385e+19 and parameters: {'degree': 5}. Best is trial 0 with value: 0.7728060333835753.
A new study created in RDB with name: Poly_Linear_92829
Trial 2 finished with value: 0.7728060333835753 and parameters: {'degree': 1}. Best is trial 6 with value: 0.7728060333835753.
Trial 6 finished with value: 0.7728060333835753 and parameters: {'degree': 1}. Best is trial 6 with value: 0.7728060333835753.
Trial 11 finished with value: 0.7728060333835753 and parameters: {'degree': 1}. Best is trial 12 with value: 0.818369494924769.
Trial 22 finished with value: 0.7728060333835753 and parameters: {'degree': 1}. Best is trial 12 with value: 0.818369494924769.
Trial 10 finished with value: 0.7332903237803265 and parameters: {'degree': 3}. Best is trial 12 with value: 0.818369494924769.
Trial 5 finished with value: 0.7332903237803265 and parameters: {'degree': 3}. Best is trial 12 with value: 0.818369494924769.
Trial 12 finished with value: 0.818369494924769 and parameters: {'degree': 2}. Best is trial 12 with value: 0.818369494924769.
Trial 17 finished with value: 0.7332903237803265 and parameters: {'degree': 3}. Best is trial 12 with value: 0.818369494924769.
Trial 9 finished with value: 0.818369494924769 and parameters: {'degree': 2}. Best is trial 12 with value: 0.818369494924769.
Trial 3 finished with value: 0.7332903237803265 and parameters: {'degree': 3}. Best is trial 12 with value: 0.818369494924769.
Trial 7 finished with value: -3.047734147810578e+20 and parameters: {'degree': 4}. Best is trial 12 with value: 0.818369494924769.
Trial 21 finished with value: 0.7332903237803265 and parameters: {'degree': 3}. Best is trial 12 with value: 0.818369494924769.
Trial 19 finished with value: 0.818369494924769 and parameters: {'degree': 2}. Best is trial 12 with value: 0.818369494924769.
Trial 15 finished with value: -3.047734147810578e+20 and parameters: {'degree': 4}. Best is trial 12 with value: 0.818369494924769.
Trial 13 finished with value: -3.047734147810578e+20 and parameters: {'degree': 4}. Best is trial 12 with value: 0.818369494924769.
Trial 20 finished with value: -3.047734147810578e+20 and parameters: {'degree': 4}. Best is trial 12 with value: 0.818369494924769.
Trial 28 finished with value: 0.7728060333835753 and parameters: {'degree': 1}. Best is trial 12 with value: 0.818369494924769.
Trial 30 finished with value: 0.818369494924769 and parameters: {'degree': 2}. Best is trial 12 with value: 0.818369494924769.
Trial 14 finished with value: -3.047734147810578e+20 and parameters: {'degree': 4}. Best is trial 12 with value: 0.818369494924769.
Trial 4 finished with value: -6.5608901133283385e+19 and parameters: {'degree': 5}. Best is trial 12 with value: 0.818369494924769.
Trial 26 finished with value: 0.7728060333835753 and parameters: {'degree': 1}. Best is trial 12 with value: 0.818369494924769.
Trial 29 finished with value: 0.7728060333835753 and parameters: {'degree': 1}. Best is trial 12 with value: 0.818369494924769.
Trial 23 finished with value: -3.047734147810578e+20 and parameters: {'degree': 4}. Best is trial 12 with value: 0.818369494924769.
Trial 24 finished with value: -3.047734147810578e+20 and parameters: {'degree': 4}. Best is trial 12 with value: 0.818369494924769.
Trial 0 finished with value: -6.5608901133283385e+19 and parameters: {'degree': 5}. Best is trial 12 with value: 0.818369494924769.
Trial 1 finished with value: -6.5608901133283385e+19 and parameters: {'degree': 5}. Best is trial 12 with value: 0.818369494924769.
Trial 27 finished with value: 0.7332903237803265 and parameters: {'degree': 3}. Best is trial 12 with value: 0.818369494924769.
Trial 32 finished with value: 0.7332903237803265 and parameters: {'degree': 3}. Best is trial 12 with value: 0.818369494924769.
Trial 18 finished with value: -6.5608901133283385e+19 and parameters: {'degree': 5}. Best is trial 12 with value: 0.818369494924769.
Trial 25 finished with value: -3.047734147810578e+20 and parameters: {'degree': 4}. Best is trial 12 with value: 0.818369494924769.
Trial 8 finished with value: -6.5608901133283385e+19 and parameters: {'degree': 5}. Best is trial 12 with value: 0.818369494924769.
Trial 31 finished with value: -3.047734147810578e+20 and parameters: {'degree': 4}. Best is trial 12 with value: 0.818369494924769.
Trial 16 finished with value: -6.5608901133283385e+19 and parameters: {'degree': 5}. Best is trial 12 with value: 0.818369494924769.
